Workbook

Sheet Human Details
A1: id | B1: category | C1: difficulty | D1: user_input | E1: response | F1: reference | G1: retrieved_contexts | H1: retrieved_urls | I1: retrieved_content_types | J1: faithfulness | K1: context_recall | L1: context_precision | M1: semantic_similarity | N1: context_entity_recall | O1: answer_relevancy | P1: bert_f1 | Q1: bert_precision | R1: bert_recall | S1: RR_at5 | T1: hit_at5 | U1: latency | V1: prompt_tokens | W1: completion_tokens | X1: total_tokens | Y1: reranking_tokens | Z1: context_count | AA1: response_time_seconds
A2: 1 | B2: Allgemein | C2: medium | D2: Inwiefern würde ich als Student von einem Studium an der WiSo-Fakultät profitieren? | E2: Ein Studium an der WiSo-Fakultät der Universität zu Köln bietet viele Vorteile: 1. **Umfassende Fächervielfalt**: Die WiSo-Fakultät bietet ein breites Spektrum von Fächern, sodass Sie Ihren Interessen und Fähigkeiten entsprechend wählen können. 2. **Exzellente Qualität in Lehre und Forschung**: Die WiSo-Fakultät belegt kontinuierlich Spitzenplätze in Rankings wie dem "Handelsblatt" und der "Wirtschaftswoche". 3. **Ausgezeichnete Berufs- und Weiterbildungsaussichten**: Ein erfolgreich absolviertes Bachelorstudium bietet eine gute Grundlage für Ihre berufliche Karriere oder den Zugang zum konsekutiven Master. 4. **Hervorragende Services und Betreuung**: Das WiSo-Studienberatungszentrum unterstützt Sie bei der Planung Ihres Studienverlaufs, während das WiSo-Career-Service Ihnen bei der Vorbereitung auf Ihren Berufseinstieg hilft. 5. **Engagiertes Studentenleben**: Die Universität bietet eine dynamische Atmosphäre und viele Möglichkeiten für studentisches Engagement. Die WiSo-Fakultät ist eine der renommiertesten Einrichtungen für Wirtschafts- und Sozialwissenschaften in Europa, mit einer Vielzahl von Abteilungen und akademischen Mitarbeitern. Sie bietet ein breites Spektrum an Fächern und Möglichkeiten für Auslandsaufenthalte im Rahmen verschiedener Studien- und Austauschprogramme. Die Fakultät unterhält exzellente Partnerschaften mit führenden Hochschulen auf der ganzen Welt, was es Ihnen ermöglicht, Ihre Studien- und Karriereziele zu erreichen. | F2: Als Student profitierst du von einem theorie- und methodenorientierten Studienansatz, in dem Forschung und Lehre eng mit der Praxis verzahnt sind, sowie von der ausgeprägten Praxisnähe durch die langjährige Zusammenarbeit der WiSo-Fakultät mit Unternehmen und Lehrbeauftragten aus verschiedenen Berufsfeldern. | G2: ['# Erstsemesterinformationen\n\n##### Herzlich willkommen an der WiSo-Fakultät der Universität zu Köln!\n\nWir freuen uns sehr, dass Sie sich für ein Studium bei uns an der Wirtschafts- und Sozialwissenschaftlichen (kurz: WiSo) Fakultät entschieden haben. Sie erwartet ein spannendes Studium an einer der renommiertesten Fakultäten für Wirtschafts- und Sozialwissenschaften in einer attraktiven Stadt mit sehr guten Karriere- und Berufsperspektiven.\n\n## Infos zum WiSo-Studienstart\n\n## WiSo Welcome und Vorkurse Bachelor\n\n## WiSo Master Welcome Week\n\nHI\n\nzum Seitenanfang', 'inen der bedeutendsten Wirtschaftsstandorte in Deutschland dar.\n\n## Sie interessieren sich für ein Studium an der WiSo-Fakultät?\n\nPaco, deine künstliche Intelligenz zum Studium an der WiSo-Fakultät der Universität zu Köln, beantwortet dir jederzeit alle faktenbasierten Fragen zu deinem Wunschstudiengang! - Du suchst schnelle Infos zu, Zulassungsverfahren oder allgemeinen Fragen zur Universität zu Köln?\n\nDann ist Paco genau das Richtige für dich!*\n\nUnsere WiSo-Fakultät bietet:\n\nEinzigartige Fächervielfalt\nJe nach Interesse und Fähigkeiten können Sie aus dem umfangreichen Spektrum einer der renommiertesten Wirtschafts- und Sozialwissenschaftlichen Fakultäten Deutschlands wählen.\n\nExzellente Qualität in Lehre und Forschung\nDie WiSo-Fakultät belegt kontinuierlich die vordersten Plätze in zahlreichen namhaften Rankings, z.B. im „Handelsblatt“ und in der „Wirtschaftswoche“.\n\nAusgezeichnete Berufs- und Weiterbildungsaussichten\nNutzen Sie Ihren erfolgreich absolvierten Bachelorabschluss als vielversprechenden Ausgangspunkt für Ihre berufliche Karriere oder bewerben Sie sich für den konsekutiven Master.\n\nHervorragende Services und Betreuung\nDas WiSo-Studienberatungszentrum berät Sie gerne persönlich über den Studienverlauf, der WiSo-Career-Service unterstützt Sie bei der Vorbereitung Ihres Berufseinstiegs.\n\nEngagiertes Studentenleben\nDas dynamische Campusleben und eine Vielzahl studentischer Initiativen (z.B. der internationale OFW-Kongress) ermöglichen es Ihnen, Einsatz und Engagemen', 'n und energiewirtschaftlichen Themen, die mich geprägt haben. Der Ruf und das Netzwerk der WiSo haben mir den Einstieg in den Beruf erleichtert. Die fundamentalen Fähigkeiten, die ich für meinen Beruf brauche und die mir von anspruchsvollen Lehrkräften an einer renommierten Hochschule vermittelt wurden, helfen mir bis heute. – Dr. Dirk Schmelzer, Chief Financial Officer der Scout 24 SE\n\n-\n\nIch bin stolz darauf, ein Alumnus der Wirtschafts- und Sozialwissenschaftlichen Fakultät der Universität zu Köln zu sein, an der ich ein Studium der Betriebswirtschaftslehre absolviert habe. Das Wissen, die Fähigkeiten und die Erfahrungen, die ich während meiner Zeit an der WiSo gesammelt habe, sind für meinen beruflichen Werdegang von unschätzbarem Wert gewesen. Ich empfehle ein Studium an der WiSo-Fakultät jedem, der eine umfassende Ausbildung und eine solide Grundlage für eine erfolgreiche Karriere in der Geschäftswelt sucht. – Henning Gieseke, Chief Financial Officer der Ströer Management AG\n\nHI\n\nzum Seitenanfang', 'en. Eine Orientierung zu weiteren Kosten Sie u.a. hier.\n\n## 5. Was zeichnet das Studium an der Wiso Fakultät aus?\n\nEin Studium an der WiSo-Fakultät der Universität zu Köln stellt eine hervorragende Ausgangsbasis für Ihre weiteren professionellen und persönlichen Pläne dar. Mit ca. 9.000 Studierenden und einer Vielzahl an Professuren und wissenschaftlichen Mitarbeitern ist die Fakultät eine der wissenschaftlich renommiertesten Fakultäten für Wirtschafts- und Sozialwissenschaften in Europa.\n\nEntscheidende Rankings bewerten die Qualität von Forschung und Lehre an Hochschulen und der Fakultätsentwicklung anhand verschiedener Kriterien. Die WiSo-Fakultät freut sich, ihre Position in vielen renommierten Rankings behaupten und in einigen Fällen ausbauen zu können.\n\nDie Verbindung von Forschung und Lehre, Theorie und Praxis, Wirtschafts- und Sozialwissenschaften begründet unser Leitbild: „Today\'s ideas. Tomorrow\'s impact". Innerhalb Ihres Studiums erarbeiten Sie mit Hilfe moderner Analysemethoden und Modelle neue Lösungsansätze für relevante wirtschafts- und sozialwissenschaftliche Zukunftsfragen.\n\nKöln ist nicht nur als Studienort eine attraktive Stadt. Sie ist weit über den Karneval hinaus für ihre vielfältige Kulturszene bekannt und stellt zusammen mit dem Umland einen der bedeutendsten Wirtschaftsstandorte in Deutschland dar.\n\n## Wenn Sie schon mal studiert haben\n\n## 1. Kann ich an der WiSo-Fakultät ein Studium aufnehmen, wenn ich einen gleichwertigen Studiengang bzw. eine dort v', 'herausragenden Netzwerks von Universitäten und kooperiert mit führenden Organisationen. Hierdurch haben wir eine hervorragende Reputation in Lehre, Forschung, und Praxistransfer der sich in unseren hervorragenden Rankings widerspiegelt.” Prof. Ulrich W. Thonemann, PhD Dekan der Wirtschafts- und Sozialwissenschaftlichen Fakultät © Lisa BellerZAHLEN UND FAKTEN DER WISO-FAKULTÄT Mit einem Studium an der WiSo-Fakultät der Universität zu Köln schaffen Sie sich eine hervorragende Basis für Ihren weiteren beruflichen und persönlichen Werdegang. Mit knapp 8.000 Studierenden und einer Vielzahl von Abteilungen und akademischen Mitarbeiter:innen ist die WiSo-Fakultät eine der größten und renommiertesten Einrichtungen für Management, Wirtschaft und Sozialwissenschaften in Europa. 8.735 nationale und internationale Studierende 168 Partneruniversitäten weltweit1 97 Professor:innen Über 100 Jahre an Erfahrung in exzellenter Lehre und Forschung Stand: Mai 2023 1 Die WiSo-Fakultät unterhält exzellente Partnerschaften mit 160 führenden Hochschulen auf der ganzen Welt auf verschiedenen Studienebenen und ermöglicht ihren Studierenden Auslandsaufenthalte im Rahmen verschiedener Studien- und Austauschprogramme. Die Studierenden können je nach gewähltem Studiengang aus einem attraktiven Angebot an Partnerhochschulen wählen.Im Rahmen Ihres Studiums erlernen Sie alles, was Sie für den nächsten Schritt in Ihrer Karriere benötigen. Als eine der größten Bildungseinrichtungen Deutschlands zählt die Fakul'] | H2: ['https://wiso.uni-koeln.de/de/studium/studienorganisation/erstsemester', 'https://wiso.uni-koeln.de/de/studium', 'https://wiso.uni-koeln.de/de/praxis/wisoalumni/tomorrows-impact', 'https://wiso.uni-koeln.de/de/studium/studienorganisation/faq/allgemeine-fragen', 'file://D:/Uni-Köln/Masterarbeit/Software/uzk-masterarbeit/data/pdf_cache/__wiso.uni-koeln.de_sites_fakultaet_dokumente_studium_bachelor_Broschuere-Bachelor_VWL-WiSo_Fakultaet-Uni-Koeln.pdf'] | I2: ['html', 'html', 'html', 'html', 'pdf'] | J2: 1 | K2: 1 | L2: 0.68 | M2: 0.67894446 | N2: 0.45454545 | O2: 1 | P2: 0.10237458 | Q2: -0.040825743 | R2: 0.24944803 | S2: 0 | T2: 0 | U2: 50.469219 | V2: 3217 | W2: 441 | X2: 3658 | Y2: 0 | Z2: 5 | AA2: 50.469219
A3: 8 | B3: Allgemein | C3: hard | D3: Welchen Vorteil bietet das Projekt E-PLUS? | E3: Das Projekt E-PLUS bietet verschiedene Vorteile, darunter: * Eine optimierte Lernumgebung für Studierende durch die Verwendung von e-Homework-Aufgaben * Eine erhöhte Motivation der Studierenden durch das Bonuspunktesystem * Eine verbesserte Fähigkeit der Dozenten, Aufgaben zu erstellen und zu bewerten * Eine Erweiterung des Projekts auf weitere Bachelor-Kurse und möglicherweise auch auf andere Studiengänge Das Projekt E-PLUS zielt darauf ab, die Anwendungsbereiche von Mathematik und Statistik in den Wirtschaftswissenschaften zu verbessern. | F3: Das Projekt E-PLUS bietet den Vorteil, dass durch die von den Studierenden selbst eingebrachten, individuellen Aufgaben ein breit gefächerter Aufgabenpool entsteht, aus dem viele verschieden aufgebaute E-Probe-Klausuren zum intensiven Üben generiert werden können. Die Studierenden erhalten zu ihren Bearbeitungen direktes Feedback, können ihren Lernstand dadurch gezielt reflektieren und anpassen und Lehrende erkennen typische Schwachstellen, die sie in der Präsenzveranstaltung noch einmal aufgreifen. Gleichzeitig werden die eigentlichen Klausuren als individualisierte E-Prüfungen angeboten, die zeitlich sehr flexibel abgelegt werden können, sodass sich die Klausurtermine entzerren und der Prüfungsbetrieb organisatorisch wie administrativ entlastet wird. | G3: ['t further action is necessary.\n\nThe e-homework assignment tool also uses, if available, a bonus point system, which could have a positive effect on the mark for the final examination if the assignments are completed successfully. This increases student motivation and leads to lower fail and drop-out rates.\n\nThe e-homework assignment tool will be used by and by\xa0from winter semester 2017/18 on the following bachelor courses: "Basic Module Mathematics", "Basic Module Microeconomics", "Basic Module Statistics","Advanced Module Statistics" and "Basic Module Fundamentals of Economics". In the long term, the plan is to expand the project both within the Faculty and University-wide to take in other courses in which quantitative mathematical or statistical methods are applied.\n\n## AufbaU: Tasks in Business Administration classes\n\nThe aim of the project - led by Prof. Dr. Matthias Pilz, holder of the Chair for Business and Economic Education and Training - is to optimise application-oriented learning tasks on the mass bachelor degree programme in Business Administration and to expand lecturers’ task-construction skills.\nIn contrast to pure exercises, these learning tasks not only allow students to revise and practise what they have learned in the lectures, but also to develop new competencies, based on the application of the acquired knowledge to solve real problems.\n\nAs part of this project, the first step in the 2017 summer term was to analyse the existing learning tasks in selected', 'loped project management solutions. ... apply modern methods of project planning and project execution such as agile or help-based project management systems ... apply real options thinking to determine the value of uncertain projects. ... recommend project approaches to cope with uncertainty, complexity, and human behavior while accounting for the multidimensional goals of project stakeholders 4 Teaching and Learning Methods lecture practice 5 Module Entry Requirements Recommended: at least 12 ECTS credits from the group Foundation Knowledge 6 Mode of End-Of-Module Examination Written test: PO 7 Prerequisites for Awarding of Credit Points Passing the written test. 8 Other Programmes that Use the Module Master of Science Business Administration - Supply Chain Management: Specialization Section Supply Chain Management Master of Science Mathematik: MA Business and Economics Sciences Mathematics Master of Science Economics: Supplementary Section Master of Science Wirtschaftsmathematik: MA Business and Economics Sciences Mathematics --- Page 209 --- valid for students of the ER 2015 (enrolment for winter semester 2020/21 at the latest) MODULE CATALOGUE - ECONOMICS - MASTER OF SCIENCE 205 Master of Science International Management: Core and Advanced Section International Management Supplementary Section International Management Master of Education Wirtschaftspädagogik/Lehramt an Berufskollegs: Supplementary Section Business Education Master of Science Information Systems: Suppleme', 'nt: Supplementary Section Corporate Development Master of Science Information Systems: Specialisation Section Information Systems Master of Science Business Analytics & Econometrics: Supplementar y Section Business Analytics & Econometrics Master of Education Wirtschaftspädagogik/Lehramt an Berufskollegs: Ergänzungbereich Wirtschaftspädagogik 9 Module Manager Univ. -Prof. Dr. Wolf Ketter 10 Miscellaneous --- Page 116 --- valid for students of the ER 2021 (enrolment fr om winter semester 2021/22 ) BUSINESS ADMINISTRATION : ACCOUNTING AND TAXATION - MASTER OF SCIENCE 112 SpM Information Systems II Module Code 1277MSISY2 Workload 180h ECTS Credits 6 Module Language English Module Availability every term Duration 1 Term 1 Courses a) Emerging Electronic Business b) Digital Design c) IT Entrepreneurship d) Bayesian Data Analytics Contact Hours a) 45h b) 30h c) 50h d) 45h Self-Stu- dies a) 135h b) 150h c) 130h d) 135h Course Language a) English b) English c) English d) English 2 Module Content a) Emerging Electronic Business • Current IT trends and the transformation of electronic business into ""ambient business"" in the context of networked and computerised objects and environments (Internet of Things, smart En- vironments) • Conceptual basics of relevant technologies (inclu ding sensors, RFID, telecommunication) • Design and applications of smart environments • Design of intuitive human -computer interaction (HCI) • Context awareness and context -based services • Freely offering', 'eporting. ... analyse current questions and challenges in the area of sustainability/ESG reporting. ... assess and discuss findings and research results of specialized theories / methods. ... justify and defend (independently developed) positions or problem solutions. ... critically evaluate current social developments and develop alternative solutions. 4 Teaching and Learning Methods lecture practice 5 Module Entry Requirements none 6 Mode of End-Of-Module Examination Written test: WT (60) 7 Prerequisites for Awarding of Credit Points Passing the module examination 8 Other Programmes that Use the Module Master of Science Business Administration - Supply Chain Management: Supplementary Section Supply Chain Management Master of Science Business Administration - Marketing: Supplementary Section Marketing Master of Science Business Administration - Finance: Supplementary Section Finance Master of Science Information Systems: Supplementary Section Information Systems Master of Science Business Administration - Corporate Development: Supplementary Section Corporate Development Master of Science Informatik: Anwendungsfeld Master of Science Geographie: Wahlpflichtfach Management & Social Sciences --- Page 69 --- valid for students of the ER 2015 (enrolment for winter semester 2020/21 at the latest) BUSINESS ADMINISTRATION: Finance - MASTER OF SCIENCE 65 Master of Science Economics: Supplementary Section Management & Social Sciences Master of Science Mathematik: Economics Sciences Ma', 'e practice 5 Module Entry Requirements Recommendation: The basic modules Supply Ch ain Analytics I and II should have been completed. 6 Mode of End -Of-Module Examination Written test: PO 7 Prerequisites for Awarding of Credit Points Passing the module examination 8 Other Programmes that Use the Module Master of Science Business Administration - Supply Chain Management: Specialisation Section Supply Chain Management Master of Science Economics: Supplementary Section Management & Social Sciences Master of Science Business Administration - Accounting and Taxation: Supplementary Section Accounting and Taxation Master of Science Business Administration - Finance: Supplementary Section Finance Master of Science Business Administration - Marketing: Supplementary Section Marketing Master of Science Information Systems: Suppleme ntary Section Information Systems Master of Science Business Administration - Corporate Development: --- Page 85 --- valid for students of the ER 2021 (enrolment fr om winter semester 2021/22 ) INTERNATIONAL MANAGEMENT - MASTER OF SCIENCE 85 Supplementary Section Corporate Development Master of Science International Management: Supplementary Section International Management Master of Science Mathematik: Economics Sciences Master of Science Wirtschaftsmathematik: Economics Sciences Master of Science Informatik: Anwendungsfeld Master of Education Wirtschaftspädagogik/Lehramt an Berufskollegs: Ergänzungbereich Wirtschaftspädagogik 9 Module Manager Prof. Dr. Nico'] | H3: ['https://wiso.uni-koeln.de/en/studies/teaching-innovations', 'file://D:/Uni-Köln/Masterarbeit/Software/uzk-masterarbeit/data/pdf_cache/__wiso.uni-koeln.de_sites_fakultaet_dokumente_downloads_Modulhandbuecher_Studienjahr_22-23_MHB_PO2015_m_mhb_po2015_e_economics.pdf', 'file://D:/Uni-Köln/Masterarbeit/Software/uzk-masterarbeit/data/pdf_cache/__wiso.uni-koeln.de_sites_fakultaet_dokumente_downloads_master_Studienjahr_24-25_m_mhb_po2021_e_ba_accounting.pdf', 'file://D:/Uni-Köln/Masterarbeit/Software/uzk-masterarbeit/data/pdf_cache/__wiso.uni-koeln.de_sites_fakultaet_dokumente_downloads_Modulhandbuecher_Studienjahr_22-23_MHB_PO2015_m_mhb_po2015_e_ba_finance.pdf', 'file://D:/Uni-Köln/Masterarbeit/Software/uzk-masterarbeit/data/pdf_cache/__wiso.uni-koeln.de_sites_fakultaet_dokumente_downloads_master_Studienjahr_24-25_m_mhb_po2021_e_intmanagement.pdf'] | I3: ['html', 'pdf', 'pdf', 'pdf', 'pdf'] | J3: 0 | K3: 0 | L3: 0 | M3: 0.75543241 | N3: 0 | O3: 0.25 | P3: 0.14917925 | Q3: 0.19621211 | R3: 0.099259786 | S3: 0 | T3: 0 | U3: 13.999557 | V3: 2978 | W3: 169 | X3: 3147 | Y3: 0 | Z3: 5 | AA3: 13.999557
A4: 11 | B4: Modulhandbuch/PO | C4: medium | D4: Welche Bachelorstudiengänge der WiSo-Fakultät haben ein eigenes Modulhandbuch unter PO 2021? | E4: Basierend auf den Suchergebnissen können wir folgende Bachelorstudiengänge der WiSo-Fakultät identifizieren, die ein eigenes Modulhandbuch unter PO 2021 haben: - Betriebswirtschaftslehre - Volkswirtschaftslehre - Management, Economics and Social Sciences - Sozialwissenschaften - Gesundheitsökonomie - Wirtschaftsinformatik - Lehramt am Berufskolleg I Bitte beachten Sie, dass die Modulhandbücher für das Studienjahr 2024/25 gültig sind und im Modulhandbuch-Archiv auch vergangene Studienjahre ab dem Studienjahr 2021/22 verfügbar sind. | F4: Für das Studienjahr 2025/26 gibt es unter der Bachelor PO 2021 Modulhandbücher für Betriebswirtschaftslehre, Volkswirtschaftslehre, Management, Economics and Social Sciences, Sozialwissenschaften, Gesundheitsökonomie, Wirtschaftsinformatik sowie Lehramt am Berufskolleg I. | G4: ['# Modulhandbuch-Archiv\n\nHier Sie die Modulhandbücher (MHB) aller WiSo-Studiengänge vergangener Studienjahre ab dem Studienjahr 2021/22. Bitte beachten Sie, dass diese MHB keine Gültigkeit mehr besitzen.\xa0\n\n## Inhaltsverzeichnis\n\n- Bachelor\n\n- Bachelor PO 2021\n- Bachelor PO 2015\n\xa0\n\n- Master\n\n- Master PO 2021\n- Master PO 2015\n\nAchten Sie zudem auch auf die entsprechende Prüfungsordnung (PO). Die PO 2021 gilt ab dem Studienjahr 2021/22; die PO 2015 ist für Masterstudiengänge im Studienjahr 2022/23 ausgelaufen und für Bachelorstudiengänge zum Studienjahr 2024/25.\n\n\xa0\n\nFalls Sie ein MHB aus einem anderen Studienjahr benötigen, dann können Sie sich gerne über das Kontaktformular an den WiSo Student Service Point wenden.\n\n## Bachelor PO 2021\n\n## Bachelor Modulhandbücher | gültig vom 01.10.2024-30.09.2025\n\nNachfolgend Sie für jeden Bachelorstudiengang\xa0das Modulhandbuch der Prüfungsordnung PO 2021 gültig für das Studienjahr 2024/25.\n\n- Betriebswirtschaftslehre\n- Volkswirtschaftslehre\n- Management, Economics and Social Sciences\n- Sozialwissenschaften\n- Gesundheitsökonomie\n- Wirtschaftsinformatik\n- Lehramt am Berufskolleg I\n\n## Bachelor Modulhandbücher | gültig vom 01.10.2023-30.09.2024\n\nNachfolgend Sie für jeden Bachelorstudiengang\xa0das Modulhandbuch der Prüfungsordnung PO 2021 gültig für das Studienjahr 2023/24.\n\n- Betriebswirtschaftslehre\n- Volkswirtschaftslehre\n- Management, Economics and Social Sciences\n- Sozialwissenschaften\n- Gesundheitsökonomie\n- Wirtschaftsinformatik\n- Lehramt am', 'Dokumente und Medien - Prüfungsordnung 2021\n\n# Bachelor PO 2021\n\nHier Sie alle wichtigen Dokumente, die Sie zur Orientierung und für die Organisation Ihres Studiums benötigen.\xa0\n\nGültig für Studierende der Prüfungsordnung 2021 (Einschreibung ab WiSe 2021/22).\n\nIm Modulhandbuch-Archiv Sie die Modulhandbücher vergangener Studienjahre.\n\n## Bachelor Modulhandbücher | gültig vom 01.10.2025-30.09.2026\n\nNachfolgend Sie für jeden Bachelorstudiengang\xa0das Modulhandbuch der Prüfungsordnung PO 2021 gültig ab dem 01.10.2025.\n\n- Betriebswirtschaftslehre\n- Volkswirtschaftslehre\n- Management, Economics and Social Sciences\n- Sozialwissenschaften\n- Gesundheitsökonomie\n- Wirtschaftsinformatik\n- Lehramt am Berufskolleg I\n\n## Prüfungsordnungen PO 2021\n\nIm Download-Bereich des Prüfungsamtes Sie die gemeinsame Prüfungsordnung der WiSo-Studiengänge, sowie die zusätzliche Bachelorprüfungsordnung.\n\nHI\n\nzum Seitenanfang', 'ungsmodul RE Referat FS Fallstudie SM Schwerpunktmodul HA Hausarbeit SSt Selbststudium K Kontaktzeit (= Präsenzzeit in LV) SWS Semesterwochenstunde KL Klausur SI Studium Integrale LP Leistungspunkt (engl.: CP) VN Vor- und Nachbereitungszeit LV Lehrveranstaltung WP Wahlpflichtveranstaltung MP Mündliche Prüfung WL Workload = Arbeitsaufwand --- Page 4 --- Gültig für Studierende der PO 2021 (Einschreibung ab WiSe 2021/22) MODULHANDBUCH – BETRIEBSWIRTSCHAFTSLEHRE – BACHELOR OF SCIENCE 4 Inhaltsverzeichnis 1 BETRIEBSWIRTSCHAFTSL EHRE ................................ ................................ ..... 5 1.1 Inhalte und Studienziele ................................ ................................ ........................... 5 1.2 Voraussetzungen ................................ ................................ ................................ .... 7 1.3 Studienaufbau und -abfolge ................................ ................................ .................... 7 1.4 Study Abroad Option ................................ ................................ ............................... 8 1.4.1 Das Studies Abroad Programme (STAP) der WiSo -Fakultät ................................ . 9 1.4.2 Anrechnungsmöglichkeiten Studies Abroad ................................ ......................... 10 1.5 Musterstudienpläne ................................ ................................ ................................ 10 1.6 Midterm Regelung ................................ ............', '# Modulhandbücher und Prüfungsordnung\n\nHier Sie die gültigen Modulhandbücher und Prüfungsordnungen des aktuell laufenden Studienjahres der Prüfungsordnung (PO) 2021. Im Modulhandbuch-Archiv Sie darüberhinaus die Modulhandbücher vergangener Studienjahre.\n\n## Bachelor PO 2021\n\n## Master PO 2021\n\n## Modulhandbuch-Archiv\n\nHI\n\nzum Seitenanfang', '# Modulhandbücher und Prüfungsordnung\n\nHier Sie die gültigen Modulhandbücher und Prüfungsordnungen des aktuell laufenden Studienjahres der Prüfungsordnung (PO) 2021. Im Modulhandbuch-Archiv Sie darüberhinaus die Modulhandbücher vergangener Studienjahre.\n\n## Bachelor PO 2021\n\n## Master PO 2021\n\n## Modulhandbuch-Archiv\n\nHI\n\nzum Seitenanfang'] | H4: ['https://wiso.uni-koeln.de/de/studium/modulhandbuecher-und-pruefungsordnungen/modulhandbuch-archiv', 'https://wiso.uni-koeln.de/de/studium/modulhandbuecher-und-pruefungsordnungen/bachelor-po-2021', 'file://D:/Uni-Köln/Masterarbeit/Software/uzk-masterarbeit/data/pdf_cache/__wiso.uni-koeln.de_sites_fakultaet_dokumente_downloads_Modulhandbuecher_Studienjahr_22-23_MHB_PO2021_b_mhb_po2021_bwl_01.pdf', 'https://wiso.uni-koeln.de/de/studium/modulhandbuecher-und-pruefungsordnungen', 'https://wiso.uni-koeln.de/de/studium/modulhandbuecher-und-pruefungsordnungen?Chain=&cHash=48741bdec96c2f016003263d312f4737'] | I4: ['html', 'html', 'pdf', 'html', 'html'] | J4: 1 | K4: 0.33333333 | L4: 0.325 | M4: 0.78070322 | N4: 1 | O4: 1 | P4: 0.43012413 | Q4: 0.29123804 | R4: 0.57347947 | S4: 0.5 | T4: 1 | U4: 14.705635 | V4: 2914 | W4: 206 | X4: 3120 | Y4: 0 | Z4: 5 | AA4: 14.705635
A5: 17 | B5: Bachelor-Studium | C5: easy | D5: Welche Bachelorstudiengänge bietet WiSo-Fakultät allgemein an? | E5: Die WiSo-Fakultät der Universität zu Köln bietet folgende Bachelorstudiengänge an: 1. Betriebswirtschaftslehre 2. Volkswirtschaftslehre 3. Management, Economics and Social Sciences 4. Sozialwissenschaften 5. Gesundheitsökonomie 6. Wirtschaftsinformatik 7. Lehramt Berufskolleg | F5: Die WiSo-Fakultät bietet folgende Bachelorprogramme an: Betriebswirtschaftslehre, Volkswirtschaftslehre, Sozialwissenschaften, Management, Economics & Social Sciences, Wirtschaftsinformatik, Gesundheitsökonomie sowie der Lehramts-Bachelor. | G5: ['Studiengänge an der WiSo-Fakultät\n\n# Bachelorstudiengänge\n\nSchaffen Sie sich eine exzellente Basis für Ihre weitere Karriere!\n\nEin wirtschafts- oder sozialwissenschaftlicher Bachelor-Abschluss ebnet Ihnen Ihren individuellen Karriereweg – egal, ob Sie direkt nach dem Bachelor in den Beruf einsteigen, ein Trainee-Programm absolvieren oder Sie sich für einen weiterführenden Masterstudiengang entscheiden. Sie den Bachelor-Studiengang, der zu Ihnen passt und studieren Sie an einer top-gerankten Universität in einer pulsierenden Stadt.\n\n## Inhaltsverzeichnis\n\n- Spitzenpositionen in Rankings\n- Attraktiver Standort\n- Chat with Paco\n- Unsere Bachelorstudiengänge im Überblick\n- Weitere Bachelorstudiengänge\n- Auslaufende Bachelorstudiengänge\n\n## Spitzenpositionen in Rankings\n\nDie WiSo-Fakultät kombiniert Theorie und Praxis. Die Bachelor-Studiengänge sind interdisziplinär ausgerichtet und fördern den Wissenstausch sowohl unter den Studierenden als auch zwischen den Disziplinen. Auch dank der innovativen Lehre und der exzellenten Forschung schneidet die Fakultät in nationalen als auch internationalen Hochsschulrankings bestens ab.\n\n## Attraktiver Standort\n\nKöln ist für seine Lebensfreude, Toleranz und Weltoffenheit bekannt. Die Metropolregion ist nicht nur als Wissenschaftsstandort interessant, sondern bietet Studierenden auch eine breite Palette von Kontaktmöglichkeiten zur beruflichen Praxis. Die Region Region über einen attraktiven und zukunftsfähigen Branchenmix, in dem unter anderem', '# Bachelorstudium: FAQ\n\nHier beantworten wir alle Fragen rund um die Bachelorstudiengänge der WiSo-Fakultät. Die Fragen beziehen sich einerseits auf die Aufnahme eines Studiums bei uns (Studienentscheidung, Voraussetzungen für ein Studium allgemein, Hochschulwechsel, Anrechnungsoptionen) sowie auch auf Aspekte während des Studiums (Wahl von Spezialisierungen, Anmeldung zu Prüfungen etc.)\n\nBitte wählen Sie also, ob Sie eine Frage zur Studienwahl/Bewerbung haben oder etwas zum Studium wissen wollen und klicken Sie den entsprechenden Bereich an!\n\nHI\n\nzum Seitenanfang', 'urch den Einsatz von IT zu unterstützen. Dies umfasst sowohl die Forschung und Berufswelt als auch den privaten Alltag.\n\n> Das Bachelorstudium der Wirtschaftsinformatik an der renommierten WiSo-Fakultät und am Kölner Institut für Wirtschaftsinformatik bietet eine breite Grundlagenausbildung im Zusammenspiel von Theorie und Praxis an der Schnittstelle von Wirtschaftswissenschaften und Informatik. Sie erhalten die Möglichkeit, forschungs- und anwendungsnah analytisches Strukturieren, Denken und Handeln in die Praxis umsetzen, indem Sie die erworbenen Kenntnisse und Fähigkeiten zur Lösung praktischer Problemstellungen einsetzen.\n\nzum Seitenanfang\n\nNoch unentschieden?\n\nDann lerne unsere Angebote für Studieninteressierte kennen - koordiniert vom WiSo-Student Service Point - die Dir eine individuelle Beratung bieten, die genau auf Deine Bedürfnisse zugeschnitten ist.\n\n- Orientierungs- und Beratungsangebot für Studieninteressierte\n\n## Akademische Exzellenz mit internationalem Angebot\n\n### Internationale Ausrichtung über das gesamte Studium hinweg\n\nFür den Großteil unseres Studienangebots erhalten wir Bewerbungen von einer großen Anzahl verschiedener Nationalitäten, sodass Sie sich auf ein internationales und interkulturelles Umfeld an der Fakultät und auch innerhalb Ihres Studiengangs freuen können. Eine Vielzahl der Kurse wird je nach Spezialisierung in englischer Sprache angeboten.\n\n### Optionales Auslandssemester\n\nDie WiSo-Fakultät ist Mitglied in mehreren Netzwerken', 'üssen vor dem Start des Studiums das einsemestrige Programm "Studienstart International" verpflichtend durchlaufen.\n\n##### Master\n\nMasterstudiengänge starten zum 1. Fachsemester an der Wiso-Fakultät nur zum Wintersemester. Die Bewerbung erfolgt online über KLIPS. Die Bewerbungsfristen variieren hinsichtlich der Studiengänge. Genauere Informationen zum Bewerbungsverfahren sowie einzureichende Unterlagen entnehmen Sie bitte unseren Seite zum Masterbewerbungsverfahren.\n\n## 2. Welche (grundständigen) Bachelorstudiengänge können an der WiSo-Fakultät studiert werden?\n\nAn der Wiso-Fakultät der Universität zu Köln können momentan sieben Bachelorstudiengänge studiert werden:\n\n- Betriebswirtschaftslehre\n- Volkswirtschaftslehre\n- Management, Economics and Social Sciences\n- Sozialwissenschaften\n- Gesundheitsökonomie\n- Wirtschaftsinformatik\n- Lehramt Berufskolleg\n\nAlle diese Bachelorstudiengänge (außer Lehramt BK) sind Bachelor of Science-Studiengänge und sogenannte 1-Fach-Bachelor. D.h. Sie können nicht mit anderen Studiengängen der Uni Köln kombiniert werden. Neben den Fachstudiengängen bieten wir außerdem das Bachelor of Arts-Programm "Lehramt Berufskolleg" an. Hier studieren Sie das Unterrichtsfach "Wirtschaftswissenschaften" in Kombination mit einem anderen Unterrichtsfach, welches nicht an der WiSo-Fakultät angesiedelt ist.\nNur die Bachelorstudiengänge Betriebs- und Volkswirtschaftslehre werden zum Winter- und Sommersemester angeboten, alle übrigen Bachelorstudiengänge starten nur z', "# Bachelor's programme: FAQ\n\nHere we answer all questions about the Bachelor's degree programmes of the WiSo Faculty. On the one hand, the questions relate to taking up a degree programme with us (study decision, requirements for a degree programme in general, change of university, credit transfer options) and also to aspects during the degree programme (choice of specialisations, registration for examinations, etc.).\n\nSo please choose whether you have a question about the choice of study/application or want to know something about studying and click on the corresponding area!\n\nHI\n\nTo top of page"] | H5: ['https://wiso.uni-koeln.de/de/studium/bachelor', 'https://wiso.uni-koeln.de/de/studium/studienorganisation/faq/bachelor', 'https://wiso.uni-koeln.de/de/studium/bachelor/bachelor-wirtschaftsinformatik', 'https://wiso.uni-koeln.de/de/studium/studienorganisation/faq/allgemeine-fragen', 'https://wiso.uni-koeln.de/en/studies/organising-your-studies/faq/bachelor'] | I5: ['html', 'html', 'html', 'html', 'html'] | J5: 1 | K5: 1 | L5: 0.325 | M5: 0.85747824 | N5: 1 | O5: 1 | P5: 0.59260499 | Q5: 0.53976047 | R5: 0.64456999 | S5: 1 | T5: 1 | U5: 13.274629 | V5: 3046 | W5: 132 | X5: 3178 | Y5: 0 | Z5: 5 | AA5: 13.274629
A6: 20 | B6: Bachelor-Studium | C6: hard | D6: Welche Bachelor-Verbundstudiengänge mit WiSo-Beteiligung werden angeboten? | E6: Die WiSo-Fakultät der Universität zu Köln bietet verschiedene Bachelor-Verbundstudiengänge mit Beteiligung an. Dazu gehören: * Regionalstudien China: Wahlpflichtfächer "Betriebswirtschaftslehre", "Sozialwissenschaften" und "Volkswirtschaftslehre" * Regionalstudien Lateinamerika: Wahlpflichtfächer "Sozialwissenschaften" und "Volkswirtschaftslehre" * Regionalstudien Ost- und Mitteleuropa: Wahlpflichtfächer "Sozialwissenschaften" und "Volkswirtschaftslehre" * Medienwissenschaft: Wahlpflichtfach "Medienmanagement und Medienökonomie" Darüber hinaus gibt es auch andere Studiengänge, in denen Leistungen in Neben- oder Ergänzungsfächern an der WiSo-Fakultät studiert werden dürfen. Dazu gehören: * Mathematik und Wirtschaftsmathematik (Nebenfächer "Wirtschaftswissenschaften" oder "Volkswirtschaftslehre") * Geographie (Nebenfächer "BWL", "VWL" oder "SOWI") Es ist wichtig zu beachten, dass diese Studiengänge nur zum Wintersemester starten. | F6: Es werden folgende Verbundstudiengänge der Philosophischen Fakultät angeboten: Bachelorstudiengang Regionalstudien China, Bachelorstudiengang Regionalstudien Lateinamerika, Bachelorstudiengang Regionalstudien Ost- und Mitteleuropa, Bachelorstudiengang Medienwissenschaft, Bachelorstudiengang Wirtschaftsmathematik, Bachelorstudiengang Mathematik, Bachelor Geographie, Bachelor Klinische Pflege | G6: ['nge\n\n### Bachelorstudiengänge mit WiSo-Beteiligung\n\nNeben den Bachelorstudiengängen der WiSo-Fakultät gibt es auch weitere Studiengänge mit WiSo-Beteiligung. Die WiSo-Fakultät bietet in den folgenden Verbundstudiengängen Wahlpflichtfächer an, die Studiengänge starten alle nur zum Wintersemester:\n\n## Verbundstudiengänge mit WiSo-Beteiligung (Philosophische Fakultät)\n\nFachliche Fragen zu Ihrem Wahlpflichtfach beantwortet gerne der WiSo Student Service Point. Für alle anderen Fragen wenden Sie sich bitte an das Prüfungsamt und den Studierendenservice der Philosophischen Fakultät.\n\n- Bachelorstudiengang Regionalstudien China: Wahlpflichtfächer „Betriebswirtschaftslehre“, „Sozialwissenschaften“ und „Volkswirtschaftslehre“\n- Bachelorstudiengang Regionalstudien Lateinamerika: Wahlpflichtfächer „Sozialwissenschaften“ und „Volkswirtschaftslehre“\n- Bachelorstudiengang Regionalstudien Ost- und Mitteleuropa: Wahlpflichtfächer „Sozialwissenschaften“ und „Volkswirtschaftslehre“\n- Bachelorstudiengang Medienwissenschaft: Wahlpflichtfach „Medienmanagement und Medienökonomie"\n\n\xa0\n\n## Mathematik und Wirtschaftsmathematik (Mathematisch-Naturwissenschaftliche Fakultät)\n\n- Bachelorstudiengang Wirtschaftsmathematik (Nebenfächer "Wirtschaftswissenschaften" oder "Volkswirtschaftslehre")\n- Bachelorstudiengang Mathematik (Nebenfächer "Wirtschaftswissenschaften" oder "Volkswirtschaftslehre")\n\n## Geographie (Mathematisch-Naturwissenschaftliche Fakultät)\n\nAllgemeine Informationen zum B.Sc. Geographie Sie a', '# Bachelorstudium: FAQ\n\nHier beantworten wir alle Fragen rund um die Bachelorstudiengänge der WiSo-Fakultät. Die Fragen beziehen sich einerseits auf die Aufnahme eines Studiums bei uns (Studienentscheidung, Voraussetzungen für ein Studium allgemein, Hochschulwechsel, Anrechnungsoptionen) sowie auch auf Aspekte während des Studiums (Wahl von Spezialisierungen, Anmeldung zu Prüfungen etc.)\n\nBitte wählen Sie also, ob Sie eine Frage zur Studienwahl/Bewerbung haben oder etwas zum Studium wissen wollen und klicken Sie den entsprechenden Bereich an!\n\nHI\n\nzum Seitenanfang', "# Bachelor's programme: FAQ\n\nHere we answer all questions about the Bachelor's degree programmes of the WiSo Faculty. On the one hand, the questions relate to taking up a degree programme with us (study decision, requirements for a degree programme in general, change of university, credit transfer options) and also to aspects during the degree programme (choice of specialisations, registration for examinations, etc.).\n\nSo please choose whether you have a question about the choice of study/application or want to know something about studying and click on the corresponding area!\n\nHI\n\nTo top of page", 'urch den Einsatz von IT zu unterstützen. Dies umfasst sowohl die Forschung und Berufswelt als auch den privaten Alltag.\n\n> Das Bachelorstudium der Wirtschaftsinformatik an der renommierten WiSo-Fakultät und am Kölner Institut für Wirtschaftsinformatik bietet eine breite Grundlagenausbildung im Zusammenspiel von Theorie und Praxis an der Schnittstelle von Wirtschaftswissenschaften und Informatik. Sie erhalten die Möglichkeit, forschungs- und anwendungsnah analytisches Strukturieren, Denken und Handeln in die Praxis umsetzen, indem Sie die erworbenen Kenntnisse und Fähigkeiten zur Lösung praktischer Problemstellungen einsetzen.\n\nzum Seitenanfang\n\nNoch unentschieden?\n\nDann lerne unsere Angebote für Studieninteressierte kennen - koordiniert vom WiSo-Student Service Point - die Dir eine individuelle Beratung bieten, die genau auf Deine Bedürfnisse zugeschnitten ist.\n\n- Orientierungs- und Beratungsangebot für Studieninteressierte\n\n## Akademische Exzellenz mit internationalem Angebot\n\n### Internationale Ausrichtung über das gesamte Studium hinweg\n\nFür den Großteil unseres Studienangebots erhalten wir Bewerbungen von einer großen Anzahl verschiedener Nationalitäten, sodass Sie sich auf ein internationales und interkulturelles Umfeld an der Fakultät und auch innerhalb Ihres Studiengangs freuen können. Eine Vielzahl der Kurse wird je nach Spezialisierung in englischer Sprache angeboten.\n\n### Optionales Auslandssemester\n\nDie WiSo-Fakultät ist Mitglied in mehreren Netzwerken', 'chtsfach "Wirtschaftswissenschaften" in Kombination mit einem anderen Unterrichtsfach, welches nicht an der WiSo-Fakultät angesiedelt ist.\nNur die Bachelorstudiengänge Betriebs- und Volkswirtschaftslehre werden zum Winter- und Sommersemester angeboten, alle übrigen Bachelorstudiengänge starten nur zum Wintersemester.\n\nDie Philosophische Fakultät bietet folgende Verbundstudiengänge an, die ein wirtschafts- und sozialwissenschaftliches Wahlpflichtfach umfassen, welches dann an der WiSo-Fakultät verortet ist:\n\n- Medienwissenschaften\n- Regionalstudien China\n- Regionalstudien Ost- und Mitteleuropa\n- Regionalstudien Lateinamerika\n\nZudem gibt es noch einige andere Studiengänge, in denen in verschiedenem Umfang Leistungen in Neben- oder Ergänzungsfächern an der WiSo-Fakultät studiert werden dürfen.\nAn der Mathematisch-Naturwissenschaftlichen Fakultät sind das:\n\n- Mathematik und Wirtschaftsmathe (Nebenfächer Wirtschaftswissenschaften oder VWL)\n- Geographie (Nebenfächer BWL, VWL oder SOWI)\n\nAn der Humanwissenschaftlichen Fakultät ist das der Studiengang:\n\n- Psychologie (Interdisziplinäre Vernetzung BWL oder VWL oder Sozialwissenschaften)\n\n## 3. Welche Masterstudiengänge können an der WiSo-Fakultät studiert werden?\n\nFolgenden Masterstudiengänge werden an der WiSo-Fakultät angeboten:\n\n- Business Administration (mit 5 verschiedenen Spezialisierungen)\n- International Management (CEMS MIM)\n- Business Analytics and Econometrics\n- Economics\n- Economic Research\n- Politikwissenschaft\n- Sociolog'] | H6: ['https://wiso.uni-koeln.de/de/studium/bachelor', 'https://wiso.uni-koeln.de/de/studium/studienorganisation/faq/bachelor', 'https://wiso.uni-koeln.de/en/studies/organising-your-studies/faq/bachelor', 'https://wiso.uni-koeln.de/de/studium/bachelor/bachelor-wirtschaftsinformatik', 'https://wiso.uni-koeln.de/de/studium/studienorganisation/faq/allgemeine-fragen'] | I6: ['html', 'html', 'html', 'html', 'html'] | J6: 1 | K6: =6/7 -> 0.85714286 | L6: 0.7 | M6: 0.66610816 | N6: =6/7 -> 0.85714286 | O6: 1 | P6: 0.14522821 | Q6: -0.065234184 | R6: 0.36939746 | S6: 1 | T6: 1 | U6: 20.277224 | V6: 3098 | W6: 330 | X6: 3428 | Y6: 0 | Z6: 5 | AA6: 20.277224
A7: 30 | B7: Bachelor-Studium | C7: easy | D7: Wo finden internationale Studieninteressierte Informationen zum Bewerbungsverfahren für einen WiSo-Bachelor? | E7: Die Bewerbung für einen WiSo-Bachelor als internationaler Studieninteressierter kann wie folgt erfolgen: 1. Besuchen Sie die Website der Universität zu Köln und navigieren Sie zur Fakultät für Wirtschafts- und Sozialwissenschaften (WiSo). 2. Klicken Sie auf "Bewerbung" oder "Studieninteressierte" und wählen Sie den Bachelor-Studiengang aus, für den Sie sich interessieren. 3. Lesen Sie die Informationen zum Bewerbungsverfahren und den Anforderungen sorgfältig durch. 4. Füllen Sie das Online-Bewerbungsformular aus und laden Sie alle erforderlichen Dokumente hoch. Es ist ratsam, vor der Bewerbung die Website der Universität zu Köln und der WiSo-Fakultät regelmäßig zu besuchen, um sicherzustellen, dass Sie die aktuellsten Informationen haben. | F7: Internationale Studieninteressierte sollen sich vor der Bewerbung beim International Office der Universität zu Köln über das Bewerbungsverfahren informieren. Der Link zum International Office ist auf der WiSo-Bachelor-Bewerbungsseite hinterlegt. | G7: ['# Bewerbung\n\nSie interessieren sich für unsere Bachelor- oder Masterprogramme, oder möchten an der WiSo-Fakultät promovieren? Auf den folgenden Seiten Sie Informationen rund um das Thema Bewerbung. Klicken Sie auf den Bereich, der Sie interessiert.\n\n## Bachelor\n\n## Master\n\n## Promotion\n\nHI\n\nzum Seitenanfang', "offered at the WiSo-Faculty via these links:\nBachelor's programme\nMaster's programme\n\n> The inter-, multi- and trans-disciplinary approach of the WiSo Faculty is deeply embedded in all our programmes. The wide range of subjects offers every student the opportunity to define their career direction. The international and intercultural environment is ideal for your professional and personal development.\n\nHI\n\nTo top of page", 'serer internationalen Fakultätsmitglieder integrieren wir gezielt englischsprachige Kursangebote in unsere Bachelor-Studiengänge und stärken Ihre internationale Kommunikationsfähigkeit in Fachfragen in einer Disziplin, deren Fachsprache Englisch ist. Englischsprachige Angebote sind gleichzeitig auch besonders attraktiv für Incoming-Studierende aus dem Ausland. Gemeinsame Kursbesuche mit Incomings eröffnen Ihnen vor Ort die Möglichkeit, sich mit unseren internationalen Studierenden bekannt zu machen.\n\n### Englischsprachige Fachliteratur\n\nIhre Englischkenntnisse, die Sie zum Studium mitbringen, sind äußerst nützlich, um englischsprachige Lehrbuch- und Fachliteratur zu lesen. Aktuelle Forschungsergebnisse werden in der Regel in englischer Sprache publiziert und sollen von den Bachelorstudierenden in Seminaren und Projekten verarbeitet werden. Das Studium wird in ausgewählten Bereichen, jedoch nicht zur Gänze, in englischer Sprache abgelegt.\n\n### Optionales Auslandssemester\n\nDie WiSo-Fakultät ist Mitglied in mehreren Netzwerken internationaler Universitäten, was Ihnen dabei hilft, ein Semester an einer der über 80 renommierten Partnerhochschulen im Ausland mit einem Kursangebot in Volkswirtschaftslehre zu verbringen. Das Programm ist so konzipiert, dass Sie im vierten oder fünften Semester ein Auslandssemester absolvieren können. Wir beraten Sie gerne über Ihre Möglichkeiten und unterstützen Sie organisatorisch vor, während und nach Ihrem Auslandsaufenthalt.\n\n### Eine internation', 'cal problems.\n\nTo top of page\n\nStill undecided?\n\nThen get to know our offers for prospective students, which are coordinated by the WiSo Student Service Point and will provide you with individual advice tailored precisely to your needs.\n\n- Orientation and counselling services for prospective students\n\n## Academic excellence meets international scope\n\n### International orientation throughout the entire course of study\n\nWe receive applications from a large number of different nationalities for the majority of our degree programmes, so a large international and intercultural environment exists both at the faculty and within your degree programme. A large number of courses are therefore offered in English, depending on the specialisation. \xa0\xa0\xa0\n\n### Optional semester abroad\n\nThe WiSo Faculty is a member of several networks of international universities, which assists you in spending a semester abroad at a renowned partner university. The programme is designed so that you can spend a semester abroad in your fourth or fifth semester. We are happy to advise you on your options and provide you with organisational support before, during and after your exchange. \xa0\xa0 \xa0\xa0\xa0 \xa0\xa0\xa0 \xa0\xa0\xa0 \xa0\n\n### An opportunity for global networking\n\nWith its balanced theoretical and practical approach, the degree programme prepares you for entry into internationally oriented professions and enables you to work in an international environment. Additionally, the WiSo Faculty has a broad alumni network of former studen', 'in ein Postgraduierten-Programm (Ph.D.).\n\nGleichzeitig ist der Master-of-Science-Abschluss natürlich eine hervorragende Basis für die Bewerbung für Graduiertenstudiengänge an anderen nationalen und internationalen Universitäten.\n\nzum Seitenanfang\n\n##### .\n\n## Bewerbung\n\n\xa0\n\nAlle Infos zur Masterbewerbung an der WiSo-Fakultät.\n\n##### ...\n\n## Weitere Informationen und Kontakt\n\nWir unterstützen Sie gerne bei Ihren Ambitionen:\n\nBei Interesse oder Fragen zu unseren WiSo-Studiengängen helfen die Studienberater:innen im WiSo Student Service Point gerne weiter:\n\n- WiSo Student Service Point - Hotline: +49 (0) 221/470-8818\n- www.wiso-studentservice.uni-koeln.de\n\nzum Seitenanfang\n\nHI\n\nzum Seitenanfang'] | H7: ['https://wiso.uni-koeln.de/de/studium/bewerbung', 'https://wiso.uni-koeln.de/en/studies/application/studying-at-the-wiso-faculty', 'https://wiso.uni-koeln.de/de/studium/bachelor/bachelor-vwl', 'https://wiso.uni-koeln.de/en/studies/bachelor/information-systems', 'https://wiso.uni-koeln.de/de/studium/master/master-business-administration/corporate-development'] | I7: ['html', 'html', 'html', 'html', 'html'] | J7: 0 | K7: 0 | L7: 0 | M7: 0.81118953 | N7: 0 | O7: 0.25 | P7: 0.243762 | Q7: 0.061681412 | R7: 0.43517283 | S7: 0 | T7: 0 | U7: 16.67166 | V7: 2555 | W7: 244 | X7: 2799 | Y7: 0 | Z7: 5 | AA7: 16.67166
A8: 33 | B8: Studiengang spezifisch | C8: easy | D8: Welche Bewerbungsfrist gilt für den Master Studiengang Information Systems? | E8: Die Bewerbungsfrist für den Master Studiengang Information Systems ist der 15. Juni. | F8: Für den Masterstudiengang Information Systems gilt eine Bewerbungsfrist bis zum 15. Juni | G8: ['Master of Science\n\n# Master Information Systems\n\nDoppelqualifikation in Betriebswirtschaftslehre und Informatik\n\nDiese Website wird derzeit bis voraussichtlich Dezember für das Bewerbungsverfahren 2026 überarbeitet.\xa0\n\nWenn Sie sich\xa0über spezifische Details in dem\xa0Masterstudiengang Information Systems informieren möchten, klicken Sie bitte\xa0hier.\n\n## Informationen zur Bewerbung\n\n## Bewerbungsfrist\n\nAb Mitte April bis zum 15. Juni bewerben Sie sich ausschließlich online über das Campusmanagement System\xa0KLIPS.\n\n- Alle fachlichen und sprachlichen Anforderungen müssen zum Zeitpunkt der Bewerbung erfüllt sein.\n- Alle erforderlichen Unterlagen müssen zum Zeitpunkt der Bewerbung eingereicht werden.\n- Nachgereichte Unterlagen nach Ablauf der Bewerbungsfrist werden nicht akzeptiert.\n\n## Fachliche Anforderungen\n\nUm am Auswahlverfahren teilzunehmen, müssen folgende fachliche Anforderungen erfüllt sein:\n\nAbgeschlossenes Bachelorstudium\nAbgeschlossenes Bachelorstudium, das dem ausgewählten Masterstudium fachlich entspricht.\n\nBei nicht abgeschlossenem Bachelorstudium müssen mindestens 80% der zu erwerbenden Leistungspunkte erfolgreich erbracht sein. Die noch ausstehenden Leistungen sind bis spätestens 30. September zu absolvieren.\n\nBachelornote keine Mindestnote\n\nfachliche Zugangsvoraussetzungen\n\nHinweise zur Einordnung der Kurse\n\n1. mindestens 20 ECTS aus dem Fachgebiet Information Systems bzw. Wirtschaftsinformatik\n2. mindestens 30 ECTS aus dem Fachgebiet Wirtschaftswissenschaften\n3. minde', "Master of Science\n\n# Master Information Systems\n\nDouble Qualification in Business Studies and Computer Science\n\nThis website is currently being revised for the 2026 application process and is expected to be completed in December.\n\nIf you would like to find out more about the specific details of the master's programme Information Systems, please click here.\n\n## Application information\n\n## Application deadline\n\nFrom mid-April until 15 June, you apply exclusively online via the campus management system\xa0KLIPS.\n\n- At the time of application, all subject and language requirements must be met.\n- At the time of application, all documents must be provided in either German or in English.\n- Documents submitted after the application deadline will not be accepted.\n\n## Subject-related requirements\n\nTo take part in the selection procedure, the subject-related admission requirements must be met:\n\nCompleted bachelor's degree\nCompleted Bachelor's degree programme that corresponds to the subject of the selected Master's degree programme.\n\nIf you have not completed your bachelor's degree, at least 80% of the credit points to be earned must be completed. The pending examinations must be completed by 30 September at the latest.\n\nBachelor's grade no minimum grade required\n\nSubject-related requirements\n\nspecifications on the allocation of courses to the subject areas\n\n1. at least\xa020 ECTS credits in the field of Infomation Systems\n2. at\xa0least 30 ECTS credits in\xa0the field of Business Administration an", 'Master of Science\n\n# Master International Management (CEMS MIM)\n\nDer Schlüssel für Ihre zukünftige Karriere in einem globalen Arbeitsumfeld\n\nDiese Website wird derzeit bis voraussichtlich Dezember für das Bewerbungsverfahren 2026 überarbeitet.\xa0\n\nWenn Sie\xa0sich über spezifische Details in dem Masterstudiengang International Management (CEMS MIM) informieren möchten, klicken Sie bitte\xa0hier.\n\n## Informationen zur Bewerbung\n\n## Bewerbungsfrist\n\nAb Mitte Januar bis zum 31. März bewerben Sie sich ausschließlich online über das Campusmanagement System\xa0KLIPS.\n\n- Alle fachlichen und sprachlichen Anforderungen müssen zum Zeitpunkt der Bewerbung erfüllt sein.\n- Alle erforderlichen Unterlagen müssen zum Zeitpunkt der Bewerbung eingereicht werden.\n- Nachgereichte Unterlagen nach Ablauf der Bewerbungsfrist werden nicht akzeptiert.\n\n## Fachliche Anforderungen\n\nUm am Auswahlverfahren teilzunehmen, müssen folgende fachliche Anforderungen erfüllt sein:\n\nAbgeschlossenes Bachelorstudium\nAbgeschlossenes Bachelorstudium, das dem ausgewählten Masterstudium fachlich entspricht.\n\nBei nicht abgeschlossenem Bachelorstudium müssen mindestens 70 % der zu erwerbenden Leistungspunkte erfolgreich erbracht sein. Die noch ausstehenden Leistungen sind bis spätestens 30. September zu absolvieren.\n\nBachelornote mindestens 2,5\n\nfachliche Zugangsvoraussetzungen\n\nHinweise zur Einordnung der Kurse\n\n1. mindestens 48 ECTS aus dem Fachgebiet Betriebswirtschaftslehre\n2. mindestens 10 ECTS aus dem Fachgebiet Volkswirtscha', "Master of Science\n\n# Master International Management (CEMS MIM)\n\nThe key to your future career in a global business environment\n\nThis website is currently being revised for the 2026 application process and is expected to be completed in December.\n\nIf you would like to find out more about the specific details of the master's programme International Management (CEMS MIM), please click here.\n\n## Application information\n\n## Application deadline\n\nFrom mid-January until 31 March, you apply exclusively online via the campus management system\xa0KLIPS.\n\n- At the time of application, all subject and language requirements must be met.\n- At the time of application, all documents must be provided in either German or in English.\n- Documents submitted after the application deadline will not be accepted.\n\n## Subject-related requirements\n\nTo take part in the selection procedure, the subject-related admission requirements must be met:\n\nCompleted bachelor's degree\nCompleted Bachelor's degree programme that corresponds to the subject of the selected Master's degree programme.\n\nIf you have not completed your bachelor's degree, at least 70% of the credit points to be earned must be completed. The pending examinations must be completed by 30 September at the latest.\n\nBachelor's grade at least 2.5 (German grading system)\n\nSubject-related requirements\n\nspecifications on the allocation of courses to the subject areas\n\n1. at least 48 ECTS in the field of Business Administration/ Management\n2. at least 10", 'Master of Science\n\n# Master Information Systems\n\nDoppelqualifikation in Betriebswirtschaftslehre und Informatik\n\n## Inhaltsverzeichnis\n\n- Überblick\n- Ihre Vorteile auf einen Blick\n- Für wen ist das Programm geeignet?\n- Programmübersicht\n- Akademische Exzellenz mit internationalem Angebot\n- Karrieremöglichkeiten\n- Bewerbung\n- Weitere Informationen und Kontakt\n\nWenn Sie bereits den Masterstudiengang Information Systems absolvieren und sich über spezifische Details informieren möchten, besuchen Sie bitte die Seite zum Studienaufbau.\n\n## Überblick\n\nAbschluss: Master of Science\n\nDauer 4 Semester, Vollzeit\n\nCredits: 120 ECTS\n\nSprache: Englisch und Deutsch (in ausgewählten Kursen)\n\nInhalt: Interdisziplinäre Disziplin der Betriebswirtschaftslehre und Informatik, die sich mit der Konzeption, Entwicklung und Anwendung von Informationssystemen in Wirtschaft, Verwaltung und zunehmend auch im privaten Bereich beschäftigt.\n\nInternational: Auslandssemester, Summer School (optional)\n\nBewerbungsfrist: 15.06.\n\n## Master-Virtueller Infotag\n\nBitte HIER ANMELDEN, um am virtuellen Master-Infotag teilzunehmen. Nutzen Sie die Gelegenheit, mehr über die WiSo-Fakultät zu erfahren, die Studienprogramme zu erkunden und wertvolle Einblicke von Professor:innen, aktuellen Studierenden und Alumni zu gewinnen.\n\n## Ihre Vorteile auf einen Blick:\n\n- theoretische und methodische Grundlagen für die Auseinandersetzung mit zentralen Themen wie Data Science, digitale Transformation und Innovation, Prozesse und Gesc'] | H8: ['https://wiso.uni-koeln.de/de/studium/bewerbung/master/master-information-systems', 'https://wiso.uni-koeln.de/en/studies/application/master/master-information-systems', 'https://wiso.uni-koeln.de/de/studium/bewerbung/master/master-international-management-cems-mim', 'https://wiso.uni-koeln.de/en/studies/application/master/master-international-management-cems-mim', 'https://wiso.uni-koeln.de/de/studium/master/master-information-systems'] | I8: ['html', 'html', 'html', 'html', 'html'] | J8: 1 | K8: 1 | L8: 0.87 | M8: 0.97693004 | N8: 1 | O8: 1 | P8: 0.7211951 | Q8: 0.72738326 | R8: 0.71378559 | S8: 0.2 | T8: 1 | U8: 7.8358102 | V8: 3332 | W8: 50 | X8: 3382 | Y8: 0 | Z8: 5 | AA8: 7.8358102
