Workbook

Sheet Tabelle1
A1: gpt-4.1-mini
B3: run1 | C3: run2 | D3: run3 | E3: min | F3: max | G3: Schwankung | I3: Durchschnitt | K3: Rangkorrelation aus Validation | L3: Pearson-Korrelation aus Validation | M3: p-Value
A4: faithfulness | B4: 0.66156887 | C4: 0.6679912 | D4: 0.66501745 | E4: =MIN(B4:D4) -> 0.66156887 | F4: =MAX(B4:D4) -> 0.6679912 | G4: =(F4-E4)*100 -> 0.64223313 | I4: =AVERAGE(B4:D4) -> 0.66485918 | J4: faithfulness | K4: 0.53558363 | L4: =PEARSON('[1]Human Details'!$J$2:$J$16, '[1]gpt-4.1-mini-Details'!$J$2:$J$16) -> 0.73322698 | M4: =_xlfn.T.TEST('Human Details'!J2:J16, 'gpt-4.1-mini Details'!J2:J16,2,1) -> 0.079559261
A5: context_recall | B5: 0.62444581 | C5: 0.62875616 | D5: 0.64269294 | E5: =MIN(B5:D5) -> 0.62444581 | F5: =MAX(B5:D5) -> 0.64269294 | G5: =(F5-E5)*100 -> 1.8247126 | I5: =AVERAGE(B5:D5) -> 0.63196497 | J5: context_recall | K5: 0.58594568 | L5: =PEARSON('[1]Human Details'!$K$2:$K$16, '[1]gpt-4.1-mini-Details'!$K$2:$K$16) -> 0.56215487 | M5: =_xlfn.T.TEST('Human Details'!K2:K16, 'gpt-4.1-mini Details'!K2:K16,2,1) -> 0.28661465
A6: context_precision | B6: 0.62411398 | C6: 0.60958937 | D6: 0.62180316 | E6: =MIN(B6:D6) -> 0.60958937 | F6: =MAX(B6:D6) -> 0.62411398 | G6: =(F6-E6)*100 -> 1.4524613 | I6: =AVERAGE(B6:D6) -> 0.61850217 | J6: context_precision | K6: 0.50327669 | L6: =PEARSON('[1]Human Details'!$L$2:$L$16, '[1]gpt-4.1-mini-Details'!$L$2:$L$16) -> 0.5510758 | M6: =_xlfn.T.TEST('Human Details'!L2:L16, 'gpt-4.1-mini Details'!L2:L16,2,1) -> 0.08474845
A7: semantic_similarity | B7: 0.75828298 | C7: 0.75907 | D7: 0.75907 | E7: =MIN(B7:D7) -> 0.75828298 | F7: =MAX(B7:D7) -> 0.75907 | G7: =(F7-E7)*100 -> 0.07870209 | I7: =AVERAGE(B7:D7) -> 0.75880766 | J7: semantic_similarity | K7: 0.2452823 | L7: =PEARSON('[1]Human Details'!$M$2:$M$16, '[1]gpt-4.1-mini-Details'!$M$2:$M$16) -> 0.26938296 | M7: =_xlfn.T.TEST('Human Details'!M2:M16, 'gpt-4.1-mini Details'!M2:M16,2,1) -> 3.3677966e-05
A8: context_entity_recall | B8: 0.27292447 | C8: 0.27443563 | D8: 0.2611677 | E8: =MIN(B8:D8) -> 0.2611677 | F8: =MAX(B8:D8) -> 0.27443563 | G8: =(F8-E8)*100 -> 1.3267928 | I8: =AVERAGE(B8:D8) -> 0.26950927 | J8: context_entity_recall | K8: 0.40351567 | L8: =PEARSON('[1]Human Details'!$N$2:$N$16, '[1]gpt-4.1-mini-Details'!$N$2:$N$16) -> 0.36082996 | M8: =_xlfn.T.TEST('Human Details'!N2:N16, 'gpt-4.1-mini Details'!N2:N16,2,1) -> 0.69885498
A9: answer_relevancy | B9: 0.59892572 | C9: 0.60156607 | D9: 0.59534115 | E9: =MIN(B9:D9) -> 0.59534115 | F9: =MAX(B9:D9) -> 0.60156607 | G9: =(F9-E9)*100 -> 0.6224927 | I9: =AVERAGE(B9:D9) -> 0.59861098 | J9: answer_relevancy | K9: 0.44812488 | L9: =PEARSON('[1]Human Details'!$O$2:$O$16, '[1]gpt-4.1-mini-Details'!$O$2:$O$16) -> 0.46513088 | M9: =_xlfn.T.TEST('Human Details'!O2:O16, 'gpt-4.1-mini Details'!O2:O16,2,1) -> 0.17697203
A10: MRR@5 | B10: 0.3466954 | C10: 0.3466954 | D10: 0.3466954 | E10: =MIN(B10:D10) -> 0.3466954 | F10: =MAX(B10:D10) -> 0.3466954 | G10: =(F10-E10)*100 -> 0 | I10: =AVERAGE(B10:D10) -> 0.3466954
A11: Hit@5 | B11: 0.50862069 | C11: 0.50862069 | D11: 0.50862069 | E11: =MIN(B11:D11) -> 0.50862069 | F11: =MAX(B11:D11) -> 0.50862069 | G11: =(F11-E11)*100 -> 0 | I11: =AVERAGE(B11:D11) -> 0.50862069
A12: latency | B12: 12.829804 | C12: 12.829804 | D12: 12.829804 | E12: =MIN(B12:D12) -> 12.829804 | F12: =MAX(B12:D12) -> 12.829804 | G12: =(F12-E12)*100 -> 0 | I12: =AVERAGE(B12:D12) -> 12.829804
J13: =PEARSON('[1]Human Details'!$J$2:$J$16, '[1]gpt-4.1-mini-Details'!$J$2:$J$16) -> 0.73322698 | K13: =PEARSON('[1]Human Details'!$K$2:$K$16, '[1]gpt-4.1-mini-Details'!$K$2:$K$16) -> 0.56215487 | L13: =PEARSON('[1]Human Details'!$L$2:$L$16, '[1]gpt-4.1-mini-Details'!$L$2:$L$16) -> 0.5510758 | M13: =PEARSON('[1]Human Details'!$M$2:$M$16, '[1]gpt-4.1-mini-Details'!$M$2:$M$16) -> 0.26938296 | N13: =PEARSON('[1]Human Details'!$N$2:$N$16, '[1]gpt-4.1-mini-Details'!$N$2:$N$16) -> 0.36082996 | O13: =PEARSON('[1]Human Details'!$O$2:$O$16, '[1]gpt-4.1-mini-Details'!$O$2:$O$16) -> 0.46513088
A15: qwen2.5:7b
B17: run1 | C17: run2 | D17: run3 | I17: Durchschnitt | J17: Rangkorrelation aus Validation | K17: Pearson-Korrelation aus Validation | L17: p-Value
A18: faithfulness | B18: 0.64263006 | C18: 0.63493628 | D18: 0.63637491 | I18: =AVERAGE(B18:D18) -> 0.63798042 | J18: =0.57370678 -> 0.57370678 | K18: =0.65302115 -> 0.65302115 | L18: =_xlfn.T.TEST('Human Details'!J2:J16, 'qwen Details'!J2:J16,2,1) -> 0.5863355
A19: context_recall | B19: 0.68697723 | C19: 0.69513547 | D19: 0.69039409 | I19: =AVERAGE(B19:D19) -> 0.69083559 | J19: =0.74415851 -> 0.74415851 | K19: =0.73529279 -> 0.73529279 | L19: =_xlfn.T.TEST('Human Details'!K2:K16, 'qwen Details'!K2:K16,2,1) -> 0.26913217
A20: context_precision | B20: 0.71522947 | C20: 0.71342193 | D20: 0.71805556 | I20: =AVERAGE(B20:D20) -> 0.71556899 | J20: =0.22305764 -> 0.22305764 | K20: =0.41218722 -> 0.41218722 | L20: =_xlfn.T.TEST('Human Details'!L2:L16, 'qwen Details'!L2:L16,2,1) -> 0.27693847
A21: semantic_similarity | B21: 0.76445786 | C21: 0.76511235 | D21: 0.76511235 | I21: =AVERAGE(B21:D21) -> 0.76489419 | J21: =0.04769378 -> 0.04769378 | K21: =0.14385935 -> 0.14385935 | L21: =_xlfn.T.TEST('Human Details'!M2:M16, 'qwen Details'!M2:M16,2,1) -> 5.6580739e-05
A22: context_entity_recall | B22: 0.11283209 | C22: 0.11317209 | D22: 0.11348339 | I22: =AVERAGE(B22:D22) -> 0.11316252 | J22: =0.45819723 -> 0.45819723 | K22: 0.16880378 | L22: =_xlfn.T.TEST('Human Details'!N2:N16, 'qwen Details'!N2:N16,2,1) -> 0.02862346
A23: answer_relevancy | B23: 0.53499108 | C23: 0.53717342 | D23: 0.53762224 | I23: =AVERAGE(B23:D23) -> 0.53659558 | J23: =-0.14656358 -> -0.14656358 | K23: =0.37830878 -> 0.37830878 | L23: =_xlfn.T.TEST('Human Details'!O2:O16, 'qwen Details'!O2:O16,2,1) -> 0.26703064
A24: MRR@5 | B24: 0.31057971 | C24: 0.31652299 | D24: 0.31652299 | I24: =AVERAGE(B24:D24) -> 0.3145419
A25: Hit@5 | B25: 0.46086957 | C25: 0.46551724 | D25: 0.46551724 | I25: =AVERAGE(B25:D25) -> 0.46396802
A26: latency | B26: 11.527936 | C26: 11.658797 | D26: 11.658797 | I26: =AVERAGE(B26:D26) -> 11.615177

Sheet Human Details
A1: id | B1: category | C1: difficulty | D1: user_input | E1: response | F1: reference | G1: retrieved_contexts | H1: retrieved_urls | I1: retrieved_content_types | J1: faithfulness | K1: context_recall | L1: context_precision | M1: semantic_similarity | N1: context_entity_recall | O1: answer_relevancy | P1: RR_at5 | Q1: hit_at5 | R1: latency | S1: context_count | T1: response_time_seconds | U1: Entitäten (Referenz) | V1: Gedeckte Entitäten (Retrieved Context) | W1: Nicht gedeckte Entitäten (Retrieved Context) | X1: Anzahl Gedeckte Entitäten (Retrieved Context) | Y1: Anzahl nicht-gedeckter Entitäten (Retrieved Context) | Z1: Anmerkungen
A2: 1 | B2: Allgemein | C2: medium | D2: Inwiefern würde ich als Student von einem Studium an der WiSo-Fakultät profitieren? | E2: Als Student von einem Studium an der WiSo-Fakultät profitieren Sie in mehreren Aspekten: 1. **Renommierte Fakultät**: Die WiSo-Fakultät ist eine der renommiertesten Fakultäten für Wirtschafts- und Sozialwissenschaften in Europa, was Ihnen Zugang zu einer hervorragenden Ausbildung bietet. 2. **Breite Palette an Studiengängen**: Die Fakultät bietet eine Vielzahl von Studiengängen an, die sich auf verschiedene Bereiche der Wirtschafts- und Sozialwissenschaften konzentrieren, wie z.B. Betriebswirtschaftslehre, Volkswirtschaftslehre, Politikwissenschaft oder Soziologie. 3. **Exzellente Lehre**: Die WiSo-Fakultät ist bekannt für ihre exzellente Lehre, die durch erfahrene und renommierte Professoren und wissenschaftliche Mitarbeiter garantiert wird. 4. **Gutes Netzwerk**: Durch die enge Kooperation mit führenden Organisationen und Universitäten bietet die WiSo-Fakultät ein hervorragendes Netzwerk für Ihre beruflichen und persönlichen Ziele. 5. **Hohe Karriere- und Berufschancen**: Die Absolventen der WiSo-Fakultät genießen eine hohe Reputation auf dem Arbeitsmarkt, was Ihnen gute Karriere- und Berufschancen bietet. Insgesamt bietet ein Studium an der WiSo-Fakultät der Universität zu Köln eine hervorragende Ausbildung, ein breites Angebot an Studiengängen, exzellente Lehre, ein gutes Netzwerk und hohe Karriere- und Berufschancen. | F2: Als Student profitierst du von einem theorie- und methodenorientierten Studienansatz, in dem Forschung und Lehre eng mit der Praxis verzahnt sind, sowie von der ausgeprägten Praxisnähe durch die langjährige Zusammenarbeit der WiSo-Fakultät mit Unternehmen und Lehrbeauftragten aus verschiedenen Berufsfeldern. | G2: ['# Erstsemesterinformationen\n\n##### Herzlich willkommen an der WiSo-Fakultät der Universität zu Köln!\n\nWir freuen uns sehr, dass Sie sich für ein Studium bei uns an der Wirtschafts- und Sozialwissenschaftlichen (kurz: WiSo) Fakultät entschieden haben. Sie erwartet ein spannendes Studium an einer der renommiertesten Fakultäten für Wirtschafts- und Sozialwissenschaften in einer attraktiven Stadt mit sehr guten Karriere- und Berufsperspektiven.\n\n## Infos zum WiSo-Studienstart\n\n## WiSo Welcome und Vorkurse Bachelor\n\n## WiSo Master Welcome Week\n\nHI\n\nzum Seitenanfang', 'inen der bedeutendsten Wirtschaftsstandorte in Deutschland dar.\n\n## Sie interessieren sich für ein Studium an der WiSo-Fakultät?\n\nPaco, deine künstliche Intelligenz zum Studium an der WiSo-Fakultät der Universität zu Köln, beantwortet dir jederzeit alle faktenbasierten Fragen zu deinem Wunschstudiengang! - Du suchst schnelle Infos zu, Zulassungsverfahren oder allgemeinen Fragen zur Universität zu Köln?\n\nDann ist Paco genau das Richtige für dich!*\n\nUnsere WiSo-Fakultät bietet:\n\nEinzigartige Fächervielfalt\nJe nach Interesse und Fähigkeiten können Sie aus dem umfangreichen Spektrum einer der renommiertesten Wirtschafts- und Sozialwissenschaftlichen Fakultäten Deutschlands wählen.\n\nExzellente Qualität in Lehre und Forschung\nDie WiSo-Fakultät belegt kontinuierlich die vordersten Plätze in zahlreichen namhaften Rankings, z.B. im „Handelsblatt“ und in der „Wirtschaftswoche“.\n\nAusgezeichnete Berufs- und Weiterbildungsaussichten\nNutzen Sie Ihren erfolgreich absolvierten Bachelorabschluss als vielversprechenden Ausgangspunkt für Ihre berufliche Karriere oder bewerben Sie sich für den konsekutiven Master.\n\nHervorragende Services und Betreuung\nDas WiSo-Studienberatungszentrum berät Sie gerne persönlich über den Studienverlauf, der WiSo-Career-Service unterstützt Sie bei der Vorbereitung Ihres Berufseinstiegs.\n\nEngagiertes Studentenleben\nDas dynamische Campusleben und eine Vielzahl studentischer Initiativen (z.B. der internationale OFW-Kongress) ermöglichen es Ihnen, Einsatz und Engagemen', 'n und energiewirtschaftlichen Themen, die mich geprägt haben. Der Ruf und das Netzwerk der WiSo haben mir den Einstieg in den Beruf erleichtert. Die fundamentalen Fähigkeiten, die ich für meinen Beruf brauche und die mir von anspruchsvollen Lehrkräften an einer renommierten Hochschule vermittelt wurden, helfen mir bis heute. – Dr. Dirk Schmelzer, Chief Financial Officer der Scout 24 SE\n\n-\n\nIch bin stolz darauf, ein Alumnus der Wirtschafts- und Sozialwissenschaftlichen Fakultät der Universität zu Köln zu sein, an der ich ein Studium der Betriebswirtschaftslehre absolviert habe. Das Wissen, die Fähigkeiten und die Erfahrungen, die ich während meiner Zeit an der WiSo gesammelt habe, sind für meinen beruflichen Werdegang von unschätzbarem Wert gewesen. Ich empfehle ein Studium an der WiSo-Fakultät jedem, der eine umfassende Ausbildung und eine solide Grundlage für eine erfolgreiche Karriere in der Geschäftswelt sucht. – Henning Gieseke, Chief Financial Officer der Ströer Management AG\n\nHI\n\nzum Seitenanfang', 'en. Eine Orientierung zu weiteren Kosten Sie u.a. hier.\n\n## 5. Was zeichnet das Studium an der Wiso Fakultät aus?\n\nEin Studium an der WiSo-Fakultät der Universität zu Köln stellt eine hervorragende Ausgangsbasis für Ihre weiteren professionellen und persönlichen Pläne dar. Mit ca. 9.000 Studierenden und einer Vielzahl an Professuren und wissenschaftlichen Mitarbeitern ist die Fakultät eine der wissenschaftlich renommiertesten Fakultäten für Wirtschafts- und Sozialwissenschaften in Europa.\n\nEntscheidende Rankings bewerten die Qualität von Forschung und Lehre an Hochschulen und der Fakultätsentwicklung anhand verschiedener Kriterien. Die WiSo-Fakultät freut sich, ihre Position in vielen renommierten Rankings behaupten und in einigen Fällen ausbauen zu können.\n\nDie Verbindung von Forschung und Lehre, Theorie und Praxis, Wirtschafts- und Sozialwissenschaften begründet unser Leitbild: „Today\'s ideas. Tomorrow\'s impact". Innerhalb Ihres Studiums erarbeiten Sie mit Hilfe moderner Analysemethoden und Modelle neue Lösungsansätze für relevante wirtschafts- und sozialwissenschaftliche Zukunftsfragen.\n\nKöln ist nicht nur als Studienort eine attraktive Stadt. Sie ist weit über den Karneval hinaus für ihre vielfältige Kulturszene bekannt und stellt zusammen mit dem Umland einen der bedeutendsten Wirtschaftsstandorte in Deutschland dar.\n\n## Wenn Sie schon mal studiert haben\n\n## 1. Kann ich an der WiSo-Fakultät ein Studium aufnehmen, wenn ich einen gleichwertigen Studiengang bzw. eine dort v', 'herausragenden Netzwerks von Universitäten und kooperiert mit führenden Organisationen. Hierdurch haben wir eine hervorragende Reputation in Lehre, Forschung, und Praxistransfer der sich in unseren hervorragenden Rankings widerspiegelt.” Prof. Ulrich W. Thonemann, PhD Dekan der Wirtschafts- und Sozialwissenschaftlichen Fakultät © Lisa BellerZAHLEN UND FAKTEN DER WISO-FAKULTÄT Mit einem Studium an der WiSo-Fakultät der Universität zu Köln schaffen Sie sich eine hervorragende Basis für Ihren weiteren beruflichen und persönlichen Werdegang. Mit knapp 8.000 Studierenden und einer Vielzahl von Abteilungen und akademischen Mitarbeiter:innen ist die WiSo-Fakultät eine der größten und renommiertesten Einrichtungen für Management, Wirtschaft und Sozialwissenschaften in Europa. 8.735 nationale und internationale Studierende 168 Partneruniversitäten weltweit1 97 Professor:innen Über 100 Jahre an Erfahrung in exzellenter Lehre und Forschung Stand: Mai 2023 1 Die WiSo-Fakultät unterhält exzellente Partnerschaften mit 160 führenden Hochschulen auf der ganzen Welt auf verschiedenen Studienebenen und ermöglicht ihren Studierenden Auslandsaufenthalte im Rahmen verschiedener Studien- und Austauschprogramme. Die Studierenden können je nach gewähltem Studiengang aus einem attraktiven Angebot an Partnerhochschulen wählen.Im Rahmen Ihres Studiums erlernen Sie alles, was Sie für den nächsten Schritt in Ihrer Karriere benötigen. Als eine der größten Bildungseinrichtungen Deutschlands zählt die Fakul'] | H2: ['https://wiso.uni-koeln.de/de/studium/studienorganisation/erstsemester', 'https://wiso.uni-koeln.de/de/studium', 'https://wiso.uni-koeln.de/de/praxis/wisoalumni/tomorrows-impact', 'https://wiso.uni-koeln.de/de/studium/studienorganisation/faq/allgemeine-fragen', 'file://D:/Uni-Köln/Masterarbeit/Software/uzk-masterarbeit/data/pdf_cache/__wiso.uni-koeln.de_sites_fakultaet_dokumente_studium_bachelor_Broschuere-Bachelor_VWL-WiSo_Fakultaet-Uni-Koeln.pdf'] | I2: ['html', 'html', 'html', 'html', 'pdf'] | J2: 1 | K2: 1 | L2: 0.68 | M2: 0.75 | N2: =IFERROR(X2/(X2+Y2), 0) -> 0.45454545 | O2: 1 | P2: 0 | Q2: 0 | R2: 45.547115 | S2: 5 | T2: 45.547115 | U2: Student, Theorie- und methodenorientierter Studienansatz, Forschung, Lehre, Praxis, Praxisnähe, Langjährige Zusammenarbeit, WiSo-Fakultät, Unternehmen, Lehrbeauftragte, Berufsfelder | V2: Student, Forschung, Lehre, Praxis, WiSo-Fakultät | W2: Theorie- und methodenorientierter Studienansatz, Praxisnähe, Langjährige Zusammenarbeit, Unternehmen, Lehrbeauftragte, Berufsfelder | X2: 5 | Y2: 6 | Z2: Obwohl nicht die Gold-Referenz gefunden wurde, sind die Chunks sehr relevant. Im Grunde genommen zeigt dies, wie schwierig es ist tatsächlich ein RAG-System zu evaluieren. Der Testsatz ist bspw. Bei dieser Frage sehr gut auf den eigentlichen Inhalt zugeschnitten, aber die Gold-Referenz wird nicht gefetched. Stattdessen wird Context gefetched, der sehr relevant ist
A3: 8 | B3: Allgemein | C3: hard | D3: Welchen Vorteil bietet das Projekt E-PLUS? | E3: Das Projekt E-PLUS bietet mehrere Vorteile, darunter: * Eine höhere Motivation der Studierenden durch die Möglichkeit, Bonuspunkte zu sammeln und ihre Leistung in den Hausaufgaben zu verbessern. * Eine geringere Anzahl von Fehlern und Abbrüchen durch die Verwendung eines e-Hausaufgabensystems. Es ist jedoch wichtig zu beachten, dass diese Informationen aus der Universitäts-Wissensdatenbank stammen und möglicherweise nicht auf alle Studiengänge oder Semester anwendbar sind. Es wird empfohlen, sich direkt an die Studienberatung oder den zuständigen Dozenten zu wenden, um weitere Informationen zu erhalten. | F3: Das E-Assessment-Konzept von E-PLUS bietet den Vorteil, dass durch die von den Studierenden selbst eingebrachten, individuellen Aufgaben ein breit gefächerter Aufgabenpool entsteht, aus dem viele verschieden aufgebaute E-Probe-Klausuren zum intensiven Üben generiert werden können. Die Studierenden erhalten zu ihren Bearbeitungen direktes Feedback, können ihren Lernstand dadurch gezielt reflektieren und anpassen und Lehrende erkennen typische Schwachstellen, die sie in der Präsenzveranstaltung noch einmal aufgreifen. Gleichzeitig werden die eigentlichen Klausuren als individualisierte E-Prüfungen angeboten, die zeitlich sehr flexibel abgelegt werden können, sodass sich die Klausurtermine entzerren und der Prüfungsbetrieb organisatorisch wie administrativ entlastet wird. | G3: ['t further action is necessary.\n\nThe e-homework assignment tool also uses, if available, a bonus point system, which could have a positive effect on the mark for the final examination if the assignments are completed successfully. This increases student motivation and leads to lower fail and drop-out rates.\n\nThe e-homework assignment tool will be used by and by\xa0from winter semester 2017/18 on the following bachelor courses: "Basic Module Mathematics", "Basic Module Microeconomics", "Basic Module Statistics","Advanced Module Statistics" and "Basic Module Fundamentals of Economics". In the long term, the plan is to expand the project both within the Faculty and University-wide to take in other courses in which quantitative mathematical or statistical methods are applied.\n\n## AufbaU: Tasks in Business Administration classes\n\nThe aim of the project - led by Prof. Dr. Matthias Pilz, holder of the Chair for Business and Economic Education and Training - is to optimise application-oriented learning tasks on the mass bachelor degree programme in Business Administration and to expand lecturers’ task-construction skills.\nIn contrast to pure exercises, these learning tasks not only allow students to revise and practise what they have learned in the lectures, but also to develop new competencies, based on the application of the acquired knowledge to solve real problems.\n\nAs part of this project, the first step in the 2017 summer term was to analyse the existing learning tasks in selected', 'loped project management solutions. ... apply modern methods of project planning and project execution such as agile or help-based project management systems ... apply real options thinking to determine the value of uncertain projects. ... recommend project approaches to cope with uncertainty, complexity, and human behavior while accounting for the multidimensional goals of project stakeholders 4 Teaching and Learning Methods lecture practice 5 Module Entry Requirements Recommended: at least 12 ECTS credits from the group Foundation Knowledge 6 Mode of End-Of-Module Examination Written test: PO 7 Prerequisites for Awarding of Credit Points Passing the written test. 8 Other Programmes that Use the Module Master of Science Business Administration - Supply Chain Management: Specialization Section Supply Chain Management Master of Science Mathematik: MA Business and Economics Sciences Mathematics Master of Science Economics: Supplementary Section Master of Science Wirtschaftsmathematik: MA Business and Economics Sciences Mathematics --- Page 209 --- valid for students of the ER 2015 (enrolment for winter semester 2020/21 at the latest) MODULE CATALOGUE - ECONOMICS - MASTER OF SCIENCE 205 Master of Science International Management: Core and Advanced Section International Management Supplementary Section International Management Master of Education Wirtschaftspädagogik/Lehramt an Berufskollegs: Supplementary Section Business Education Master of Science Information Systems: Suppleme', 'nt: Supplementary Section Corporate Development Master of Science Information Systems: Specialisation Section Information Systems Master of Science Business Analytics & Econometrics: Supplementar y Section Business Analytics & Econometrics Master of Education Wirtschaftspädagogik/Lehramt an Berufskollegs: Ergänzungbereich Wirtschaftspädagogik 9 Module Manager Univ. -Prof. Dr. Wolf Ketter 10 Miscellaneous --- Page 116 --- valid for students of the ER 2021 (enrolment fr om winter semester 2021/22 ) BUSINESS ADMINISTRATION : ACCOUNTING AND TAXATION - MASTER OF SCIENCE 112 SpM Information Systems II Module Code 1277MSISY2 Workload 180h ECTS Credits 6 Module Language English Module Availability every term Duration 1 Term 1 Courses a) Emerging Electronic Business b) Digital Design c) IT Entrepreneurship d) Bayesian Data Analytics Contact Hours a) 45h b) 30h c) 50h d) 45h Self-Stu- dies a) 135h b) 150h c) 130h d) 135h Course Language a) English b) English c) English d) English 2 Module Content a) Emerging Electronic Business • Current IT trends and the transformation of electronic business into ""ambient business"" in the context of networked and computerised objects and environments (Internet of Things, smart En- vironments) • Conceptual basics of relevant technologies (inclu ding sensors, RFID, telecommunication) • Design and applications of smart environments • Design of intuitive human -computer interaction (HCI) • Context awareness and context -based services • Freely offering', 'eporting. ... analyse current questions and challenges in the area of sustainability/ESG reporting. ... assess and discuss findings and research results of specialized theories / methods. ... justify and defend (independently developed) positions or problem solutions. ... critically evaluate current social developments and develop alternative solutions. 4 Teaching and Learning Methods lecture practice 5 Module Entry Requirements none 6 Mode of End-Of-Module Examination Written test: WT (60) 7 Prerequisites for Awarding of Credit Points Passing the module examination 8 Other Programmes that Use the Module Master of Science Business Administration - Supply Chain Management: Supplementary Section Supply Chain Management Master of Science Business Administration - Marketing: Supplementary Section Marketing Master of Science Business Administration - Finance: Supplementary Section Finance Master of Science Information Systems: Supplementary Section Information Systems Master of Science Business Administration - Corporate Development: Supplementary Section Corporate Development Master of Science Informatik: Anwendungsfeld Master of Science Geographie: Wahlpflichtfach Management & Social Sciences --- Page 69 --- valid for students of the ER 2015 (enrolment for winter semester 2020/21 at the latest) BUSINESS ADMINISTRATION: Finance - MASTER OF SCIENCE 65 Master of Science Economics: Supplementary Section Management & Social Sciences Master of Science Mathematik: Economics Sciences Ma', 'e practice 5 Module Entry Requirements Recommendation: The basic modules Supply Ch ain Analytics I and II should have been completed. 6 Mode of End -Of-Module Examination Written test: PO 7 Prerequisites for Awarding of Credit Points Passing the module examination 8 Other Programmes that Use the Module Master of Science Business Administration - Supply Chain Management: Specialisation Section Supply Chain Management Master of Science Economics: Supplementary Section Management & Social Sciences Master of Science Business Administration - Accounting and Taxation: Supplementary Section Accounting and Taxation Master of Science Business Administration - Finance: Supplementary Section Finance Master of Science Business Administration - Marketing: Supplementary Section Marketing Master of Science Information Systems: Suppleme ntary Section Information Systems Master of Science Business Administration - Corporate Development: --- Page 85 --- valid for students of the ER 2021 (enrolment fr om winter semester 2021/22 ) INTERNATIONAL MANAGEMENT - MASTER OF SCIENCE 85 Supplementary Section Corporate Development Master of Science International Management: Supplementary Section International Management Master of Science Mathematik: Economics Sciences Master of Science Wirtschaftsmathematik: Economics Sciences Master of Science Informatik: Anwendungsfeld Master of Education Wirtschaftspädagogik/Lehramt an Berufskollegs: Ergänzungbereich Wirtschaftspädagogik 9 Module Manager Prof. Dr. Nico'] | H3: ['https://wiso.uni-koeln.de/en/studies/teaching-innovations', 'file://D:/Uni-Köln/Masterarbeit/Software/uzk-masterarbeit/data/pdf_cache/__wiso.uni-koeln.de_sites_fakultaet_dokumente_downloads_Modulhandbuecher_Studienjahr_22-23_MHB_PO2015_m_mhb_po2015_e_economics.pdf', 'file://D:/Uni-Köln/Masterarbeit/Software/uzk-masterarbeit/data/pdf_cache/__wiso.uni-koeln.de_sites_fakultaet_dokumente_downloads_master_Studienjahr_24-25_m_mhb_po2021_e_ba_accounting.pdf', 'file://D:/Uni-Köln/Masterarbeit/Software/uzk-masterarbeit/data/pdf_cache/__wiso.uni-koeln.de_sites_fakultaet_dokumente_downloads_Modulhandbuecher_Studienjahr_22-23_MHB_PO2015_m_mhb_po2015_e_ba_finance.pdf', 'file://D:/Uni-Köln/Masterarbeit/Software/uzk-masterarbeit/data/pdf_cache/__wiso.uni-koeln.de_sites_fakultaet_dokumente_downloads_master_Studienjahr_24-25_m_mhb_po2021_e_intmanagement.pdf'] | I3: ['html', 'pdf', 'pdf', 'pdf', 'pdf'] | J3: 0.5 | K3: 0 | L3: 1 | M3: 0 | N3: =IFERROR(X3/(X3+Y3), 0) -> 0 | O3: 0 | P3: 0 | Q3: 0 | R3: 10.0105 | S3: 5 | T3: 10.0105 | Z3: Ein gutes Beispiel, wie Context-Precision durch LLM versagt. E-PLUS klingt ähnlich wie E-homework und somit wird es als "relevant" eingestuft, obwohl es das nicht ist. Das LLM kann diesen Unterschied aber nicht erkennen. Zusätzlich dazu werden Chunks nicht gefetched, da SEMANTISCHE ÄHNLICHKEIT zu niedrig --> hybrid-search könnte hier sehr gut Abhilfe schaffen
A4: 11 | B4: Modulhandbuch/PO | C4: medium | D4: Welche Bachelorstudiengänge der WiSo-Fakultät haben ein eigenes Modulhandbuch unter PO 2021? | E4: Basierend auf den Suchergebnissen können die folgenden Bachelorstudiengänge der WiSo-Fakultät ein eigenes Modulhandbuch unter PO 2021 haben: * Betriebswirtschaftslehre (BWL) Bitte beachten Sie, dass diese Informationen basieren auf den Suchergebnissen und möglicherweise nicht vollständig oder aktuell sind. Es ist immer ratsam, direkt bei der Universität zu überprüfen, ob die Informationen noch gültig sind. | F4: Für das Studienjahr 2025/26 gibt es unter der Bachelor PO 2021 Modulhandbücher für Betriebswirtschaftslehre, Volkswirtschaftslehre, Management, Economics and Social Sciences, Sozialwissenschaften, Gesundheitsökonomie, Wirtschaftsinformatik sowie Lehramt am Berufskolleg I. | G4: ['# Modulhandbuch-Archiv\n\nHier Sie die Modulhandbücher (MHB) aller WiSo-Studiengänge vergangener Studienjahre ab dem Studienjahr 2021/22. Bitte beachten Sie, dass diese MHB keine Gültigkeit mehr besitzen.\xa0\n\n## Inhaltsverzeichnis\n\n- Bachelor\n\n- Bachelor PO 2021\n- Bachelor PO 2015\n\xa0\n\n- Master\n\n- Master PO 2021\n- Master PO 2015\n\nAchten Sie zudem auch auf die entsprechende Prüfungsordnung (PO). Die PO 2021 gilt ab dem Studienjahr 2021/22; die PO 2015 ist für Masterstudiengänge im Studienjahr 2022/23 ausgelaufen und für Bachelorstudiengänge zum Studienjahr 2024/25.\n\n\xa0\n\nFalls Sie ein MHB aus einem anderen Studienjahr benötigen, dann können Sie sich gerne über das Kontaktformular an den WiSo Student Service Point wenden.\n\n## Bachelor PO 2021\n\n## Bachelor Modulhandbücher | gültig vom 01.10.2024-30.09.2025\n\nNachfolgend Sie für jeden Bachelorstudiengang\xa0das Modulhandbuch der Prüfungsordnung PO 2021 gültig für das Studienjahr 2024/25.\n\n- Betriebswirtschaftslehre\n- Volkswirtschaftslehre\n- Management, Economics and Social Sciences\n- Sozialwissenschaften\n- Gesundheitsökonomie\n- Wirtschaftsinformatik\n- Lehramt am Berufskolleg I\n\n## Bachelor Modulhandbücher | gültig vom 01.10.2023-30.09.2024\n\nNachfolgend Sie für jeden Bachelorstudiengang\xa0das Modulhandbuch der Prüfungsordnung PO 2021 gültig für das Studienjahr 2023/24.\n\n- Betriebswirtschaftslehre\n- Volkswirtschaftslehre\n- Management, Economics and Social Sciences\n- Sozialwissenschaften\n- Gesundheitsökonomie\n- Wirtschaftsinformatik\n- Lehramt am', 'Dokumente und Medien - Prüfungsordnung 2021\n\n# Bachelor PO 2021\n\nHier Sie alle wichtigen Dokumente, die Sie zur Orientierung und für die Organisation Ihres Studiums benötigen.\xa0\n\nGültig für Studierende der Prüfungsordnung 2021 (Einschreibung ab WiSe 2021/22).\n\nIm Modulhandbuch-Archiv Sie die Modulhandbücher vergangener Studienjahre.\n\n## Bachelor Modulhandbücher | gültig vom 01.10.2025-30.09.2026\n\nNachfolgend Sie für jeden Bachelorstudiengang\xa0das Modulhandbuch der Prüfungsordnung PO 2021 gültig ab dem 01.10.2025.\n\n- Betriebswirtschaftslehre\n- Volkswirtschaftslehre\n- Management, Economics and Social Sciences\n- Sozialwissenschaften\n- Gesundheitsökonomie\n- Wirtschaftsinformatik\n- Lehramt am Berufskolleg I\n\n## Prüfungsordnungen PO 2021\n\nIm Download-Bereich des Prüfungsamtes Sie die gemeinsame Prüfungsordnung der WiSo-Studiengänge, sowie die zusätzliche Bachelorprüfungsordnung.\n\nHI\n\nzum Seitenanfang', 'von vorstrukturierten Kontexten. ... begr ünden und bewerten eigenst ändig erarbeitete Positionen. ... gestalten ihre Lern- und Arbeitsprozesse eigenst ändig. ... kennen und verstehen die relevanten Methoden und Theorien zu den zuvor unter "Inhalte des Moduls" genannten Punkten. 4 Lehr - und Lernformen Seminar 5 Modulvoraussetzungen keine 6 Form der Modulabschlusspr üfung Schriftliche Prü fung: PO 7 Voraussetzungen f ür die Vergabe von Leistungspunkten Bestehen der Modulabschlusspr üfung 8 Verwendung des Moduls (in anderen Studieng ängen) Bachelor of Science Management, Economics and Social Sciences: Schwerpunktbereich Management, Economics and Social Sciences Bachelor of Science Betriebswirtschaftslehre: Schwerpunktbereich Betriebswirtschaftslehre Bachelor of Science Wirtschafts informatik: Ergänzungsbereich Wirtschaftsinformatik Bachelor of Science Sozialwissenschaften: Ergänzungsbereich Sozialwissenschaften Bachelor of Science Volkswirtschaftslehre: Schwerpunkt Studienrichtung BWL Bachelor of Science Wirtschaftsinformatik (ab WS24/25): Ergänzungsbereich Wirtschaftsinformatik Bachelor of Arts Medienwissenschaft: Media and Technology Management 9 Modulbeauftragte/r Univ. -Prof. Dr. ‘ Claudia Loebbecke, M.B.A. --- Page 122 --- Gültig für Studierende der PO 2021 (Einschreibung ab WiSe 2021/22) MODULHANDBUCH - WIRTSCHAFTSINFORMATIK - BACHELOR OF SCIENCE 122 10 Sonstige Informationen --- Page 123 --- Gültig für Studierende der PO 2021 (Einschreibung ab WiSe 2021/22) MODULHANDBU', 'e Schwerpunktbereich: 48 von 168 LP d) Note Bachelorarbeit: 18 von 168 LP. 1.8 Modularität Die Fachgruppen der Bachelorstudiengänge sind in Module gegliedert, wobei die Modulinhalte in den dazugehörenden Modulbeschreibungen dargelegt sind. Das Bachelormodulhandbuch ist auf der Homepage der WiSo -Fakultät im Downloadbereich einsehbar . Die erfolgreiche Teilnahme an Modulen wird durch die Vergabe von Leistungspunkten auf der Grundlage von erfolgreich absolvierten Prüfungsleistungen nachgewiesen. Die Modulprüfungen werden studienbegleitend abgelegt. Ein Modul setzt sich aus verschiedenen Teilen zusammen und ist in der Regel in einem oder zwei Semestern abschließbar. Diese Information finden Sie im Feld „ Moduldauer “ der Modulbeschreibung. Ein Modul kann entweder aus einer Vorlesung, einer Übung und ggf. einem Tutorium zum gleichen Thema bestehen. Zudem gibt es Module, die nur eine Veranstaltung, z.B. ein Seminar, umfassen. Außerdem gibt es Module, in denen mehrere verschiedene Veranstaltung en zur Wahl angeboten werden, von denen eine oder auch mehrere absolviert werden müssen. In diesem Fall kann sich die Prüfung auf eine Veranstaltung oder auf die Inhalte mehrerer Veranstaltung en beziehen. Bitte beachten Sie bei der Studienplanung, dass nicht jedes Modul jedes Semester angeboten wird, diese Information finden Sie im Feld „Turnus“ der Modulbeschreibung. --- Page 17 --- Gültig für Studierende der PO 2021 (Einschreibung ab WiSe 2021/22) MODULHANDBUCH - SOZIALWISSENSCHAFTEN - BA', 'ungsmodul RE Referat FS Fallstudie SM Schwerpunktmodul HA Hausarbeit SSt Selbststudium K Kontaktzeit (= Präsenzzeit in LV) SWS Semesterwochenstunde KL Klausur SI Studium Integrale LP Leistungspunkt (engl.: CP) VN Vor- und Nachbereitungszeit LV Lehrveranstaltung WP Wahlpflichtveranstaltung MP Mündliche Prüfung WL Workload = Arbeitsaufwand --- Page 4 --- Gültig für Studierende der PO 2021 (Einschreibung ab WiSe 2021/22) MODULHANDBUCH – BETRIEBSWIRTSCHAFTSLEHRE – BACHELOR OF SCIENCE 4 Inhaltsverzeichnis 1 BETRIEBSWIRTSCHAFTSL EHRE ................................ ................................ ..... 5 1.1 Inhalte und Studienziele ................................ ................................ ........................... 5 1.2 Voraussetzungen ................................ ................................ ................................ .... 7 1.3 Studienaufbau und -abfolge ................................ ................................ .................... 7 1.4 Study Abroad Option ................................ ................................ ............................... 8 1.4.1 Das Studies Abroad Programme (STAP) der WiSo -Fakultät ................................ . 9 1.4.2 Anrechnungsmöglichkeiten Studies Abroad ................................ ......................... 10 1.5 Musterstudienpläne ................................ ................................ ................................ 10 1.6 Midterm Regelung ................................ ............'] | H4: ['https://wiso.uni-koeln.de/de/studium/modulhandbuecher-und-pruefungsordnungen/modulhandbuch-archiv', 'https://wiso.uni-koeln.de/de/studium/modulhandbuecher-und-pruefungsordnungen/bachelor-po-2021', 'file://D:/Uni-Köln/Masterarbeit/Software/uzk-masterarbeit/data/pdf_cache/__wiso.uni-koeln.de_sites_fakultaet_dokumente_downloads_bachelor_b_mhb_po2021_winfo.pdf', 'file://D:/Uni-Köln/Masterarbeit/Software/uzk-masterarbeit/data/pdf_cache/__wiso.uni-koeln.de_sites_fakultaet_dokumente_downloads_bachelor_b_mhb_po2021_sowi.pdf', 'file://D:/Uni-Köln/Masterarbeit/Software/uzk-masterarbeit/data/pdf_cache/__wiso.uni-koeln.de_sites_fakultaet_dokumente_downloads_Modulhandbuecher_Studienjahr_22-23_MHB_PO2021_b_mhb_po2021_bwl_01.pdf'] | I4: ['html', 'html', 'pdf', 'pdf', 'pdf'] | J4: =0.5 -> 0.5 | K4: 1 | L4: 1 | M4: 0.5 | N4: =IFERROR(X4/(X4+Y4), 0) -> 0.27272727 | O4: 0.5 | P4: 0.5 | Q4: 1 | R4: 9.473851 | S4: 5 | T4: 9.473851 | U4: Studienjahr 2025 / 2026, Bachelor PO 2021, Betriebswirtschaftslehre, Volkswirtschaftslehre, Management, Economics and Social Sciences, Sozialwissenschaften, Gesundheitsökonomie, Wirtschaftsinformatik, Lehramt am Berufskolleg I., Modulhandbuch | V4: Modulhandbuch, Bachelor PO 2021, Betriebswirtschaftslehre | X4: 3 | Y4: 8
A5: 17 | B5: Bachelor-Studium | C5: easy | D5: Welche Bachelorstudiengänge bietet WiSo-Fakultät allgemein an? | E5: Basierend auf den Suchergebnissen kann ich sagen, dass die WiSo-Fakultät der Universität zu Köln folgende Bachelorstudiengänge anbietet: * Betriebswirtschaftslehre (BWL) * Volkswirtschaftslehre (VWL) Diese Informationen sind jedoch möglicherweise nicht vollständig oder aktuell. Ich empfehle, sich direkt bei der Universität zu informieren, um die genauesten und neuesten Informationen zu erhalten. Wenn Sie weitere Fragen haben oder mehr über diese Studiengänge erfahren möchten, stehe ich Ihnen gerne zur Verfügung! | F5: Die WiSo-Fakultät bietet folgende Bachelorprogramme an: Betriebswirtschaftslehre, Volkswirtschaftslehre, Sozialwissenschaften, Management, Economics & Social Sciences, Wirtschaftsinformatik, Gesundheitsökonomie sowie der Lehramts-Bachelor. | G5: ['# Bachelorstudium: FAQ\n\nHier beantworten wir alle Fragen rund um die Bachelorstudiengänge der WiSo-Fakultät. Die Fragen beziehen sich einerseits auf die Aufnahme eines Studiums bei uns (Studienentscheidung, Voraussetzungen für ein Studium allgemein, Hochschulwechsel, Anrechnungsoptionen) sowie auch auf Aspekte während des Studiums (Wahl von Spezialisierungen, Anmeldung zu Prüfungen etc.)\n\nBitte wählen Sie also, ob Sie eine Frage zur Studienwahl/Bewerbung haben oder etwas zum Studium wissen wollen und klicken Sie den entsprechenden Bereich an!\n\nHI\n\nzum Seitenanfang', 'Studiengänge an der WiSo-Fakultät\n\n# Bachelorstudiengänge\n\nSchaffen Sie sich eine exzellente Basis für Ihre weitere Karriere!\n\nEin wirtschafts- oder sozialwissenschaftlicher Bachelor-Abschluss ebnet Ihnen Ihren individuellen Karriereweg – egal, ob Sie direkt nach dem Bachelor in den Beruf einsteigen, ein Trainee-Programm absolvieren oder Sie sich für einen weiterführenden Masterstudiengang entscheiden. Sie den Bachelor-Studiengang, der zu Ihnen passt und studieren Sie an einer top-gerankten Universität in einer pulsierenden Stadt.\n\n## Inhaltsverzeichnis\n\n- Spitzenpositionen in Rankings\n- Attraktiver Standort\n- Chat with Paco\n- Unsere Bachelorstudiengänge im Überblick\n- Weitere Bachelorstudiengänge\n- Auslaufende Bachelorstudiengänge\n\n## Spitzenpositionen in Rankings\n\nDie WiSo-Fakultät kombiniert Theorie und Praxis. Die Bachelor-Studiengänge sind interdisziplinär ausgerichtet und fördern den Wissenstausch sowohl unter den Studierenden als auch zwischen den Disziplinen. Auch dank der innovativen Lehre und der exzellenten Forschung schneidet die Fakultät in nationalen als auch internationalen Hochsschulrankings bestens ab.\n\n## Attraktiver Standort\n\nKöln ist für seine Lebensfreude, Toleranz und Weltoffenheit bekannt. Die Metropolregion ist nicht nur als Wissenschaftsstandort interessant, sondern bietet Studierenden auch eine breite Palette von Kontaktmöglichkeiten zur beruflichen Praxis. Die Region Region über einen attraktiven und zukunftsfähigen Branchenmix, in dem unter anderem', "# Bachelor's programme: FAQ\n\nHere we answer all questions about the Bachelor's degree programmes of the WiSo Faculty. On the one hand, the questions relate to taking up a degree programme with us (study decision, requirements for a degree programme in general, change of university, credit transfer options) and also to aspects during the degree programme (choice of specialisations, registration for examinations, etc.).\n\nSo please choose whether you have a question about the choice of study/application or want to know something about studying and click on the corresponding area!\n\nHI\n\nTo top of page", 'nge\n\n### Bachelorstudiengänge mit WiSo-Beteiligung\n\nNeben den Bachelorstudiengängen der WiSo-Fakultät gibt es auch weitere Studiengänge mit WiSo-Beteiligung. Die WiSo-Fakultät bietet in den folgenden Verbundstudiengängen Wahlpflichtfächer an, die Studiengänge starten alle nur zum Wintersemester:\n\n## Verbundstudiengänge mit WiSo-Beteiligung (Philosophische Fakultät)\n\nFachliche Fragen zu Ihrem Wahlpflichtfach beantwortet gerne der WiSo Student Service Point. Für alle anderen Fragen wenden Sie sich bitte an das Prüfungsamt und den Studierendenservice der Philosophischen Fakultät.\n\n- Bachelorstudiengang Regionalstudien China: Wahlpflichtfächer „Betriebswirtschaftslehre“, „Sozialwissenschaften“ und „Volkswirtschaftslehre“\n- Bachelorstudiengang Regionalstudien Lateinamerika: Wahlpflichtfächer „Sozialwissenschaften“ und „Volkswirtschaftslehre“\n- Bachelorstudiengang Regionalstudien Ost- und Mitteleuropa: Wahlpflichtfächer „Sozialwissenschaften“ und „Volkswirtschaftslehre“\n- Bachelorstudiengang Medienwissenschaft: Wahlpflichtfach „Medienmanagement und Medienökonomie"\n\n\xa0\n\n## Mathematik und Wirtschaftsmathematik (Mathematisch-Naturwissenschaftliche Fakultät)\n\n- Bachelorstudiengang Wirtschaftsmathematik (Nebenfächer "Wirtschaftswissenschaften" oder "Volkswirtschaftslehre")\n- Bachelorstudiengang Mathematik (Nebenfächer "Wirtschaftswissenschaften" oder "Volkswirtschaftslehre")\n\n## Geographie (Mathematisch-Naturwissenschaftliche Fakultät)\n\nAllgemeine Informationen zum B.Sc. Geographie Sie a', 'chtsfach "Wirtschaftswissenschaften" in Kombination mit einem anderen Unterrichtsfach, welches nicht an der WiSo-Fakultät angesiedelt ist.\nNur die Bachelorstudiengänge Betriebs- und Volkswirtschaftslehre werden zum Winter- und Sommersemester angeboten, alle übrigen Bachelorstudiengänge starten nur zum Wintersemester.\n\nDie Philosophische Fakultät bietet folgende Verbundstudiengänge an, die ein wirtschafts- und sozialwissenschaftliches Wahlpflichtfach umfassen, welches dann an der WiSo-Fakultät verortet ist:\n\n- Medienwissenschaften\n- Regionalstudien China\n- Regionalstudien Ost- und Mitteleuropa\n- Regionalstudien Lateinamerika\n\nZudem gibt es noch einige andere Studiengänge, in denen in verschiedenem Umfang Leistungen in Neben- oder Ergänzungsfächern an der WiSo-Fakultät studiert werden dürfen.\nAn der Mathematisch-Naturwissenschaftlichen Fakultät sind das:\n\n- Mathematik und Wirtschaftsmathe (Nebenfächer Wirtschaftswissenschaften oder VWL)\n- Geographie (Nebenfächer BWL, VWL oder SOWI)\n\nAn der Humanwissenschaftlichen Fakultät ist das der Studiengang:\n\n- Psychologie (Interdisziplinäre Vernetzung BWL oder VWL oder Sozialwissenschaften)\n\n## 3. Welche Masterstudiengänge können an der WiSo-Fakultät studiert werden?\n\nFolgenden Masterstudiengänge werden an der WiSo-Fakultät angeboten:\n\n- Business Administration (mit 5 verschiedenen Spezialisierungen)\n- International Management (CEMS MIM)\n- Business Analytics and Econometrics\n- Economics\n- Economic Research\n- Politikwissenschaft\n- Sociolog'] | H5: ['https://wiso.uni-koeln.de/de/studium/studienorganisation/faq/bachelor', 'https://wiso.uni-koeln.de/de/studium/bachelor', 'https://wiso.uni-koeln.de/en/studies/organising-your-studies/faq/bachelor', 'https://wiso.uni-koeln.de/de/studium/bachelor', 'https://wiso.uni-koeln.de/de/studium/studienorganisation/faq/allgemeine-fragen'] | I5: ['html', 'html', 'html', 'html', 'html'] | J5: =2/3 -> 0.66666667 | K5: =3/9 -> 0.33333333 | L5: 0.325 | M5: 0.5 | N5: =IFERROR(X5/(X5+Y5), 0) -> 0.33333333 | O5: 0.5 | P5: 0.5 | Q5: 1 | R5: 7.7230635 | S5: 5 | T5: 7.7230635 | U5: Bachelorprogramme, Betriebswirtschaftslehre, Volkswirtschaftslehre, Sozialwissenschaften, Management, Economics & Social Sciences, Wirtschaftsinformatik, Gesundheitsökonomie, Lehramts-Bachelor | V5: Bachelorprogramm / Bachelorstudiengang, Betriebswirtschaftslehre, Volkswirtschaftslehre | W5: Sozialwissenschaften, Management, Economics & Social Sciences, Wirtschaftsinformatik, Gesundheitsökonomie, Lehramts-Bachelor | X5: 3 | Y5: 6 | Z5: Claims: "basierend auf Suchergebnissen (es sind nicht alle in den Suchergebnissen genannt)", True: "die aufgeführten"
A6: 20 | B6: Bachelor-Studium | C6: hard | D6: Welche Verbundstudiengänge mit WiSo-Beteiligung werden angeboten? | E6: Die WiSo-Fakultät bietet in verschiedenen Verbundstudiengängen Wahlpflichtfächer an. Dazu gehören: * Wirtschaftsmathe (Nebenfächer Wirtschaftswissenschaften oder VWL) * Mathematik (Nebenfächer Wirtschaftswissenschaften oder VWL) Diese Studiengänge starten alle nur zum Wintersemester. Für weitere Informationen können Sie sich an den WiSo Student Service Point wenden. | F6: Es werden folgende Verbundstudiengänge der Philosophischen Fakultät angeboten: Bachelorstudiengang Regionalstudien China, Bachelorstudiengang Regionalstudien Lateinamerika, Bachelorstudiengang Regionalstudien Ost- und Mitteleuropa, Bachelorstudiengang Medienwissenschaft, Bachelorstudiengang Wirtschaftsmathematik, Bachelorstudiengang Mathematik, Bachelor Geographie, Bachelor Klinische Pflege | G6: ['nge\n\n### Bachelorstudiengänge mit WiSo-Beteiligung\n\nNeben den Bachelorstudiengängen der WiSo-Fakultät gibt es auch weitere Studiengänge mit WiSo-Beteiligung. Die WiSo-Fakultät bietet in den folgenden Verbundstudiengängen Wahlpflichtfächer an, die Studiengänge starten alle nur zum Wintersemester:\n\n## Verbundstudiengänge mit WiSo-Beteiligung (Philosophische Fakultät)\n\nFachliche Fragen zu Ihrem Wahlpflichtfach beantwortet gerne der WiSo Student Service Point. Für alle anderen Fragen wenden Sie sich bitte an das Prüfungsamt und den Studierendenservice der Philosophischen Fakultät.\n\n- Bachelorstudiengang Regionalstudien China: Wahlpflichtfächer „Betriebswirtschaftslehre“, „Sozialwissenschaften“ und „Volkswirtschaftslehre“\n- Bachelorstudiengang Regionalstudien Lateinamerika: Wahlpflichtfächer „Sozialwissenschaften“ und „Volkswirtschaftslehre“\n- Bachelorstudiengang Regionalstudien Ost- und Mitteleuropa: Wahlpflichtfächer „Sozialwissenschaften“ und „Volkswirtschaftslehre“\n- Bachelorstudiengang Medienwissenschaft: Wahlpflichtfach „Medienmanagement und Medienökonomie"\n\n\xa0\n\n## Mathematik und Wirtschaftsmathematik (Mathematisch-Naturwissenschaftliche Fakultät)\n\n- Bachelorstudiengang Wirtschaftsmathematik (Nebenfächer "Wirtschaftswissenschaften" oder "Volkswirtschaftslehre")\n- Bachelorstudiengang Mathematik (Nebenfächer "Wirtschaftswissenschaften" oder "Volkswirtschaftslehre")\n\n## Geographie (Mathematisch-Naturwissenschaftliche Fakultät)\n\nAllgemeine Informationen zum B.Sc. Geographie Sie a', 'n denen in verschiedenem Umfang Leistungen in Neben- oder Ergänzungsfächern studiert werden dürfen:\n\n- Wirtschaftsmathe (Nebenfächer Wirtschaftswissenschaften oder VWL)\n- Mathematik (Nebenfächer Wirtschaftswissenschaften oder VWL)\n\nZu all diesen Bereichen Sie hier die nötigen Informationen, wenn Sie auf den entsprechenden Bereich klicken.\n\nzum Seitenanfang\n\n## Verbundstudiengänge mit WiSo-Beteiligung (Philosophische Fakultät)\n\nGesamtübersichten über die WiSo-Wahlpflichtfächer in den Verbundstudiengängen der Philosophischen Fakultät:\n\n- Masterstudiengang Regionalstudien China: Wahlpflichtfächer „Betriebswirtschaftslehre, „Sozialwissenschaften“ und „Volkswirtschaftslehre“\n- Masterstudiengänge Regionalstudien Lateinamerika und Ost- und Mitteleuropa: Wahlpflichtfächer "Volkswirtschaftslehre" und "Sozialwissenschaften"\n- Masterstudiengang Medienwissenschaft: Wahlpflichtfach „Medienmanagement und Medienökonomie"\xa0\n\nVerbindliche Hinweise zu den Prüfungsordnungen Sie auf den\xa0Websites des Prüfungsamtes der Philosophischen Fakultät.\xa0\n\nZu Beginn Ihres Studiums müssen Sie sich einmalig beim Prüfungsamt der Philosophischen Fakultät registrieren, um sich für Prüfungen anmelden zu können. Bitte wenden Sie sich an die dortigen MitarbeiterInnen. Die Anmeldung für Modulabschlussprüfungen der WiSo-Module erfolgt dann in KLIPS 2.0.\n\nDie Anmeldung zu Veranstaltungen erfolgt i.d.R. in der zweiten KLIPS-Belegphase.\n\nFür Veranstaltungen\xa0der Wirtschafts- und Sozialgeographie ist ggf. auch eine Anmeldu', "ter-Infotag teilzunehmen. Nutzen Sie die Gelegenheit, mehr über die WiSo-Fakultät zu erfahren, die Studienprogramme zu erkunden und wertvolle Einblicke von Professor:innen, aktuellen Studierenden und Alumni zu gewinnen.\n\n## Inhaltsverzeichnis\n\n- Unsere Masterprogramme in der Übersicht\n- Masterstudiengänge mit WiSo-Beteiligung\n- Weitere Master der PO 2015\n\n## Unsere Masterprogramme in der Übersicht\n\n## International Management (CEMS MIM)\n\n## Business Administration\n\n## Double Master's Programme in Business Administration\n\n## Business Analytics & Econometrics\n\n## Economics\n\n## Double Master's Programme in Economics\n\n## Economic Research\n\n## Gesundheitsökonomie\n\n## Double Master's Programme in Health Economics and Management\n\n## Information Systems\n\n## Political Science\n\n## Double Master's Programme in European Studies\n\n## Sociology\n\n## Double Master's Programme in Demography and Social Inequality\n\n## Wirtschaftspädagogik\n\nzum Seitenanfang\n\n## Masterstudiengänge mit WiSo-Beteiligung\n\nAn der WiSo-Fakultät werden Wahlpflichtfächer zu den folgenden Verbund-Master der Philosophischen Fakultät studiert:\n\n- Medienwissenschaft\n- Regionalstudien China\n- Regionalstudien Lateinamerika\n- Regionalstudien Ost- und Mitteleuropa\n\nWeitere Informationen zu diesen Studiengängen erhalten Sie auf den Seiten der Philosophischen Fakultät.\n\nAuch in den Masterstudiengängen\n\n- Mathematik und\n- Wirtschaftsmathematik\n\nder Mathemathisch-Naturwissenschaftlichen Fakultät kann ein Nebenfach an der WiSo-Fakult", '# Bachelorstudium: FAQ\n\nHier beantworten wir alle Fragen rund um die Bachelorstudiengänge der WiSo-Fakultät. Die Fragen beziehen sich einerseits auf die Aufnahme eines Studiums bei uns (Studienentscheidung, Voraussetzungen für ein Studium allgemein, Hochschulwechsel, Anrechnungsoptionen) sowie auch auf Aspekte während des Studiums (Wahl von Spezialisierungen, Anmeldung zu Prüfungen etc.)\n\nBitte wählen Sie also, ob Sie eine Frage zur Studienwahl/Bewerbung haben oder etwas zum Studium wissen wollen und klicken Sie den entsprechenden Bereich an!\n\nHI\n\nzum Seitenanfang', 'lstudien Ost- und Mitteleuropa\n\nWeitere Informationen zu diesen Studiengängen erhalten Sie auf den Seiten der Philosophischen Fakultät.\n\nAuch in den Masterstudiengängen\n\n- Mathematik und\n- Wirtschaftsmathematik\n\nder Mathemathisch-Naturwissenschaftlichen Fakultät kann ein Nebenfach an der WiSo-Fakultät belegt werden. Weitere Infos hierzu erhalten Sie auf den Seiten des Mathematischen Instituts der Mathematisch-Naturwissenschatlichen Fakultät.\n\nBitte beachten Sie, dass die WiSo-Fakultät nicht für die Zulassung zu den o.g. Studiengängen verantwortlich ist. Diese erfolgt über die jeweils zuständigen Fakultäten. Informieren Sie sich bitte dort über eventuelle Zugangsvoraussetzungen und Bewerbungsverfahren.\n\nFachliche Fragen zu Ihrem Wahlpflichtfach beantwortet gerne der WiSo Student Service Point. Für alle anderen Fragen wenden Sie sich bitte an das Prüfungsamt und den Studierendenservice der Philosophischen Fakultät.\n\n## Weitere Master der PO 2015\n\nDie Philosophische Fakultät bietet Verbundstudiengänge an (Medienwissenschaften und Regionalstudien), die ein recht umfangreiches wirtschafts- und sozialwissenschaftliches Nebenfach umfassen.\n\nZudem gibt es noch einige andere Studiengänge, in denen in verschiedenem Umfang Leistungen in Neben- oder Ergänzungsfächern studiert werden dürfen:\n\n- Wirtschaftsmathe (Nebenfächer Wirtschaftswissenschaften oder VWL)\n- Mathematik (Nebenfächer Wirtschaftswissenschaften oder VWL)\n\nZu all diesen Bereichen Sie hier die nötigen Informationen, wenn Sie'] | H6: ['https://wiso.uni-koeln.de/de/studium/bachelor', 'https://wiso.uni-koeln.de/de/studium/master', 'https://wiso.uni-koeln.de/de/studium/master', 'https://wiso.uni-koeln.de/de/studium/studienorganisation/faq/bachelor', 'https://wiso.uni-koeln.de/de/studium/master'] | I6: ['html', 'html', 'html', 'html', 'html'] | J6: 0.9 | K6: 0.75 | L6: 1 | M6: 0.5 | N6: 0.25 | O6: 0.8 | P6: 1 | Q6: 1 | R6: 8.765487 | S6: 5 | T6: 8.765487 | Z6: Es sind nicht ALLE aufgelistet Fehler in der Frage (nur Bachelorstudiengänge sind gemeint!) --> Frage ist also nicht präzise genug formuliert, was aber auch in der Realität passieren kann
A7: 30 | B7: Master-Studium | C7: easy | D7: Wo finden Interessierte studiengangsspezifische Informationen zu einzelnen WiSo-Masterprogrammen, etwa zum Master Information Systems? | E7: Interessierte können studiengangsspezifische Informationen zu einzelnen WiSo-Masterprogrammen, wie dem Master Information Systems, auf der Universitäts-Website finden. Dort sind alle wichtigen Details zum Aufbau des Studiums, den inneren Zusammenhängen und den Anmeldemodalitäten zu Veranstaltungen und Prüfungen enthalten. Zusätzlich können die Informationen aus der Prüfungsordnung und dem Mastermodulhandbuch der WiSo-Fakultät eingesehen werden. Es ist auch möglich, sich an das WiSo-Studienberatungszentrum zu wenden, um weitere Fragen zu klären. | F7: Studiengangsspezifische Informationen zu den einzelnen WiSo-Masterprogrammen findest du auf der Master-Bewerbungsseite im Abschnitt „Studiengangsspezifische Informationen“. Dort sind alle Masterstudiengänge – unter anderem auch der Master Information Systems – jeweils mit eigenen Informationsseiten verlinkt. | G7: ['ergebnissen die Möglichkeit für ein Promotions-Aufbaustudium (Ph.D.).\n\nGleichzeitig ist der Master in Information Systems natürlich eine hervorragende Basis für die Bewerbung auf Graduiertenstudiengänge an anderen nationalen und internationalen Universitäten.\n\n\xa0\n\n##### .\n\n## Bewerbung\n\n\xa0\n\nAlle Infos zur Masterbewerbung an der WiSo-Fakultät.\n\n## Weitere Informationen und Kontakt\n\nWir unterstützen Sie gerne bei Ihren Ambitionen:\n\nBei Interesse oder Fragen zu unseren WiSo-Studiengängen helfen die Studienberater:innen im WiSo Student Service Point gerne weiter:\n\n- WiSo Student Service Point Hotline: +49 (0) 221/470-8818\n- www.wiso-studentservice.uni-koeln.de\n\nHI\n\nzum Seitenanfang', 'en bietet sich ein breites Feld spannender Forschungsaufgaben schon im Rahmen der Lehre, etwa im Bereich Social (Media) Network Analysis oder Nachhaltigkeit.\n\nDer vom KIWI getragene Masterstudiengang „Information Systems“ bietet mit den drei Schwerpunkten Business Analytics and Data Science, Digital Innovation and Entrepreneurship und Digital Sustainable Society ein interdisziplinär ausgelegtes Programm. Neben exzellenten Berufsaussichten vermittelt es Studierenden praktisches und theoretisches Handwerkszeug, sich in Wirtschaft, Gesellschaft oder Forschung den aktuellen gesellschaftlichen Herausforderungen zu stellen.\n\nWir gratulieren zu der herausragenden Platzierung!\n\n- Ranking-Zusammenfassung (WiSo-Fakultät)\n- Zum Ranking (Association for Information Systems) [(Anmeldung erforderlich. Einstellungen: Journals: “AIS8”, Years: “Last 5 Years”, Region: “Europe, Africa, Middle East”]\n- Kölner Institut für Wirtschaftsinformatik (KIWI)\n- Master Information Systems der Wiso-Fakultät\n\nZurück\n\n#### Social-Media-Kanäle der WiSo-Fakultät\n\n[ follow us! ]\n\nHI\n\nzum Seitenanfang', 'en Dokument detaillierter dargestellt wird : \uf0b7 Medieninformatik \uf0b7 Medienmanagement und Medienökonomie \uf0b7 Medienrecht Im nachfolgenden Dokument sind wichtige Angaben zum Aufbau, den inneren Zusammenhängen und den Anmeldemodalitäten zu Veranstaltungen und Prüfungen des Faches Medienmanagement enthalten. Zusätzlich zu unseren Hinweisen und Empfehlungen für eine erfolgreiche Studiengestaltung haben wir Informationen aus der Prüfungsordnung und dem Mastermodulhandbuch der WiSo -Fakultät eingebunden (z. B. zu Leistungspun kten oder Pflicht - und Wahlveranstaltungen)1. Durch diese Informationen werden Sie in die Lage versetzt - insbesondere zu Studienbeginn - informierte Wahlentscheidungen treffen zu können. Wir wünschen Ihnen einen guten Studienstart und freuen uns darauf, Sie auch an der WiSo - Fakultät herzlich begrüßen zu dürfen! Ihr Team vom WiSo -Studienberatungszentrum 1 Ohne Gewähr --- Page 4 --- WiSo -Wahlpflichtfächer des Masterstudiengangs Medienwissenschaft 4 2. Zulassungsvoraussetzungen Die genauen Zugangsvoraussetzungen (Link) zum Masterstudiengang Medienwissenschaft entnehmen Sie bitte der Homepage der Philosophischen Fakultät: http://phil -fak.uni - koeln.de/31766.html . Sollten S ie weitere Fragen zu den Zugangsvoraussetzungen für diesen Masterstudiengang haben, wenden Sie sich bitte an die Studienberatung der Philosophischen Fakultät studienberatung -philfak@uni -koeln.de und deren Fachberater *innen: Liste der Fachberaterinnen und Fachberater 3. Aufbau Der Master s', '# Masterstudium: FAQ\n\nHier beantworten wir alle Fragen rund um die Masterstudiengänge der WiSo-Fakultät. Die Fragen beziehen sich einerseits auf die Aufnahme eines Studiums bei uns (Zugangsvoraussetzungen, Bewerbungs- und Auswahlverfahren, Einschreibung) sowie auch auf Aspekte während des Studiums (Wahl von Spezialisierungen, Anmeldung zu Prüfungen etc.). Sollten Sie Fragen haben, die weder über unsere Homepage noch die FAQ beantwortet werden, können Sie sich gerne an das WiSo-Studienberatungszentrum wenden.\n\n#\n\nZugangsvoraussetzungen und Bewerbung\n\n#\n\nFragen im Masterstudium\n\nHI\n\nzum Seitenanfang', 'from a wide range of WiSo Faculty courses.\n- With the master’s thesis for the successful completion of your studies, you underline the knowledge and skills you have acquired throughout the programme and are ready to continue your career as an expert in your field.\n\nFurther details on the structure of the degree programme, such as course of study recommendations and module descriptions, can be found in the Module Catalogue.\n\n- Information and regulations relevant to the examination can be found in the examination regulations.\n\nIf you started your studies before 2021, please select the appropriate documents in the document overview.\n\n## Organising your Studies\n\nStudying requires a high degree of self-organisation. Well-prepared and properly informed, you will manage your studies with ease. In the following, we have compiled links to helpful information, relevant tools and counselling centres for you.\n\n## First semester students\n\n## Inspections for the examinations\n\n## Course and Examination Management: KLIPS\n\n## Certificates\n\n## Financing\n\n## Stays Abroad\n\n## FAQ\n\n## Study spaces\n\n## UoC-wide services for enroled international students\n\nHI\n\nTo top of page'] | H7: ['https://wiso.uni-koeln.de/de/studium/master/master-information-systems', 'https://wiso.uni-koeln.de/de/aktuelles-und-neuigkeiten/news-einzelansicht/bestplatzierung-fuer-koelner-institut-fuer-wirtschaftsinformatik', 'file://D:/Uni-Köln/Masterarbeit/Software/uzk-masterarbeit/data/pdf_cache/__wiso.uni-koeln.de_sites_fakultaet_dokumente_downloads_master_UEbersicht_MA_Medien_po2015.pdf', 'https://wiso.uni-koeln.de/de/studium/studienorganisation/faq/master', 'https://wiso.uni-koeln.de/en/studies/master/master-business-administration/marketing/programme-structure-marketing'] | I7: ['html', 'html', 'pdf', 'html', 'html'] | J7: =2/6 -> 0.33333333 | K7: 0 | L7: 0.75 | M7: 0.25 | N7: =IFERROR(X7/(X7+Y7), 0) -> 0 | O7: 0.25 | P7: 0 | Q7: 0 | R7: 9.9265642 | S7: 5 | T7: 9.9265642 | Z7: Frage wird aus Validation entfernt und ersetzt. Zusätzlich wird die Frage im Testset angepasst. Selbst als Mensch habe ich große Probleme diese Frage wirklich akkurat zu beantworten
