Workbook

Sheet Ränge
A1: Human
A2: ID | B2: faithfulness | C2: context_recall | D2: context_precision | E2: semantic_similarity | F2: context_entity_recall | G2: answer_relevancy
A3: 1 | B3: =_xlfn.RANK.EQ('Human Details'!J2,'Human Details'!$J$2:$J$16) -> 1 | C3: =_xlfn.RANK.EQ('Human Details'!K2,'Human Details'!$K$2:$K$16) -> 1 | D3: =_xlfn.RANK.EQ('Human Details'!L2,'Human Details'!$L$2:$L$16) -> 9 | E3: =_xlfn.RANK.EQ('Human Details'!M2,'Human Details'!$M$2:$M$16) -> 1 | F3: =_xlfn.RANK.EQ('Human Details'!N2,'Human Details'!$N$2:$N$16) -> 5 | G3: =_xlfn.RANK.EQ('Human Details'!O2,'Human Details'!$O$2:$O$16) -> 1
A4: 8 | B4: =_xlfn.RANK.EQ('Human Details'!J3,'Human Details'!$J$2:$J$16) -> 6 | C4: =_xlfn.RANK.EQ('Human Details'!K3,'Human Details'!$K$2:$K$16) -> 11 | D4: =_xlfn.RANK.EQ('Human Details'!L3,'Human Details'!$L$2:$L$16) -> 1 | E4: =_xlfn.RANK.EQ('Human Details'!M3,'Human Details'!$M$2:$M$16) -> 13 | F4: =_xlfn.RANK.EQ('Human Details'!N3,'Human Details'!$N$2:$N$16) -> 11 | G4: =_xlfn.RANK.EQ('Human Details'!O3,'Human Details'!$O$2:$O$16) -> 14
A5: 11 | B5: =_xlfn.RANK.EQ('Human Details'!J4,'Human Details'!$J$2:$J$16) -> 6 | C5: =_xlfn.RANK.EQ('Human Details'!K4,'Human Details'!$K$2:$K$16) -> 1 | D5: =_xlfn.RANK.EQ('Human Details'!L4,'Human Details'!$L$2:$L$16) -> 1 | E5: =_xlfn.RANK.EQ('Human Details'!M4,'Human Details'!$M$2:$M$16) -> 3 | F5: =_xlfn.RANK.EQ('Human Details'!N4,'Human Details'!$N$2:$N$16) -> 7 | G5: =_xlfn.RANK.EQ('Human Details'!O4,'Human Details'!$O$2:$O$16) -> 9
A6: 17 | B6: =_xlfn.RANK.EQ('Human Details'!J5,'Human Details'!$J$2:$J$16) -> 4 | C6: =_xlfn.RANK.EQ('Human Details'!K5,'Human Details'!$K$2:$K$16) -> 9 | D6: =_xlfn.RANK.EQ('Human Details'!L5,'Human Details'!$L$2:$L$16) -> 12 | E6: =_xlfn.RANK.EQ('Human Details'!M5,'Human Details'!$M$2:$M$16) -> 3 | F6: =_xlfn.RANK.EQ('Human Details'!N5,'Human Details'!$N$2:$N$16) -> 6 | G6: =_xlfn.RANK.EQ('Human Details'!O5,'Human Details'!$O$2:$O$16) -> 9
A7: 20 | B7: =_xlfn.RANK.EQ('Human Details'!J6,'Human Details'!$J$2:$J$16) -> 2 | C7: =_xlfn.RANK.EQ('Human Details'!K6,'Human Details'!$K$2:$K$16) -> 5 | D7: =_xlfn.RANK.EQ('Human Details'!L6,'Human Details'!$L$2:$L$16) -> 1 | E7: =_xlfn.RANK.EQ('Human Details'!M6,'Human Details'!$M$2:$M$16) -> 3 | F7: =_xlfn.RANK.EQ('Human Details'!N6,'Human Details'!$N$2:$N$16) -> 9 | G7: =_xlfn.RANK.EQ('Human Details'!O6,'Human Details'!$O$2:$O$16) -> 5
A8: 30 | B8: =_xlfn.RANK.EQ('Human Details'!J7,'Human Details'!$J$2:$J$16) -> 11 | C8: =_xlfn.RANK.EQ('Human Details'!K7,'Human Details'!$K$2:$K$16) -> 11 | D8: =_xlfn.RANK.EQ('Human Details'!L7,'Human Details'!$L$2:$L$16) -> 8 | E8: =_xlfn.RANK.EQ('Human Details'!M7,'Human Details'!$M$2:$M$16) -> 10 | F8: =_xlfn.RANK.EQ('Human Details'!N7,'Human Details'!$N$2:$N$16) -> 11 | G8: =_xlfn.RANK.EQ('Human Details'!O7,'Human Details'!$O$2:$O$16) -> 11
A9: 33 | B9: =_xlfn.RANK.EQ('Human Details'!J8,'Human Details'!$J$2:$J$16) -> 6 | C9: =_xlfn.RANK.EQ('Human Details'!K8,'Human Details'!$K$2:$K$16) -> 1 | D9: =_xlfn.RANK.EQ('Human Details'!L8,'Human Details'!$L$2:$L$16) -> 7 | E9: =_xlfn.RANK.EQ('Human Details'!M8,'Human Details'!$M$2:$M$16) -> 1 | F9: =_xlfn.RANK.EQ('Human Details'!N8,'Human Details'!$N$2:$N$16) -> 1 | G9: =_xlfn.RANK.EQ('Human Details'!O8,'Human Details'!$O$2:$O$16) -> 6
A10: 34 | B10: =_xlfn.RANK.EQ('Human Details'!J9,'Human Details'!$J$2:$J$16) -> 13 | C10: =_xlfn.RANK.EQ('Human Details'!K9,'Human Details'!$K$2:$K$16) -> 11 | D10: =_xlfn.RANK.EQ('Human Details'!L9,'Human Details'!$L$2:$L$16) -> 13 | E10: =_xlfn.RANK.EQ('Human Details'!M9,'Human Details'!$M$2:$M$16) -> 3 | F10: =_xlfn.RANK.EQ('Human Details'!N9,'Human Details'!$N$2:$N$16) -> 11 | G10: =_xlfn.RANK.EQ('Human Details'!O9,'Human Details'!$O$2:$O$16) -> 1
A11: 64 | B11: =_xlfn.RANK.EQ('Human Details'!J10,'Human Details'!$J$2:$J$16) -> 13 | C11: =_xlfn.RANK.EQ('Human Details'!K10,'Human Details'!$K$2:$K$16) -> 11 | D11: =_xlfn.RANK.EQ('Human Details'!L10,'Human Details'!$L$2:$L$16) -> 13 | E11: =_xlfn.RANK.EQ('Human Details'!M10,'Human Details'!$M$2:$M$16) -> 13 | F11: =_xlfn.RANK.EQ('Human Details'!N10,'Human Details'!$N$2:$N$16) -> 11 | G11: =_xlfn.RANK.EQ('Human Details'!O10,'Human Details'!$O$2:$O$16) -> 14
A12: 65 | B12: =_xlfn.RANK.EQ('Human Details'!J11,'Human Details'!$J$2:$J$16) -> 4 | C12: =_xlfn.RANK.EQ('Human Details'!K11,'Human Details'!$K$2:$K$16) -> 1 | D12: =_xlfn.RANK.EQ('Human Details'!L11,'Human Details'!$L$2:$L$16) -> 1 | E12: =_xlfn.RANK.EQ('Human Details'!M11,'Human Details'!$M$2:$M$16) -> 3 | F12: =_xlfn.RANK.EQ('Human Details'!N11,'Human Details'!$N$2:$N$16) -> 1 | G12: =_xlfn.RANK.EQ('Human Details'!O11,'Human Details'!$O$2:$O$16) -> 1
A13: 84 | B13: =_xlfn.RANK.EQ('Human Details'!J12,'Human Details'!$J$2:$J$16) -> 3 | C13: =_xlfn.RANK.EQ('Human Details'!K12,'Human Details'!$K$2:$K$16) -> 7 | D13: =_xlfn.RANK.EQ('Human Details'!L12,'Human Details'!$L$2:$L$16) -> 1 | E13: =_xlfn.RANK.EQ('Human Details'!M12,'Human Details'!$M$2:$M$16) -> 3 | F13: =_xlfn.RANK.EQ('Human Details'!N12,'Human Details'!$N$2:$N$16) -> 10 | G13: =_xlfn.RANK.EQ('Human Details'!O12,'Human Details'!$O$2:$O$16) -> 1
A14: 89 | B14: =_xlfn.RANK.EQ('Human Details'!J13,'Human Details'!$J$2:$J$16) -> 13 | C14: =_xlfn.RANK.EQ('Human Details'!K13,'Human Details'!$K$2:$K$16) -> 11 | D14: =_xlfn.RANK.EQ('Human Details'!L13,'Human Details'!$L$2:$L$16) -> 13 | E14: =_xlfn.RANK.EQ('Human Details'!M13,'Human Details'!$M$2:$M$16) -> 13 | F14: =_xlfn.RANK.EQ('Human Details'!N13,'Human Details'!$N$2:$N$16) -> 11 | G14: =_xlfn.RANK.EQ('Human Details'!O13,'Human Details'!$O$2:$O$16) -> 13
... A17: 110 | B17: =_xlfn.RANK.EQ('Human Details'!J16,'Human Details'!$J$2:$J$16) -> 12 | C17: =_xlfn.RANK.EQ('Human Details'!K16,'Human Details'!$K$2:$K$16) -> 10 | D17: =_xlfn.RANK.EQ('Human Details'!L16,'Human Details'!$L$2:$L$16) -> 6 | E17: =_xlfn.RANK.EQ('Human Details'!M16,'Human Details'!$M$2:$M$16) -> 10 | F17: =_xlfn.RANK.EQ('Human Details'!N16,'Human Details'!$N$2:$N$16) -> 8 | G17: =_xlfn.RANK.EQ('Human Details'!O16,'Human Details'!$O$2:$O$16) -> 11
A20: qwen2.5:7b
A21: ID | B21: faithfulness | C21: context_recall | D21: context_precision | E21: semantic_similarity | F21: context_entity_recall | G21: answer_relevancy
A22: 1 | B22: =_xlfn.RANK.EQ('LLM-As-Judge Details'!J2,'LLM-As-Judge Details'!$J$2:$J$16) -> 1 | C22: =_xlfn.RANK.EQ('LLM-As-Judge Details'!K2,'LLM-As-Judge Details'!$K$2:$K$16) -> 1 | D22: =_xlfn.RANK.EQ('LLM-As-Judge Details'!L2,'LLM-As-Judge Details'!$L$2:$L$16) -> 13 | E22: =_xlfn.RANK.EQ('LLM-As-Judge Details'!M2,'LLM-As-Judge Details'!$M$2:$M$16) -> 13 | F22: =_xlfn.RANK.EQ('LLM-As-Judge Details'!N2,'LLM-As-Judge Details'!$N$2:$N$16) -> 3 | G22: =_xlfn.RANK.EQ('LLM-As-Judge Details'!O7,'LLM-As-Judge Details'!$O$2:$O$16) -> 9
A23: 8 | B23: =_xlfn.RANK.EQ('LLM-As-Judge Details'!J3,'LLM-As-Judge Details'!$J$2:$J$16) -> 10 | C23: =_xlfn.RANK.EQ('LLM-As-Judge Details'!K3,'LLM-As-Judge Details'!$K$2:$K$16) -> 12 | D23: =_xlfn.RANK.EQ('LLM-As-Judge Details'!L3,'LLM-As-Judge Details'!$L$2:$L$16) -> 6 | E23: =_xlfn.RANK.EQ('LLM-As-Judge Details'!M3,'LLM-As-Judge Details'!$M$2:$M$16) -> 12 | F23: =_xlfn.RANK.EQ('LLM-As-Judge Details'!N3,'LLM-As-Judge Details'!$N$2:$N$16) -> 7 | G23: =_xlfn.RANK.EQ('LLM-As-Judge Details'!O8,'LLM-As-Judge Details'!$O$2:$O$16) -> 5
A24: 11 | B24: =_xlfn.RANK.EQ('LLM-As-Judge Details'!J4,'LLM-As-Judge Details'!$J$2:$J$16) -> 8 | C24: =_xlfn.RANK.EQ('LLM-As-Judge Details'!K4,'LLM-As-Judge Details'!$K$2:$K$16) -> 1 | D24: =_xlfn.RANK.EQ('LLM-As-Judge Details'!L4,'LLM-As-Judge Details'!$L$2:$L$16) -> 3 | E24: =_xlfn.RANK.EQ('LLM-As-Judge Details'!M4,'LLM-As-Judge Details'!$M$2:$M$16) -> 11 | F24: =_xlfn.RANK.EQ('LLM-As-Judge Details'!N4,'LLM-As-Judge Details'!$N$2:$N$16) -> 1 | G24: =_xlfn.RANK.EQ('LLM-As-Judge Details'!O9,'LLM-As-Judge Details'!$O$2:$O$16) -> 3
A25: 17 | B25: =_xlfn.RANK.EQ('LLM-As-Judge Details'!J5,'LLM-As-Judge Details'!$J$2:$J$16) -> 8 | C25: =_xlfn.RANK.EQ('LLM-As-Judge Details'!K5,'LLM-As-Judge Details'!$K$2:$K$16) -> 12 | D25: =_xlfn.RANK.EQ('LLM-As-Judge Details'!L5,'LLM-As-Judge Details'!$L$2:$L$16) -> 4 | E25: =_xlfn.RANK.EQ('LLM-As-Judge Details'!M5,'LLM-As-Judge Details'!$M$2:$M$16) -> 7 | F25: =_xlfn.RANK.EQ('LLM-As-Judge Details'!N5,'LLM-As-Judge Details'!$N$2:$N$16) -> 3 | G25: =_xlfn.RANK.EQ('LLM-As-Judge Details'!O10,'LLM-As-Judge Details'!$O$2:$O$16) -> 4
A26: 20 | B26: =_xlfn.RANK.EQ('LLM-As-Judge Details'!J6,'LLM-As-Judge Details'!$J$2:$J$16) -> 2 | C26: =_xlfn.RANK.EQ('LLM-As-Judge Details'!K6,'LLM-As-Judge Details'!$K$2:$K$16) -> 1 | D26: =_xlfn.RANK.EQ('LLM-As-Judge Details'!L6,'LLM-As-Judge Details'!$L$2:$L$16) -> 11 | E26: =_xlfn.RANK.EQ('LLM-As-Judge Details'!M6,'LLM-As-Judge Details'!$M$2:$M$16) -> 15 | F26: =_xlfn.RANK.EQ('LLM-As-Judge Details'!N6,'LLM-As-Judge Details'!$N$2:$N$16) -> 7 | G26: =_xlfn.RANK.EQ('LLM-As-Judge Details'!O11,'LLM-As-Judge Details'!$O$2:$O$16) -> 7
A27: 30 | B27: =_xlfn.RANK.EQ('LLM-As-Judge Details'!J7,'LLM-As-Judge Details'!$J$2:$J$16) -> 13 | C27: =_xlfn.RANK.EQ('LLM-As-Judge Details'!K7,'LLM-As-Judge Details'!$K$2:$K$16) -> 1 | D27: =_xlfn.RANK.EQ('LLM-As-Judge Details'!L7,'LLM-As-Judge Details'!$L$2:$L$16) -> 6 | E27: =_xlfn.RANK.EQ('LLM-As-Judge Details'!M7,'LLM-As-Judge Details'!$M$2:$M$16) -> 2 | F27: =_xlfn.RANK.EQ('LLM-As-Judge Details'!N7,'LLM-As-Judge Details'!$N$2:$N$16) -> 7 | G27: =_xlfn.RANK.EQ('LLM-As-Judge Details'!O12,'LLM-As-Judge Details'!$O$2:$O$16) -> 1
A28: 33 | B28: =_xlfn.RANK.EQ('LLM-As-Judge Details'!J8,'LLM-As-Judge Details'!$J$2:$J$16) -> 12 | C28: =_xlfn.RANK.EQ('LLM-As-Judge Details'!K8,'LLM-As-Judge Details'!$K$2:$K$16) -> 1 | D28: =_xlfn.RANK.EQ('LLM-As-Judge Details'!L8,'LLM-As-Judge Details'!$L$2:$L$16) -> 9 | E28: =_xlfn.RANK.EQ('LLM-As-Judge Details'!M8,'LLM-As-Judge Details'!$M$2:$M$16) -> 1 | F28: =_xlfn.RANK.EQ('LLM-As-Judge Details'!N8,'LLM-As-Judge Details'!$N$2:$N$16) -> 2 | G28: =_xlfn.RANK.EQ('LLM-As-Judge Details'!O13,'LLM-As-Judge Details'!$O$2:$O$16) -> 9
A29: 34 | B29: =_xlfn.RANK.EQ('LLM-As-Judge Details'!J9,'LLM-As-Judge Details'!$J$2:$J$16) -> 14 | C29: =_xlfn.RANK.EQ('LLM-As-Judge Details'!K9,'LLM-As-Judge Details'!$K$2:$K$16) -> 12 | D29: =_xlfn.RANK.EQ('LLM-As-Judge Details'!L9,'LLM-As-Judge Details'!$L$2:$L$16) -> 15 | E29: =_xlfn.RANK.EQ('LLM-As-Judge Details'!M9,'LLM-As-Judge Details'!$M$2:$M$16) -> 9 | F29: =_xlfn.RANK.EQ('LLM-As-Judge Details'!N9,'LLM-As-Judge Details'!$N$2:$N$16) -> 7 | G29: =_xlfn.RANK.EQ('LLM-As-Judge Details'!O14,'LLM-As-Judge Details'!$O$2:$O$16) -> 9
A30: 64 | B30: =_xlfn.RANK.EQ('LLM-As-Judge Details'!J10,'LLM-As-Judge Details'!$J$2:$J$16) -> 2 | C30: =_xlfn.RANK.EQ('LLM-As-Judge Details'!K10,'LLM-As-Judge Details'!$K$2:$K$16) -> 11 | D30: =_xlfn.RANK.EQ('LLM-As-Judge Details'!L10,'LLM-As-Judge Details'!$L$2:$L$16) -> 4 | E30: =_xlfn.RANK.EQ('LLM-As-Judge Details'!M10,'LLM-As-Judge Details'!$M$2:$M$16) -> 6 | F30: =_xlfn.RANK.EQ('LLM-As-Judge Details'!N10,'LLM-As-Judge Details'!$N$2:$N$16) -> 7 | G30: =_xlfn.RANK.EQ('LLM-As-Judge Details'!O15,'LLM-As-Judge Details'!$O$2:$O$16) -> 9
A31: 65 | B31: =_xlfn.RANK.EQ('LLM-As-Judge Details'!J11,'LLM-As-Judge Details'!$J$2:$J$16) -> 5 | C31: =_xlfn.RANK.EQ('LLM-As-Judge Details'!K11,'LLM-As-Judge Details'!$K$2:$K$16) -> 1 | D31: =_xlfn.RANK.EQ('LLM-As-Judge Details'!L11,'LLM-As-Judge Details'!$L$2:$L$16) -> 1 | E31: =_xlfn.RANK.EQ('LLM-As-Judge Details'!M11,'LLM-As-Judge Details'!$M$2:$M$16) -> 3 | F31: =_xlfn.RANK.EQ('LLM-As-Judge Details'!N11,'LLM-As-Judge Details'!$N$2:$N$16) -> 6 | G31: =_xlfn.RANK.EQ('LLM-As-Judge Details'!O16,'LLM-As-Judge Details'!$O$2:$O$16) -> 2
A32: 84 | B32: =_xlfn.RANK.EQ('LLM-As-Judge Details'!J12,'LLM-As-Judge Details'!$J$2:$J$16) -> 2 | C32: =_xlfn.RANK.EQ('LLM-As-Judge Details'!K12,'LLM-As-Judge Details'!$K$2:$K$16) -> 1 | D32: =_xlfn.RANK.EQ('LLM-As-Judge Details'!L12,'LLM-As-Judge Details'!$L$2:$L$16) -> 10 | E32: =_xlfn.RANK.EQ('LLM-As-Judge Details'!M12,'LLM-As-Judge Details'!$M$2:$M$16) -> 10 | F32: =_xlfn.RANK.EQ('LLM-As-Judge Details'!N12,'LLM-As-Judge Details'!$N$2:$N$16) -> 7 | G32: =_xlfn.RANK.EQ('LLM-As-Judge Details'!O17,'LLM-As-Judge Details'!$O$2:$O$16) -> 9
A33: 89 | B33: =_xlfn.RANK.EQ('LLM-As-Judge Details'!J13,'LLM-As-Judge Details'!$J$2:$J$16) -> 14 | C33: =_xlfn.RANK.EQ('LLM-As-Judge Details'!K13,'LLM-As-Judge Details'!$K$2:$K$16) -> 12 | D33: =_xlfn.RANK.EQ('LLM-As-Judge Details'!L13,'LLM-As-Judge Details'!$L$2:$L$16) -> 14 | E33: =_xlfn.RANK.EQ('LLM-As-Judge Details'!M13,'LLM-As-Judge Details'!$M$2:$M$16) -> 14 | F33: =_xlfn.RANK.EQ('LLM-As-Judge Details'!N13,'LLM-As-Judge Details'!$N$2:$N$16) -> 7 | G33: =_xlfn.RANK.EQ('LLM-As-Judge Details'!O18,'LLM-As-Judge Details'!$O$2:$O$16) -> 9
... A36: 110 | B36: =_xlfn.RANK.EQ('LLM-As-Judge Details'!J16,'LLM-As-Judge Details'!$J$2:$J$16) -> 7 | C36: =_xlfn.RANK.EQ('LLM-As-Judge Details'!K16,'LLM-As-Judge Details'!$K$2:$K$16) -> 9 | D36: =_xlfn.RANK.EQ('LLM-As-Judge Details'!L16,'LLM-As-Judge Details'!$L$2:$L$16) -> 12 | E36: =_xlfn.RANK.EQ('LLM-As-Judge Details'!M16,'LLM-As-Judge Details'!$M$2:$M$16) -> 8 | F36: =_xlfn.RANK.EQ('LLM-As-Judge Details'!N16,'LLM-As-Judge Details'!$N$2:$N$16) -> 5 | G36: =_xlfn.RANK.EQ('LLM-As-Judge Details'!O21,'LLM-As-Judge Details'!$O$2:$O$16) -> 9
A39: gpt4o-mini
A40: ID | B40: faithfulness | C40: context_recall | D40: context_precision | E40: semantic_similarity | F40: context_entity_recall | G40: answer_relevancy
A41: 1 | B41: =_xlfn.RANK.EQ('GPT4o-mini-Details'!J2,'GPT4o-mini-Details'!$J$2:$J$16) -> 4 | C41: =_xlfn.RANK.EQ('GPT4o-mini-Details'!K2,'GPT4o-mini-Details'!$K$2:$K$16) -> 1 | D41: =_xlfn.RANK.EQ('GPT4o-mini-Details'!L2,'GPT4o-mini-Details'!$L$2:$L$16) -> 1 | E41: =_xlfn.RANK.EQ('GPT4o-mini-Details'!M2,'GPT4o-mini-Details'!$M$2:$M$16) -> 13 | F41: =_xlfn.RANK.EQ('GPT4o-mini-Details'!N2,'GPT4o-mini-Details'!$N$2:$N$16) -> 6 | G41: =_xlfn.RANK.EQ('GPT4o-mini-Details'!O2,'GPT4o-mini-Details'!$O$2:$O$16) -> 5
A42: 8 | B42: =_xlfn.RANK.EQ('GPT4o-mini-Details'!J3,'GPT4o-mini-Details'!$J$2:$J$16) -> 10 | C42: =_xlfn.RANK.EQ('GPT4o-mini-Details'!K3,'GPT4o-mini-Details'!$K$2:$K$16) -> 9 | D42: =_xlfn.RANK.EQ('GPT4o-mini-Details'!L3,'GPT4o-mini-Details'!$L$2:$L$16) -> 8 | E42: =_xlfn.RANK.EQ('GPT4o-mini-Details'!M3,'GPT4o-mini-Details'!$M$2:$M$16) -> 12 | F42: =_xlfn.RANK.EQ('GPT4o-mini-Details'!N3,'GPT4o-mini-Details'!$N$2:$N$16) -> 9 | G42: =_xlfn.RANK.EQ('GPT4o-mini-Details'!O3,'GPT4o-mini-Details'!$O$2:$O$16) -> 9
A43: 11 | B43: =_xlfn.RANK.EQ('GPT4o-mini-Details'!J4,'GPT4o-mini-Details'!$J$2:$J$16) -> 5 | C43: =_xlfn.RANK.EQ('GPT4o-mini-Details'!K4,'GPT4o-mini-Details'!$K$2:$K$16) -> 1 | D43: =_xlfn.RANK.EQ('GPT4o-mini-Details'!L4,'GPT4o-mini-Details'!$L$2:$L$16) -> 6 | E43: =_xlfn.RANK.EQ('GPT4o-mini-Details'!M4,'GPT4o-mini-Details'!$M$2:$M$16) -> 11 | F43: =_xlfn.RANK.EQ('GPT4o-mini-Details'!N4,'GPT4o-mini-Details'!$N$2:$N$16) -> 1 | G43: =_xlfn.RANK.EQ('GPT4o-mini-Details'!O4,'GPT4o-mini-Details'!$O$2:$O$16) -> 9
A44: 17 | B44: =_xlfn.RANK.EQ('GPT4o-mini-Details'!J5,'GPT4o-mini-Details'!$J$2:$J$16) -> 8 | C44: =_xlfn.RANK.EQ('GPT4o-mini-Details'!K5,'GPT4o-mini-Details'!$K$2:$K$16) -> 1 | D44: =_xlfn.RANK.EQ('GPT4o-mini-Details'!L5,'GPT4o-mini-Details'!$L$2:$L$16) -> 14 | E44: =_xlfn.RANK.EQ('GPT4o-mini-Details'!M5,'GPT4o-mini-Details'!$M$2:$M$16) -> 7 | F44: =_xlfn.RANK.EQ('GPT4o-mini-Details'!N5,'GPT4o-mini-Details'!$N$2:$N$16) -> 6 | G44: =_xlfn.RANK.EQ('GPT4o-mini-Details'!O5,'GPT4o-mini-Details'!$O$2:$O$16) -> 9
A45: 20 | B45: =_xlfn.RANK.EQ('GPT4o-mini-Details'!J6,'GPT4o-mini-Details'!$J$2:$J$16) -> 7 | C45: =_xlfn.RANK.EQ('GPT4o-mini-Details'!K6,'GPT4o-mini-Details'!$K$2:$K$16) -> 10 | D45: =_xlfn.RANK.EQ('GPT4o-mini-Details'!L6,'GPT4o-mini-Details'!$L$2:$L$16) -> 7 | E45: =_xlfn.RANK.EQ('GPT4o-mini-Details'!M6,'GPT4o-mini-Details'!$M$2:$M$16) -> 15 | F45: =_xlfn.RANK.EQ('GPT4o-mini-Details'!N6,'GPT4o-mini-Details'!$N$2:$N$16) -> 9 | G45: =_xlfn.RANK.EQ('GPT4o-mini-Details'!O6,'GPT4o-mini-Details'!$O$2:$O$16) -> 7
A46: 30 | B46: =_xlfn.RANK.EQ('GPT4o-mini-Details'!J7,'GPT4o-mini-Details'!$J$2:$J$16) -> 1 | C46: =_xlfn.RANK.EQ('GPT4o-mini-Details'!K7,'GPT4o-mini-Details'!$K$2:$K$16) -> 1 | D46: =_xlfn.RANK.EQ('GPT4o-mini-Details'!L7,'GPT4o-mini-Details'!$L$2:$L$16) -> 9 | E46: =_xlfn.RANK.EQ('GPT4o-mini-Details'!M7,'GPT4o-mini-Details'!$M$2:$M$16) -> 2 | F46: =_xlfn.RANK.EQ('GPT4o-mini-Details'!N7,'GPT4o-mini-Details'!$N$2:$N$16) -> 9 | G46: =_xlfn.RANK.EQ('GPT4o-mini-Details'!O7,'GPT4o-mini-Details'!$O$2:$O$16) -> 4
A47: 33 | B47: =_xlfn.RANK.EQ('GPT4o-mini-Details'!J8,'GPT4o-mini-Details'!$J$2:$J$16) -> 8 | C47: =_xlfn.RANK.EQ('GPT4o-mini-Details'!K8,'GPT4o-mini-Details'!$K$2:$K$16) -> 1 | D47: =_xlfn.RANK.EQ('GPT4o-mini-Details'!L8,'GPT4o-mini-Details'!$L$2:$L$16) -> 10 | E47: =_xlfn.RANK.EQ('GPT4o-mini-Details'!M8,'GPT4o-mini-Details'!$M$2:$M$16) -> 1 | F47: =_xlfn.RANK.EQ('GPT4o-mini-Details'!N8,'GPT4o-mini-Details'!$N$2:$N$16) -> 9 | G47: =_xlfn.RANK.EQ('GPT4o-mini-Details'!O8,'GPT4o-mini-Details'!$O$2:$O$16) -> 2
A48: 34 | B48: =_xlfn.RANK.EQ('GPT4o-mini-Details'!J9,'GPT4o-mini-Details'!$J$2:$J$16) -> 14 | C48: =_xlfn.RANK.EQ('GPT4o-mini-Details'!K9,'GPT4o-mini-Details'!$K$2:$K$16) -> 12 | D48: =_xlfn.RANK.EQ('GPT4o-mini-Details'!L9,'GPT4o-mini-Details'!$L$2:$L$16) -> 15 | E48: =_xlfn.RANK.EQ('GPT4o-mini-Details'!M9,'GPT4o-mini-Details'!$M$2:$M$16) -> 9 | F48: =_xlfn.RANK.EQ('GPT4o-mini-Details'!N9,'GPT4o-mini-Details'!$N$2:$N$16) -> 9 | G48: =_xlfn.RANK.EQ('GPT4o-mini-Details'!O9,'GPT4o-mini-Details'!$O$2:$O$16) -> 1
...

Sheet Korrelationen
A1: Rangkorrelation | B1: faithfulness | C1: context_recall | D1: context_precision | E1: semantic_similarity | F1: context_entity_recall | G1: answer_relevancy
A2: qwen | B2: =CORREL(Ränge!B3:B17,Ränge!B22:B36) -> 0.57370678 | C2: =CORREL(Ränge!C3:C17,Ränge!C22:C36) -> 0.74415851 | D2: =CORREL(Ränge!D3:D17,Ränge!D22:D36) -> 0.22305764 | E2: =CORREL(Ränge!E3:E17,Ränge!E22:E36) -> 0.047693781 | F2: =CORREL(Ränge!F3:F17,Ränge!F22:F36) -> 0.45819723 | G2: =CORREL(Ränge!G3:G17,Ränge!G22:G36) -> -0.14656358
A3: gpt4o-mini | B3: =CORREL(Ränge!B3:B17,Ränge!B41:B55) -> 0.56436406 | C3: =CORREL(Ränge!C3:C17,Ränge!C41:C55) -> 0.59462271 | D3: =CORREL(Ränge!D3:D17,Ränge!D41:D55) -> 0.3009366 | E3: =CORREL(Ränge!E3:E17,Ränge!E41:E55) -> 0.047693781 | F3: =CORREL(Ränge!F3:F17,Ränge!F41:F55) -> 0.48759105 | G3: =CORREL(Ränge!G3:G17,Ränge!G41:G55) -> 0.58980493
A4: gpt-4.1 | B4: =CORREL(Ränge!B3:B17, Ränge!B60:B74) -> 0.2043488 | C4: =CORREL(Ränge!C3:C17, Ränge!C60:C74) -> 0.19377776 | D4: =CORREL(Ränge!D3:D17, Ränge!D60:D74) -> -0.15423533 | E4: =CORREL(Ränge!E3:E17, Ränge!E60:E74) -> -0.4871579 | F4: =CORREL(Ränge!F3:F17, Ränge!F60:F74) -> -0.27500567 | G4: =CORREL(Ränge!G3:G17, Ränge!G60:G74) -> 0.20069751
A5: gpt-5.2 | B5: =CORREL(Ränge!B3:B17, Ränge!B79:B93) -> 0.50725933 | C5: =CORREL(Ränge!C3:C17, Ränge!C79:C93) -> 0.73104248 | D5: =CORREL(Ränge!D3:D17, Ränge!D79:D93) -> 0.75094236 | E5: =CORREL(Ränge!E3:E17, Ränge!E79:E93) -> 0.047693781 | F5: =CORREL(Ränge!F3:F17, Ränge!F79:F93) -> 0.74855081 | G5: =CORREL(Ränge!G3:G17, Ränge!G79:G93) -> 0.14822493
A6: gpt-4.1-mini | B6: =CORREL(Ränge!B3:B17, Ränge!B117:B131) -> 0.53558363 | C6: =CORREL(Ränge!C3:C17, Ränge!C117:C131) -> 0.58594568 | D6: =CORREL(Ränge!D3:D17, Ränge!D117:D131) -> 0.50327669 | E6: =CORREL(Ränge!E3:E17, Ränge!E117:E131) -> 0.2452823 | F6: =CORREL(Ränge!F3:F17, Ränge!F117:F131) -> 0.40351567 | G6: =CORREL(Ränge!G3:G17, Ränge!G117:G131) -> 0.44812488
A9: Pearson Korrelation | B9: faithfulness | C9: context_recall | D9: context_precision | E9: semantic_similarity | F9: context_entity_recall | G9: answer_relevancy
A10: qwen | B10: =PEARSON('Human Details'!$J$2:$J$16, 'LLM-As-Judge Details'!$J$2:$J$16) -> 0.65302115 | C10: =PEARSON('Human Details'!$K$2:$K$16, 'LLM-As-Judge Details'!$K$2:$K$16) -> 0.73529279 | D10: =PEARSON('Human Details'!$L$2:$L$16, 'LLM-As-Judge Details'!$L$2:$L$16) -> 0.41218722 | E10: =PEARSON('Human Details'!$M$2:$M$16, 'LLM-As-Judge Details'!$M$2:$M$16) -> 0.14385935 | F10: =PEARSON('Human Details'!$N$2:$N$16, 'LLM-As-Judge Details'!$N$2:$N$16) -> 0.16880378 | G10: =PEARSON('Human Details'!$O$2:$O$16, 'LLM-As-Judge Details'!$O$2:$O$16) -> 0.37830878
A11: gpt4o-mini | B11: =PEARSON('Human Details'!$J$2:$J$16, 'GPT4o-mini-Details'!$J$2:$J$16) -> 0.64855385 | C11: =PEARSON('Human Details'!$K$2:$K$16, 'GPT4o-mini-Details'!$K$2:$K$16) -> 0.59067257 | D11: =PEARSON('Human Details'!$L$2:$L$16, 'GPT4o-mini-Details'!$L$2:$L$16) -> 0.58517312 | E11: =PEARSON('Human Details'!$M$2:$M$16, 'GPT4o-mini-Details'!$M$2:$M$16) -> 0.14385935 | F11: =PEARSON('Human Details'!$N$2:$N$16, 'GPT4o-mini-Details'!$N$2:$N$16) -> 0.18258654 | G11: =PEARSON('Human Details'!$O$2:$O$16, 'GPT4o-mini-Details'!$O$2:$O$16) -> 0.69920987
A12: gpt-4.1 | B12: =PEARSON('Human Details'!$J$2:$J$16, 'gpt-4.1-Details'!$J$2:$J$16) -> 0.31901447 | C12: =PEARSON('Human Details'!$K$2:$K$16, 'gpt-4.1-Details'!$K$2:$K$16) -> 0.17682219 | D12: =PEARSON('Human Details'!$L$2:$L$16, 'gpt-4.1-Details'!$L$2:$L$16) -> -0.15955961 | E12: =PEARSON('Human Details'!$M$2:$M$16, 'gpt-4.1-Details'!$M$2:$M$16) -> -0.42476534 | F12: =PEARSON('Human Details'!$N$2:$N$16, 'gpt-4.1-Details'!$N$2:$N$16) -> -0.28831767 | G12: =PEARSON('Human Details'!$O$2:$O$16, 'gpt-4.1-Details'!$O$2:$O$16) -> 0.31097902
A13: gpt-5.2 | B13: =PEARSON('Human Details'!$J$2:$J$16, 'gpt-5.2-Details'!$J$2:$J$16) -> 0.63105836 | C13: =PEARSON('Human Details'!$K$2:$K$16, 'gpt-5.2-Details'!$K$2:$K$16) -> 0.67944728 | D13: =PEARSON('Human Details'!$L$2:$L$16, 'gpt-5.2-Details'!$L$2:$L$16) -> 0.68822528 | E13: =PEARSON('Human Details'!$M$2:$M$16, 'gpt-5.2-Details'!$M$2:$M$16) -> 0.14385935 | F13: =PEARSON('Human Details'!$N$2:$N$16, 'gpt-5.2-Details'!$N$2:$N$16) -> 0.45089067 | G13: =PEARSON('Human Details'!$O$2:$O$16, 'gpt-5.2-Details'!$O$2:$O$16) -> 0.40086275
A14: gpt-4.1-mini | B14: =PEARSON('Human Details'!$J$2:$J$16, 'gpt-4.1-mini-Details'!$J$2:$J$16) -> 0.73322698 | C14: =PEARSON('Human Details'!$K$2:$K$16, 'gpt-4.1-mini-Details'!$K$2:$K$16) -> 0.56215487 | D14: =PEARSON('Human Details'!$L$2:$L$16, 'gpt-4.1-mini-Details'!$L$2:$L$16) -> 0.5510758 | E14: =PEARSON('Human Details'!$M$2:$M$16, 'gpt-4.1-mini-Details'!$M$2:$M$16) -> 0.26938296 | F14: =PEARSON('Human Details'!$N$2:$N$16, 'gpt-4.1-mini-Details'!$N$2:$N$16) -> 0.36082996 | G14: =PEARSON('Human Details'!$O$2:$O$16, 'gpt-4.1-mini-Details'!$O$2:$O$16) -> 0.46513088

Sheet Metriken_qwen
B1: Abs
A2: ID | B2: faithfulness | C2: context_recall | D2: context_precision | E2: semantic_similarity | F2: context_entity_recall | G2: answer_relevancy
A3: 1 | B3: =ABS('Human Details'!J2-'LLM-As-Judge Details'!J2) -> 0.14285714 | C3: =ABS('Human Details'!K2-'LLM-As-Judge Details'!K2) -> 0 | D3: =ABS('Human Details'!L2-'LLM-As-Judge Details'!L2) -> 0.26333333 | E3: =ABS('Human Details'!M2-'GPT4o-mini-Details'!M2) -> 0.058254654 | F3: =ABS('Human Details'!N2-'LLM-As-Judge Details'!N2) -> 0.34343434 | G3: =ABS('Human Details'!O2-'LLM-As-Judge Details'!O2) -> 0.17067878
A4: 8 | B4: =ABS('Human Details'!J3-'LLM-As-Judge Details'!J3) -> 0.1 | C4: =ABS('Human Details'!K3-'LLM-As-Judge Details'!K3) -> 0 | D4: =ABS('Human Details'!L3-'LLM-As-Judge Details'!L3) -> 1.0000001e-10 | E4: =ABS('Human Details'!M3-'GPT4o-mini-Details'!M3) -> 0.71366373 | F4: =ABS('Human Details'!N3-'LLM-As-Judge Details'!N3) -> 0 | G4: =ABS('Human Details'!O3-'LLM-As-Judge Details'!O3) -> 0
A5: 11 | B5: =ABS('Human Details'!J4-'LLM-As-Judge Details'!J4) -> 0 | C5: =ABS('Human Details'!K4-'LLM-As-Judge Details'!K4) -> 0 | D5: =ABS('Human Details'!L4-'LLM-As-Judge Details'!L4) -> 3.3333336e-11 | E5: =ABS('Human Details'!M4-'GPT4o-mini-Details'!M4) -> 0.21741346 | F5: =ABS('Human Details'!N4-'LLM-As-Judge Details'!N4) -> 0.52727273 | G5: =ABS('Human Details'!O4-'LLM-As-Judge Details'!O4) -> 0.5
A6: 17 | B6: =ABS('Human Details'!J5-'LLM-As-Judge Details'!J5) -> 0.16666667 | C6: =ABS('Human Details'!K5-'LLM-As-Judge Details'!K5) -> 0.33333333 | D6: =ABS('Human Details'!L5-'LLM-As-Judge Details'!L5) -> 0.675 | E6: =ABS('Human Details'!M5-'GPT4o-mini-Details'!M5) -> 0.26307918 | F6: =ABS('Human Details'!N5-'LLM-As-Judge Details'!N5) -> 0.22222222 | G6: =ABS('Human Details'!O5-'LLM-As-Judge Details'!O5) -> 0.5
A7: 20 | B7: =ABS('Human Details'!J6-'LLM-As-Judge Details'!J6) -> 0.1 | C7: =ABS('Human Details'!K6-'LLM-As-Judge Details'!K6) -> 0.25 | D7: =ABS('Human Details'!L6-'LLM-As-Judge Details'!L6) -> 0.3 | E7: =ABS('Human Details'!M6-'GPT4o-mini-Details'!M6) -> 0.047320968 | F7: =ABS('Human Details'!N6-'LLM-As-Judge Details'!N6) -> 0.25 | G7: =ABS('Human Details'!O6-'LLM-As-Judge Details'!O6) -> 0.24063257
A8: 30 | B8: =ABS('Human Details'!J7-'LLM-As-Judge Details'!J7) -> 0.083333333 | C8: =ABS('Human Details'!K7-'LLM-As-Judge Details'!K7) -> 1 | D8: =ABS('Human Details'!L7-'LLM-As-Judge Details'!L7) -> 0.25 | E8: =ABS('Human Details'!M7-'GPT4o-mini-Details'!M7) -> 0.61740094 | F8: =ABS('Human Details'!N7-'LLM-As-Judge Details'!N7) -> 0 | G8: =ABS('Human Details'!O7-'LLM-As-Judge Details'!O7) -> 0.25
A9: 33 | B9: =ABS('Human Details'!J8-'LLM-As-Judge Details'!J8) -> 0.16666667 | C9: =ABS('Human Details'!K8-'LLM-As-Judge Details'!K8) -> 0 | D9: =ABS('Human Details'!L8-'LLM-As-Judge Details'!L8) -> 0.0033333334 | E9: =ABS('Human Details'!M8-'GPT4o-mini-Details'!M8) -> 0.13175794 | F9: =ABS('Human Details'!N8-'LLM-As-Judge Details'!N8) -> 0.75 | G9: =ABS('Human Details'!O8-'LLM-As-Judge Details'!O8) -> 0.12696433
A10: 34 | B10: =ABS('Human Details'!J9-'LLM-As-Judge Details'!J9) -> 0 | C10: =ABS('Human Details'!K9-'LLM-As-Judge Details'!K9) -> 0 | D10: =ABS('Human Details'!L9-'LLM-As-Judge Details'!L9) -> 0 | E10: =ABS('Human Details'!M9-'GPT4o-mini-Details'!M9) -> 0.24801994 | F10: =ABS('Human Details'!N9-'LLM-As-Judge Details'!N9) -> 0 | G10: =ABS('Human Details'!O9-'LLM-As-Judge Details'!O9) -> 0.073886782
A11: 64 | B11: =ABS('Human Details'!J10-'LLM-As-Judge Details'!J10) -> 0.8 | C11: =ABS('Human Details'!K10-'LLM-As-Judge Details'!K10) -> 0.14285714 | D11: =ABS('Human Details'!L10-'LLM-As-Judge Details'!L10) -> 1 | E11: =ABS('Human Details'!M10-'GPT4o-mini-Details'!M10) -> 0.80823798 | F11: =ABS('Human Details'!N10-'LLM-As-Judge Details'!N10) -> 0 | G11: =ABS('Human Details'!O10-'LLM-As-Judge Details'!O10) -> 0.90574995
A12: 65 | B12: =ABS('Human Details'!J11-'LLM-As-Judge Details'!J11) -> 0 | C12: =ABS('Human Details'!K11-'LLM-As-Judge Details'!K11) -> 0 | D12: =ABS('Human Details'!L11-'LLM-As-Judge Details'!L11) -> 2.0000002e-11 | E12: =ABS('Human Details'!M11-'GPT4o-mini-Details'!M11) -> 0.35041125 | F12: =ABS('Human Details'!N11-'LLM-As-Judge Details'!N11) -> 0.94117647 | G12: =ABS('Human Details'!O11-'LLM-As-Judge Details'!O11) -> 0.27756833
A13: 84 | B13: =ABS('Human Details'!J12-'LLM-As-Judge Details'!J12) -> 0.085714286 | C13: =ABS('Human Details'!K12-'LLM-As-Judge Details'!K12) -> 0.6 | D13: =ABS('Human Details'!L12-'LLM-As-Judge Details'!L12) -> 0.24444444 | E13: =ABS('Human Details'!M12-'GPT4o-mini-Details'!M12) -> 0.22480964 | F13: =ABS('Human Details'!N12-'LLM-As-Judge Details'!N12) -> 0.11428571 | G13: =ABS('Human Details'!O12-'LLM-As-Judge Details'!O12) -> 0.040120446
A14: 89 | B14: =ABS('Human Details'!J13-'LLM-As-Judge Details'!J13) -> 0 | C14: =ABS('Human Details'!K13-'LLM-As-Judge Details'!K13) -> 0 | D14: =ABS('Human Details'!L13-'LLM-As-Judge Details'!L13) -> 0.2 | E14: =ABS('Human Details'!M13-'GPT4o-mini-Details'!M13) -> 0.57422404 | F14: =ABS('Human Details'!N13-'LLM-As-Judge Details'!N13) -> 0 | G14: =ABS('Human Details'!O13-'LLM-As-Judge Details'!O13) -> 0.2
... A17: 110 | B17: =ABS('Human Details'!J16-'LLM-As-Judge Details'!J16) -> 0.30555556 | C17: =ABS('Human Details'!K16-'LLM-As-Judge Details'!K16) -> 0.05 | D17: =ABS('Human Details'!L16-'LLM-As-Judge Details'!L16) -> 0.46666667 | E17: =ABS('Human Details'!M16-'GPT4o-mini-Details'!M16) -> 0.5122081 | F17: =ABS('Human Details'!N16-'LLM-As-Judge Details'!N16) -> 0.18623482 | G17: =ABS('Human Details'!O16-'LLM-As-Judge Details'!O16) -> 0.67710613
B19: faithfulness | C19: context_recall | D19: context_precision | E19: semantic_similarity | F19: context_entity_recall | G19: answer_relevancy | L19: Mittelwert
A20: MAE Mittelwert | B20: =AVERAGE(B3:B17) -> 0.13983923 | C20: =AVERAGE(C3:C17) -> 0.17031746 | D20: =AVERAGE(D3:D17) -> 0.28601852 | E20: =AVERAGE(E3:E17) -> 0.37915235 | F20: =AVERAGE(F3:F17) -> 0.30589816 | G20: =AVERAGE(G3:G17) -> 0.36418049 | L20: MAE
L21: Spearman

Sheet Metriken_gpt4o-mini
B1: Abs
A2: ID | B2: faithfulness | C2: context_recall | D2: context_precision | E2: semantic_similarity | F2: context_entity_recall | G2: answer_relevancy
A3: 1 | B3: =ABS('Human Details'!J2-'GPT4o-mini-Details'!J2) -> 0.058823529 | C3: =ABS('Human Details'!K2-'GPT4o-mini-Details'!K2) -> 0 | D3: =ABS('Human Details'!L2-'GPT4o-mini-Details'!L2) -> 0.32 | E3: =ABS('Human Details'!M2-'GPT4o-mini-Details'!M2) -> 0.058254654 | F3: =ABS('Human Details'!N2-'GPT4o-mini-Details'!N2) -> 0.34343434 | G3: =ABS('Human Details'!O2-'GPT4o-mini-Details'!O2) -> 0.16082544
A4: 8 | B4: =ABS('Human Details'!J3-'GPT4o-mini-Details'!J3) -> 0.045454545 | C4: =ABS('Human Details'!K3-'GPT4o-mini-Details'!K3) -> 0.66666667 | D4: =ABS('Human Details'!L3-'GPT4o-mini-Details'!L3) -> 1.0000001e-10 | E4: =ABS('Human Details'!M3-'GPT4o-mini-Details'!M3) -> 0.71366373 | F4: =ABS('Human Details'!N3-'GPT4o-mini-Details'!N3) -> 0 | G4: =ABS('Human Details'!O3-'GPT4o-mini-Details'!O3) -> 0
A5: 11 | B5: =ABS('Human Details'!J4-'GPT4o-mini-Details'!J4) -> 0.3 | C5: =ABS('Human Details'!K4-'GPT4o-mini-Details'!K4) -> 0 | D5: =ABS('Human Details'!L4-'GPT4o-mini-Details'!L4) -> 3.3333336e-11 | E5: =ABS('Human Details'!M4-'GPT4o-mini-Details'!M4) -> 0.21741346 | F5: =ABS('Human Details'!N4-'GPT4o-mini-Details'!N4) -> 0.42727273 | G5: =ABS('Human Details'!O4-'GPT4o-mini-Details'!O4) -> 0.5
A6: 17 | B6: =ABS('Human Details'!J5-'GPT4o-mini-Details'!J5) -> 0.16666667 | C6: =ABS('Human Details'!K5-'GPT4o-mini-Details'!K5) -> 0.66666667 | D6: =ABS('Human Details'!L5-'GPT4o-mini-Details'!L5) -> 0.20833333 | E6: =ABS('Human Details'!M5-'GPT4o-mini-Details'!M5) -> 0.26307918 | F6: =ABS('Human Details'!N5-'GPT4o-mini-Details'!N5) -> 0.22222222 | G6: =ABS('Human Details'!O5-'GPT4o-mini-Details'!O5) -> 0.5
A7: 20 | B7: =ABS('Human Details'!J6-'GPT4o-mini-Details'!J6) -> 0.3 | C7: =ABS('Human Details'!K6-'GPT4o-mini-Details'!K6) -> 0.15 | D7: =ABS('Human Details'!L6-'GPT4o-mini-Details'!L6) -> 5.0000004e-11 | E7: =ABS('Human Details'!M6-'GPT4o-mini-Details'!M6) -> 0.047320968 | F7: =ABS('Human Details'!N6-'GPT4o-mini-Details'!N6) -> 0.25 | G7: =ABS('Human Details'!O6-'GPT4o-mini-Details'!O6) -> 0.0046252433
A8: 30 | B8: =ABS('Human Details'!J7-'GPT4o-mini-Details'!J7) -> 0.66666667 | C8: =ABS('Human Details'!K7-'GPT4o-mini-Details'!K7) -> 1 | D8: =ABS('Human Details'!L7-'GPT4o-mini-Details'!L7) -> 0.16666667 | E8: =ABS('Human Details'!M7-'GPT4o-mini-Details'!M7) -> 0.61740094 | F8: =ABS('Human Details'!N7-'GPT4o-mini-Details'!N7) -> 0 | G8: =ABS('Human Details'!O7-'GPT4o-mini-Details'!O7) -> 0.65348978
A9: 33 | B9: =ABS('Human Details'!J8-'GPT4o-mini-Details'!J8) -> 0 | C9: =ABS('Human Details'!K8-'GPT4o-mini-Details'!K8) -> 0 | D9: =ABS('Human Details'!L8-'GPT4o-mini-Details'!L8) -> 0.0033333334 | E9: =ABS('Human Details'!M8-'GPT4o-mini-Details'!M8) -> 0.13175794 | F9: =ABS('Human Details'!N8-'GPT4o-mini-Details'!N8) -> 1 | G9: =ABS('Human Details'!O8-'GPT4o-mini-Details'!O8) -> 0.23911122
A10: 34 | B10: =ABS('Human Details'!J9-'GPT4o-mini-Details'!J9) -> 0 | C10: =ABS('Human Details'!K9-'GPT4o-mini-Details'!K9) -> 0.5 | D10: =ABS('Human Details'!L9-'GPT4o-mini-Details'!L9) -> 0 | E10: =ABS('Human Details'!M9-'GPT4o-mini-Details'!M9) -> 0.24801994 | F10: =ABS('Human Details'!N9-'GPT4o-mini-Details'!N9) -> 0 | G10: =ABS('Human Details'!O9-'GPT4o-mini-Details'!O9) -> 0.0094443726
A11: 64 | B11: =ABS('Human Details'!J10-'GPT4o-mini-Details'!J10) -> 0.44444444 | C11: =ABS('Human Details'!K10-'GPT4o-mini-Details'!K10) -> 0.42857143 | D11: =ABS('Human Details'!L10-'GPT4o-mini-Details'!L10) -> 1 | E11: =ABS('Human Details'!M10-'GPT4o-mini-Details'!M10) -> 0.80823798 | F11: =ABS('Human Details'!N10-'GPT4o-mini-Details'!N10) -> 0 | G11: =ABS('Human Details'!O10-'GPT4o-mini-Details'!O10) -> 0
A12: 65 | B12: =ABS('Human Details'!J11-'GPT4o-mini-Details'!J11) -> 0.33333333 | C12: =ABS('Human Details'!K11-'GPT4o-mini-Details'!K11) -> 0 | D12: =ABS('Human Details'!L11-'GPT4o-mini-Details'!L11) -> 2.0000002e-11 | E12: =ABS('Human Details'!M11-'GPT4o-mini-Details'!M11) -> 0.35041125 | F12: =ABS('Human Details'!N11-'GPT4o-mini-Details'!N11) -> 0.8 | G12: =ABS('Human Details'!O11-'GPT4o-mini-Details'!O11) -> 0.22918357
A13: 84 | B13: =ABS('Human Details'!J12-'GPT4o-mini-Details'!J12) -> 0.28571429 | C13: =ABS('Human Details'!K12-'GPT4o-mini-Details'!K12) -> 0.4 | D13: =ABS('Human Details'!L12-'GPT4o-mini-Details'!L12) -> 0.24444444 | E13: =ABS('Human Details'!M12-'GPT4o-mini-Details'!M12) -> 0.22480964 | F13: =ABS('Human Details'!N12-'GPT4o-mini-Details'!N12) -> 0.039560439 | G13: =ABS('Human Details'!O12-'GPT4o-mini-Details'!O12) -> 0.044786932
A14: 89 | B14: =ABS('Human Details'!J13-'GPT4o-mini-Details'!J13) -> 0 | C14: =ABS('Human Details'!K13-'GPT4o-mini-Details'!K13) -> 0 | D14: =ABS('Human Details'!L13-'GPT4o-mini-Details'!L13) -> 0.7 | E14: =ABS('Human Details'!M13-'GPT4o-mini-Details'!M13) -> 0.57422404 | F14: =ABS('Human Details'!N13-'GPT4o-mini-Details'!N13) -> 0 | G14: =ABS('Human Details'!O13-'GPT4o-mini-Details'!O13) -> 0.2
... A17: 110 | B17: =ABS('Human Details'!J16-'GPT4o-mini-Details'!J16) -> 0.38636364 | C17: =ABS('Human Details'!K16-'GPT4o-mini-Details'!K16) -> 0.3 | D17: =ABS('Human Details'!L16-'GPT4o-mini-Details'!L16) -> 0.083333333 | E17: =ABS('Human Details'!M16-'GPT4o-mini-Details'!M16) -> 0.5122081 | F17: =ABS('Human Details'!N16-'GPT4o-mini-Details'!N16) -> 0.20760234 | G17: =ABS('Human Details'!O16-'GPT4o-mini-Details'!O16) -> 0.25
B19: faithfulness | C19: context_recall | D19: context_precision | E19: semantic_similarity | F19: context_entity_recall | G19: answer_relevancy
A20: MAE Mittelwert | B20: =AVERAGE(B3:B17) -> 0.20735795 | C20: =AVERAGE(C3:C17) -> 0.29936508 | D20: =AVERAGE(D3:D17) -> 0.22433333 | E20: =AVERAGE(E3:E17) -> 0.37915235 | F20: =AVERAGE(F3:F17) -> 0.28340541 | G20: =AVERAGE(G3:G17) -> 0.24001616

Sheet Metriken gpt-4.1
B1: Abs
A2: ID | B2: faithfulness | C2: context_recall | D2: context_precision | E2: semantic_similarity | F2: context_entity_recall | G2: answer_relevancy
A3: 1 | B3: =ABS('Human Details'!J2-'gpt-4.1-Details'!J2) -> 0.058823529 | C3: =ABS('Human Details'!K2-'gpt-4.1-Details'!K2) -> 0 | D3: =ABS('Human Details'!L2-'gpt-4.1-Details'!L2) -> 0.00083333335 | E3: =ABS('Human Details'!M2-'gpt-4.1-Details'!M2) -> 0.058254654 | F3: =ABS('Human Details'!N2-'gpt-4.1-Details'!N2) -> 0.34343434 | G3: =ABS('Human Details'!O2-'gpt-4.1-Details'!O2) -> 0.154211
A4: 8 | B4: =ABS('Human Details'!J3-'gpt-4.1-Details'!J3) -> 0.11538462 | C4: =ABS('Human Details'!K3-'gpt-4.1-Details'!K3) -> 0 | D4: =ABS('Human Details'!L3-'gpt-4.1-Details'!L3) -> 1 | E4: =ABS('Human Details'!M3-'gpt-4.1-Details'!M3) -> 0.71366373 | F4: =ABS('Human Details'!N3-'gpt-4.1-Details'!N3) -> 0 | G4: =ABS('Human Details'!O3-'gpt-4.1-Details'!O3) -> 0
A5: 11 | B5: =ABS('Human Details'!J4-'gpt-4.1-Details'!J4) -> 0.3 | C5: =ABS('Human Details'!K4-'gpt-4.1-Details'!K4) -> 0 | D5: =ABS('Human Details'!L4-'gpt-4.1-Details'!L4) -> 0.05 | E5: =ABS('Human Details'!M4-'gpt-4.1-Details'!M4) -> 0.21741346 | F5: =ABS('Human Details'!N4-'gpt-4.1-Details'!N4) -> 0.27272727 | G5: =ABS('Human Details'!O4-'gpt-4.1-Details'!O4) -> 0.5
A6: 17 | B6: =ABS('Human Details'!J5-'gpt-4.1-Details'!J5) -> 0.066666667 | C6: =ABS('Human Details'!K5-'gpt-4.1-Details'!K5) -> 0.33333333 | D6: =ABS('Human Details'!L5-'gpt-4.1-Details'!L5) -> 0.125 | E6: =ABS('Human Details'!M5-'gpt-4.1-Details'!M5) -> 0.26307918 | F6: =ABS('Human Details'!N5-'gpt-4.1-Details'!N5) -> 0.066666666 | G6: =ABS('Human Details'!O5-'gpt-4.1-Details'!O5) -> 0.5
A7: 20 | B7: =ABS('Human Details'!J6-'gpt-4.1-Details'!J6) -> 0.1 | C7: =ABS('Human Details'!K6-'gpt-4.1-Details'!K6) -> 0.13888889 | D7: =ABS('Human Details'!L6-'gpt-4.1-Details'!L6) -> 0.3 | E7: =ABS('Human Details'!M6-'gpt-4.1-Details'!M6) -> 0.047320968 | F7: =ABS('Human Details'!N6-'gpt-4.1-Details'!N6) -> 0.13888889 | G7: =ABS('Human Details'!O6-'gpt-4.1-Details'!O6) -> 0.0054009888
A8: 30 | B8: =ABS('Human Details'!J7-'gpt-4.1-Details'!J7) -> 0.66666667 | C8: =ABS('Human Details'!K7-'gpt-4.1-Details'!K7) -> 1 | D8: =ABS('Human Details'!L7-'gpt-4.1-Details'!L7) -> 0.11666667 | E8: =ABS('Human Details'!M7-'gpt-4.1-Details'!M7) -> 0.63175794 | F8: =ABS('Human Details'!N7-'gpt-4.1-Details'!N7) -> 0.33333333 | G8: =ABS('Human Details'!O7-'gpt-4.1-Details'!O7) -> 0.70019121
A9: 33 | B9: =ABS('Human Details'!J8-'gpt-4.1-Details'!J8) -> 0.5 | C9: =ABS('Human Details'!K8-'gpt-4.1-Details'!K8) -> 1 | D9: =ABS('Human Details'!L8-'gpt-4.1-Details'!L8) -> 0.87 | E9: =ABS('Human Details'!M8-'gpt-4.1-Details'!M8) -> 0.0019800605 | F9: =ABS('Human Details'!N8-'gpt-4.1-Details'!N8) -> 1 | G9: =ABS('Human Details'!O8-'gpt-4.1-Details'!O8) -> 0.21368457
A10: 34 | B10: =ABS('Human Details'!J9-'gpt-4.1-Details'!J9) -> 0.33333333 | C10: =ABS('Human Details'!K9-'gpt-4.1-Details'!K9) -> 0 | D10: =ABS('Human Details'!L9-'gpt-4.1-Details'!L9) -> 0 | E10: =ABS('Human Details'!M9-'gpt-4.1-Details'!M9) -> 0.30823798 | F10: =ABS('Human Details'!N9-'gpt-4.1-Details'!N9) -> 0.058823529 | G10: =ABS('Human Details'!O9-'gpt-4.1-Details'!O9) -> 1
A11: 64 | B11: =ABS('Human Details'!J10-'gpt-4.1-Details'!J10) -> 0.44444444 | C11: =ABS('Human Details'!K10-'gpt-4.1-Details'!K10) -> 1 | D11: =ABS('Human Details'!L10-'gpt-4.1-Details'!L10) -> 0.75 | E11: =ABS('Human Details'!M10-'gpt-4.1-Details'!M10) -> 0.85041125 | F11: =ABS('Human Details'!N10-'gpt-4.1-Details'!N10) -> 0.20588235 | G11: =ABS('Human Details'!O10-'gpt-4.1-Details'!O10) -> 0
A12: 65 | B12: =ABS('Human Details'!J11-'gpt-4.1-Details'!J11) -> 0.23333333 | C12: =ABS('Human Details'!K11-'gpt-4.1-Details'!K11) -> 0.6 | D12: =ABS('Human Details'!L11-'gpt-4.1-Details'!L11) -> 0.24444444 | E12: =ABS('Human Details'!M11-'gpt-4.1-Details'!M11) -> 0.22480964 | F12: =ABS('Human Details'!N11-'gpt-4.1-Details'!N11) -> 1 | G12: =ABS('Human Details'!O11-'gpt-4.1-Details'!O11) -> 0.040120446
A13: 84 | B13: =ABS('Human Details'!J12-'gpt-4.1-Details'!J12) -> 0.21428571 | C13: =ABS('Human Details'!K12-'gpt-4.1-Details'!K12) -> 0.4 | D13: =ABS('Human Details'!L12-'gpt-4.1-Details'!L12) -> 1 | E13: =ABS('Human Details'!M12-'gpt-4.1-Details'!M12) -> 0.074224037 | F13: =ABS('Human Details'!N12-'gpt-4.1-Details'!N12) -> 0.11428571 | G13: =ABS('Human Details'!O12-'gpt-4.1-Details'!O12) -> 1
A14: 89 | B14: =ABS('Human Details'!J13-'gpt-4.1-Details'!J13) -> 0.66666667 | C14: =ABS('Human Details'!K13-'gpt-4.1-Details'!K13) -> 0.6 | D14: =ABS('Human Details'!L13-'gpt-4.1-Details'!L13) -> 0.8875 | E14: =ABS('Human Details'!M13-'gpt-4.1-Details'!M13) -> 0.83352148 | F14: =ABS('Human Details'!N13-'gpt-4.1-Details'!N13) -> 0.15 | G14: =ABS('Human Details'!O13-'gpt-4.1-Details'!O13) -> 0.2
... A17: 110 | B17: =ABS('Human Details'!J16-'gpt-4.1-Details'!J16) -> 0.375 | C17: =ABS('Human Details'!K16-'gpt-4.1-Details'!K16) -> 0.3 | D17: =ABS('Human Details'!L16-'gpt-4.1-Details'!L16) -> 0.91666667 | E17: =ABS('Human Details'!M16-'gpt-4.1-Details'!M16) -> 0.61740094 | F17: =ABS('Human Details'!N16-'gpt-4.1-Details'!N16) -> 0.096491228 | G17: =ABS('Human Details'!O16-'gpt-4.1-Details'!O16) -> 0.70413189
B19: faithfulness | C19: context_recall | D19: context_precision | E19: semantic_similarity | F19: context_entity_recall | G19: answer_relevancy
A20: MAE Mittelwert | B20: =AVERAGE(B3:B17) -> 0.28753777 | C20: =AVERAGE(C3:C17) -> 0.38957672 | D20: =AVERAGE(D3:D17) -> 0.48407407 | E20: =AVERAGE(E3:E17) -> 0.37941636 | F20: =AVERAGE(F3:F17) -> 0.32395863 | G20: =AVERAGE(G3:G17) -> 0.35845073

Sheet Metriken gpt-4.1-mini
B1: Abs | K1: Error | S1: Relative Error
A2: ID | B2: faithfulness | C2: context_recall | D2: context_precision | E2: semantic_similarity | F2: context_entity_recall | G2: answer_relevancy | J2: ID | K2: faithfulness | L2: context_recall | M2: context_precision | N2: semantic_similarity | O2: context_entity_recall | P2: answer_relevancy | R2: ID | S2: faithfulness | T2: context_recall | U2: context_precision | V2: semantic_similarity | W2: context_entity_recall | X2: answer_relevancy
A3: 1 | B3: =ABS('Human Details'!J2-'gpt-4.1-mini-Details'!J2) -> 0.055555556 | C3: =ABS('Human Details'!K2-'gpt-4.1-mini-Details'!K2) -> 0 | D3: =ABS('Human Details'!L2-'gpt-4.1-mini-Details'!L2) -> 0.20222222 | E3: =ABS('Human Details'!M2-'gpt-4.1-mini-Details'!M2) -> 0.058254654 | F3: =ABS('Human Details'!N2-'gpt-4.1-mini-Details'!N2) -> 0.34343434 | G3: =ABS('Human Details'!O2-'gpt-4.1-mini-Details'!O2) -> 0.154211 | J3: 1 | K3: ='gpt-4.1-mini-Details'!J2-'Human Details'!J2 -> -0.055555556 | L3: ='gpt-4.1-mini-Details'!K2-'Human Details'!K2 -> 0 | M3: ='gpt-4.1-mini-Details'!L2-'Human Details'!L2 -> -0.20222222 | N3: ='gpt-4.1-mini-Details'!M2-'Human Details'!M2 -> -0.058254654 | O3: ='gpt-4.1-mini-Details'!N2-'Human Details'!N2 -> -0.34343434 | P3: ='gpt-4.1-mini-Details'!O2-'Human Details'!O2 -> -0.154211 | R3: 1 | S3: =IFERROR(('gpt-4.1-mini-Details'!J2-'Human Details'!J2)/'gpt-4.1-mini-Details'!J2, ('gpt-4.1-mini-Details'!J2-'Human Details'!J2)) -> -0.058823529 | T3: =IFERROR(('gpt-4.1-mini-Details'!K2-'Human Details'!K2)/'gpt-4.1-mini-Details'!K2, ('gpt-4.1-mini-Details'!K2-'Human Details'!K2)) -> 0 | U3: =IFERROR(('gpt-4.1-mini-Details'!L2-'Human Details'!L2)/'gpt-4.1-mini-Details'!L2, ('gpt-4.1-mini-Details'!L2-'Human Details'!L2)) -> -0.42325581 | V3: =IFERROR(('gpt-4.1-mini-Details'!M2-'Human Details'!M2)/'gpt-4.1-mini-Details'!M2, ('gpt-4.1-mini-Details'!M2-'Human Details'!M2)) -> -0.084214016 | W3: =IFERROR(('gpt-4.1-mini-Details'!N2-'Human Details'!N2)/'gpt-4.1-mini-Details'!N2, ('gpt-4.1-mini-Details'!N2-'Human Details'!N2)) -> -3.0909091 | X3: =IFERROR(('gpt-4.1-mini-Details'!O2-'Human Details'!O2)/'gpt-4.1-mini-Details'!O2, ('gpt-4.1-mini-Details'!O2-'Human Details'!O2)) -> -0.18232798
A4: 8 | B4: =ABS('Human Details'!J3-'gpt-4.1-mini-Details'!J3) -> 0 | C4: =ABS('Human Details'!K3-'gpt-4.1-mini-Details'!K3) -> 0 | D4: =ABS('Human Details'!L3-'gpt-4.1-mini-Details'!L3) -> 1 | E4: =ABS('Human Details'!M3-'gpt-4.1-mini-Details'!M3) -> 0.68219253 | F4: =ABS('Human Details'!N3-'gpt-4.1-mini-Details'!N3) -> 0 | G4: =ABS('Human Details'!O3-'gpt-4.1-mini-Details'!O3) -> 0 | J4: 8 | K4: ='gpt-4.1-mini-Details'!J3-'Human Details'!J3 -> 0 | L4: ='gpt-4.1-mini-Details'!K3-'Human Details'!K3 -> 0 | M4: ='gpt-4.1-mini-Details'!L3-'Human Details'!L3 -> -1 | N4: ='gpt-4.1-mini-Details'!M3-'Human Details'!M3 -> 0.68219253 | O4: ='gpt-4.1-mini-Details'!N3-'Human Details'!N3 -> 0 | P4: ='gpt-4.1-mini-Details'!O3-'Human Details'!O3 -> 0 | R4: 8 | S4: =IFERROR(('gpt-4.1-mini-Details'!J3-'Human Details'!J3)/'gpt-4.1-mini-Details'!J3, ('gpt-4.1-mini-Details'!J3-'Human Details'!J3)) -> 0 | T4: =IFERROR(('gpt-4.1-mini-Details'!K3-'Human Details'!K3)/'gpt-4.1-mini-Details'!K3, ('gpt-4.1-mini-Details'!K3-'Human Details'!K3)) -> 0 | U4: =IFERROR(('gpt-4.1-mini-Details'!L3-'Human Details'!L3)/'gpt-4.1-mini-Details'!L3, ('gpt-4.1-mini-Details'!L3-'Human Details'!L3)) -> -1 | V4: =IFERROR(('gpt-4.1-mini-Details'!M3-'Human Details'!M3)/'gpt-4.1-mini-Details'!M3, ('gpt-4.1-mini-Details'!M3-'Human Details'!M3)) -> 1 | W4: =IFERROR(('gpt-4.1-mini-Details'!N3-'Human Details'!N3)/'gpt-4.1-mini-Details'!N3, ('gpt-4.1-mini-Details'!N3-'Human Details'!N3)) -> 0 | X4: =IFERROR(('gpt-4.1-mini-Details'!O3-'Human Details'!O3)/'gpt-4.1-mini-Details'!O3, ('gpt-4.1-mini-Details'!O3-'Human Details'!O3)) -> 0
A5: 11 | B5: =ABS('Human Details'!J4-'gpt-4.1-mini-Details'!J4) -> 0.33333333 | C5: =ABS('Human Details'!K4-'gpt-4.1-mini-Details'!K4) -> 0 | D5: =ABS('Human Details'!L4-'gpt-4.1-mini-Details'!L4) -> 5.0000004e-11 | E5: =ABS('Human Details'!M4-'gpt-4.1-mini-Details'!M4) -> 0.21741346 | F5: =ABS('Human Details'!N4-'gpt-4.1-mini-Details'!N4) -> 0.52727273 | G5: =ABS('Human Details'!O4-'gpt-4.1-mini-Details'!O4) -> 0.5 | J5: 11 | K5: ='gpt-4.1-mini-Details'!J4-'Human Details'!J4 -> 0.33333333 | L5: ='gpt-4.1-mini-Details'!K4-'Human Details'!K4 -> 0 | M5: ='gpt-4.1-mini-Details'!L4-'Human Details'!L4 -> -5.0000004e-11 | N5: ='gpt-4.1-mini-Details'!M4-'Human Details'!M4 -> 0.21741346 | O5: ='gpt-4.1-mini-Details'!N4-'Human Details'!N4 -> 0.52727273 | P5: ='gpt-4.1-mini-Details'!O4-'Human Details'!O4 -> -0.5 | R5: 11 | S5: =IFERROR(('gpt-4.1-mini-Details'!J4-'Human Details'!J4)/'gpt-4.1-mini-Details'!J4, ('gpt-4.1-mini-Details'!J4-'Human Details'!J4)) -> 0.4 | T5: =IFERROR(('gpt-4.1-mini-Details'!K4-'Human Details'!K4)/'gpt-4.1-mini-Details'!K4, ('gpt-4.1-mini-Details'!K4-'Human Details'!K4)) -> 0 | U5: =IFERROR(('gpt-4.1-mini-Details'!L4-'Human Details'!L4)/'gpt-4.1-mini-Details'!L4, ('gpt-4.1-mini-Details'!L4-'Human Details'!L4)) -> -5.0000004e-11 | V5: =IFERROR(('gpt-4.1-mini-Details'!M4-'Human Details'!M4)/'gpt-4.1-mini-Details'!M4, ('gpt-4.1-mini-Details'!M4-'Human Details'!M4)) -> 0.30305183 | W5: =IFERROR(('gpt-4.1-mini-Details'!N4-'Human Details'!N4)/'gpt-4.1-mini-Details'!N4, ('gpt-4.1-mini-Details'!N4-'Human Details'!N4)) -> 0.65909091 | X5: =IFERROR(('gpt-4.1-mini-Details'!O4-'Human Details'!O4)/'gpt-4.1-mini-Details'!O4, ('gpt-4.1-mini-Details'!O4-'Human Details'!O4)) -> -0.5
A6: 17 | B6: =ABS('Human Details'!J5-'gpt-4.1-mini-Details'!J5) -> 0.13333333 | C6: =ABS('Human Details'!K5-'gpt-4.1-mini-Details'!K5) -> 0.33333333 | D6: =ABS('Human Details'!L5-'gpt-4.1-mini-Details'!L5) -> 0.125 | E6: =ABS('Human Details'!M5-'gpt-4.1-mini-Details'!M5) -> 0.27592699 | F6: =ABS('Human Details'!N5-'gpt-4.1-mini-Details'!N5) -> 0.11111111 | G6: =ABS('Human Details'!O5-'gpt-4.1-mini-Details'!O5) -> 0.37199183 | J6: 17 | K6: ='gpt-4.1-mini-Details'!J5-'Human Details'!J5 -> 0.13333333 | L6: ='gpt-4.1-mini-Details'!K5-'Human Details'!K5 -> -0.33333333 | M6: ='gpt-4.1-mini-Details'!L5-'Human Details'!L5 -> -0.125 | N6: ='gpt-4.1-mini-Details'!M5-'Human Details'!M5 -> 0.27592699 | O6: ='gpt-4.1-mini-Details'!N5-'Human Details'!N5 -> 0.11111111 | P6: ='gpt-4.1-mini-Details'!O5-'Human Details'!O5 -> 0.37199183 | R6: 17 | S6: =IFERROR(('gpt-4.1-mini-Details'!J5-'Human Details'!J5)/'gpt-4.1-mini-Details'!J5, ('gpt-4.1-mini-Details'!J5-'Human Details'!J5)) -> 0.16666667 | T6: =IFERROR(('gpt-4.1-mini-Details'!K5-'Human Details'!K5)/'gpt-4.1-mini-Details'!K5, ('gpt-4.1-mini-Details'!K5-'Human Details'!K5)) -> -0.33333333 | U6: =IFERROR(('gpt-4.1-mini-Details'!L5-'Human Details'!L5)/'gpt-4.1-mini-Details'!L5, ('gpt-4.1-mini-Details'!L5-'Human Details'!L5)) -> -0.625 | V6: =IFERROR(('gpt-4.1-mini-Details'!M5-'Human Details'!M5)/'gpt-4.1-mini-Details'!M5, ('gpt-4.1-mini-Details'!M5-'Human Details'!M5)) -> 0.35560948 | W6: =IFERROR(('gpt-4.1-mini-Details'!N5-'Human Details'!N5)/'gpt-4.1-mini-Details'!N5, ('gpt-4.1-mini-Details'!N5-'Human Details'!N5)) -> 0.25 | X6: =IFERROR(('gpt-4.1-mini-Details'!O5-'Human Details'!O5)/'gpt-4.1-mini-Details'!O5, ('gpt-4.1-mini-Details'!O5-'Human Details'!O5)) -> 0.42660013
A7: 20 | B7: =ABS('Human Details'!J6-'gpt-4.1-mini-Details'!J6) -> 0.3 | C7: =ABS('Human Details'!K6-'gpt-4.1-mini-Details'!K6) -> 0.75 | D7: =ABS('Human Details'!L6-'gpt-4.1-mini-Details'!L6) -> 1.0000001e-10 | E7: =ABS('Human Details'!M6-'gpt-4.1-mini-Details'!M6) -> 0.047320968 | F7: =ABS('Human Details'!N6-'gpt-4.1-mini-Details'!N6) -> 0.52777778 | G7: =ABS('Human Details'!O6-'gpt-4.1-mini-Details'!O6) -> 0.0061767343 | J7: 20 | K7: ='gpt-4.1-mini-Details'!J6-'Human Details'!J6 -> -0.3 | L7: ='gpt-4.1-mini-Details'!K6-'Human Details'!K6 -> -0.75 | M7: ='gpt-4.1-mini-Details'!L6-'Human Details'!L6 -> -1.0000001e-10 | N7: ='gpt-4.1-mini-Details'!M6-'Human Details'!M6 -> 0.047320968 | O7: ='gpt-4.1-mini-Details'!N6-'Human Details'!N6 -> 0.52777778 | P7: ='gpt-4.1-mini-Details'!O6-'Human Details'!O6 -> -0.0061767343 | R7: 20 | S7: =IFERROR(('gpt-4.1-mini-Details'!J6-'Human Details'!J6)/'gpt-4.1-mini-Details'!J6, ('gpt-4.1-mini-Details'!J6-'Human Details'!J6)) -> -0.5 | T7: =IFERROR(('gpt-4.1-mini-Details'!K6-'Human Details'!K6)/'gpt-4.1-mini-Details'!K6, ('gpt-4.1-mini-Details'!K6-'Human Details'!K6)) -> -0.75 | U7: =IFERROR(('gpt-4.1-mini-Details'!L6-'Human Details'!L6)/'gpt-4.1-mini-Details'!L6, ('gpt-4.1-mini-Details'!L6-'Human Details'!L6)) -> -1.0000001e-10 | V7: =IFERROR(('gpt-4.1-mini-Details'!M6-'Human Details'!M6)/'gpt-4.1-mini-Details'!M6, ('gpt-4.1-mini-Details'!M6-'Human Details'!M6)) -> 0.086459264 | W7: =IFERROR(('gpt-4.1-mini-Details'!N6-'Human Details'!N6)/'gpt-4.1-mini-Details'!N6, ('gpt-4.1-mini-Details'!N6-'Human Details'!N6)) -> 0.67857143 | X7: =IFERROR(('gpt-4.1-mini-Details'!O6-'Human Details'!O6)/'gpt-4.1-mini-Details'!O6, ('gpt-4.1-mini-Details'!O6-'Human Details'!O6)) -> -0.0077809943
A8: 30 | B8: =ABS('Human Details'!J7-'gpt-4.1-mini-Details'!J7) -> 0.66666667 | C8: =ABS('Human Details'!K7-'gpt-4.1-mini-Details'!K7) -> 1 | D8: =ABS('Human Details'!L7-'gpt-4.1-mini-Details'!L7) -> 0.75 | E8: =ABS('Human Details'!M7-'gpt-4.1-mini-Details'!M7) -> 0.61740094 | F8: =ABS('Human Details'!N7-'gpt-4.1-mini-Details'!N7) -> 0.2 | G8: =ABS('Human Details'!O7-'gpt-4.1-mini-Details'!O7) -> 0.653618 | J8: 30 | K8: ='gpt-4.1-mini-Details'!J7-'Human Details'!J7 -> 0.66666667 | L8: ='gpt-4.1-mini-Details'!K7-'Human Details'!K7 -> 1 | M8: ='gpt-4.1-mini-Details'!L7-'Human Details'!L7 -> -0.75 | N8: ='gpt-4.1-mini-Details'!M7-'Human Details'!M7 -> 0.61740094 | O8: ='gpt-4.1-mini-Details'!N7-'Human Details'!N7 -> 0.2 | P8: ='gpt-4.1-mini-Details'!O7-'Human Details'!O7 -> 0.653618 | R8: 30 | S8: =IFERROR(('gpt-4.1-mini-Details'!J7-'Human Details'!J7)/'gpt-4.1-mini-Details'!J7, ('gpt-4.1-mini-Details'!J7-'Human Details'!J7)) -> 0.66666667 | T8: =IFERROR(('gpt-4.1-mini-Details'!K7-'Human Details'!K7)/'gpt-4.1-mini-Details'!K7, ('gpt-4.1-mini-Details'!K7-'Human Details'!K7)) -> 1 | U8: =IFERROR(('gpt-4.1-mini-Details'!L7-'Human Details'!L7)/'gpt-4.1-mini-Details'!L7, ('gpt-4.1-mini-Details'!L7-'Human Details'!L7)) -> -0.75 | V8: =IFERROR(('gpt-4.1-mini-Details'!M7-'Human Details'!M7)/'gpt-4.1-mini-Details'!M7, ('gpt-4.1-mini-Details'!M7-'Human Details'!M7)) -> 0.71178265 | W8: =IFERROR(('gpt-4.1-mini-Details'!N7-'Human Details'!N7)/'gpt-4.1-mini-Details'!N7, ('gpt-4.1-mini-Details'!N7-'Human Details'!N7)) -> 1 | X8: =IFERROR(('gpt-4.1-mini-Details'!O7-'Human Details'!O7)/'gpt-4.1-mini-Details'!O7, ('gpt-4.1-mini-Details'!O7-'Human Details'!O7)) -> 0.72333442
A9: 33 | B9: =ABS('Human Details'!J8-'gpt-4.1-mini-Details'!J8) -> 0.33333333 | C9: =ABS('Human Details'!K8-'gpt-4.1-mini-Details'!K8) -> 0 | D9: =ABS('Human Details'!L8-'gpt-4.1-mini-Details'!L8) -> 0.0033333334 | E9: =ABS('Human Details'!M8-'gpt-4.1-mini-Details'!M8) -> 0.13175794 | F9: =ABS('Human Details'!N8-'gpt-4.1-mini-Details'!N8) -> 5e-09 | G9: =ABS('Human Details'!O8-'gpt-4.1-mini-Details'!O8) -> 0.21393741 | J9: 33 | K9: ='gpt-4.1-mini-Details'!J8-'Human Details'!J8 -> 0.33333333 | L9: ='gpt-4.1-mini-Details'!K8-'Human Details'!K8 -> 0 | M9: ='gpt-4.1-mini-Details'!L8-'Human Details'!L8 -> -0.0033333334 | N9: ='gpt-4.1-mini-Details'!M8-'Human Details'!M8 -> 0.13175794 | O9: ='gpt-4.1-mini-Details'!N8-'Human Details'!N8 -> -5e-09 | P9: ='gpt-4.1-mini-Details'!O8-'Human Details'!O8 -> 0.21393741 | R9: 33 | S9: =IFERROR(('gpt-4.1-mini-Details'!J8-'Human Details'!J8)/'gpt-4.1-mini-Details'!J8, ('gpt-4.1-mini-Details'!J8-'Human Details'!J8)) -> 0.4 | T9: =IFERROR(('gpt-4.1-mini-Details'!K8-'Human Details'!K8)/'gpt-4.1-mini-Details'!K8, ('gpt-4.1-mini-Details'!K8-'Human Details'!K8)) -> 0 | U9: =IFERROR(('gpt-4.1-mini-Details'!L8-'Human Details'!L8)/'gpt-4.1-mini-Details'!L8, ('gpt-4.1-mini-Details'!L8-'Human Details'!L8)) -> -0.0038461539 | V9: =IFERROR(('gpt-4.1-mini-Details'!M8-'Human Details'!M8)/'gpt-4.1-mini-Details'!M8, ('gpt-4.1-mini-Details'!M8-'Human Details'!M8)) -> 0.14942643 | W9: =IFERROR(('gpt-4.1-mini-Details'!N8-'Human Details'!N8)/'gpt-4.1-mini-Details'!N8, ('gpt-4.1-mini-Details'!N8-'Human Details'!N8)) -> -5e-09 | X9: =IFERROR(('gpt-4.1-mini-Details'!O8-'Human Details'!O8)/'gpt-4.1-mini-Details'!O8, ('gpt-4.1-mini-Details'!O8-'Human Details'!O8)) -> 0.22194118
A10: 34 | B10: =ABS('Human Details'!J9-'gpt-4.1-mini-Details'!J9) -> 0 | C10: =ABS('Human Details'!K9-'gpt-4.1-mini-Details'!K9) -> 0 | D10: =ABS('Human Details'!L9-'gpt-4.1-mini-Details'!L9) -> 0 | E10: =ABS('Human Details'!M9-'gpt-4.1-mini-Details'!M9) -> 0.26584728 | F10: =ABS('Human Details'!N9-'gpt-4.1-mini-Details'!N9) -> 0 | G10: =ABS('Human Details'!O9-'gpt-4.1-mini-Details'!O9) -> 0.036315427 | J10: 34 | K10: ='gpt-4.1-mini-Details'!J9-'Human Details'!J9 -> 0 | L10: ='gpt-4.1-mini-Details'!K9-'Human Details'!K9 -> 0 | M10: ='gpt-4.1-mini-Details'!L9-'Human Details'!L9 -> 0 | N10: ='gpt-4.1-mini-Details'!M9-'Human Details'!M9 -> 0.26584728 | O10: ='gpt-4.1-mini-Details'!N9-'Human Details'!N9 -> 0 | P10: ='gpt-4.1-mini-Details'!O9-'Human Details'!O9 -> -0.036315427 | R10: 34 | S10: =IFERROR(('gpt-4.1-mini-Details'!J9-'Human Details'!J9)/'gpt-4.1-mini-Details'!J9, ('gpt-4.1-mini-Details'!J9-'Human Details'!J9)) -> 0 | T10: =IFERROR(('gpt-4.1-mini-Details'!K9-'Human Details'!K9)/'gpt-4.1-mini-Details'!K9, ('gpt-4.1-mini-Details'!K9-'Human Details'!K9)) -> 0 | U10: =IFERROR(('gpt-4.1-mini-Details'!L9-'Human Details'!L9)/'gpt-4.1-mini-Details'!L9, ('gpt-4.1-mini-Details'!L9-'Human Details'!L9)) -> 0 | V10: =IFERROR(('gpt-4.1-mini-Details'!M9-'Human Details'!M9)/'gpt-4.1-mini-Details'!M9, ('gpt-4.1-mini-Details'!M9-'Human Details'!M9)) -> 0.34712832 | W10: =IFERROR(('gpt-4.1-mini-Details'!N9-'Human Details'!N9)/'gpt-4.1-mini-Details'!N9, ('gpt-4.1-mini-Details'!N9-'Human Details'!N9)) -> 0 | X10: =IFERROR(('gpt-4.1-mini-Details'!O9-'Human Details'!O9)/'gpt-4.1-mini-Details'!O9, ('gpt-4.1-mini-Details'!O9-'Human Details'!O9)) -> -0.037683936
A11: 64 | B11: =ABS('Human Details'!J10-'gpt-4.1-mini-Details'!J10) -> 0 | C11: =ABS('Human Details'!K10-'gpt-4.1-mini-Details'!K10) -> 0.28571429 | D11: =ABS('Human Details'!L10-'gpt-4.1-mini-Details'!L10) -> 0 | E11: =ABS('Human Details'!M10-'gpt-4.1-mini-Details'!M10) -> 0.67507926 | F11: =ABS('Human Details'!N10-'gpt-4.1-mini-Details'!N10) -> 0 | G11: =ABS('Human Details'!O10-'gpt-4.1-mini-Details'!O10) -> 0 | J11: 64 | K11: ='gpt-4.1-mini-Details'!J10-'Human Details'!J10 -> 0 | L11: ='gpt-4.1-mini-Details'!K10-'Human Details'!K10 -> 0.28571429 | M11: ='gpt-4.1-mini-Details'!L10-'Human Details'!L10 -> 0 | N11: ='gpt-4.1-mini-Details'!M10-'Human Details'!M10 -> 0.67507926 | O11: ='gpt-4.1-mini-Details'!N10-'Human Details'!N10 -> 0 | P11: ='gpt-4.1-mini-Details'!O10-'Human Details'!O10 -> 0 | R11: 64 | S11: =IFERROR(('gpt-4.1-mini-Details'!J10-'Human Details'!J10)/'gpt-4.1-mini-Details'!J10, ('gpt-4.1-mini-Details'!J10-'Human Details'!J10)) -> 0 | T11: =IFERROR(('gpt-4.1-mini-Details'!K10-'Human Details'!K10)/'gpt-4.1-mini-Details'!K10, ('gpt-4.1-mini-Details'!K10-'Human Details'!K10)) -> 1 | U11: =IFERROR(('gpt-4.1-mini-Details'!L10-'Human Details'!L10)/'gpt-4.1-mini-Details'!L10, ('gpt-4.1-mini-Details'!L10-'Human Details'!L10)) -> 0 | V11: =IFERROR(('gpt-4.1-mini-Details'!M10-'Human Details'!M10)/'gpt-4.1-mini-Details'!M10, ('gpt-4.1-mini-Details'!M10-'Human Details'!M10)) -> 1 | W11: =IFERROR(('gpt-4.1-mini-Details'!N10-'Human Details'!N10)/'gpt-4.1-mini-Details'!N10, ('gpt-4.1-mini-Details'!N10-'Human Details'!N10)) -> 0 | X11: =IFERROR(('gpt-4.1-mini-Details'!O10-'Human Details'!O10)/'gpt-4.1-mini-Details'!O10, ('gpt-4.1-mini-Details'!O10-'Human Details'!O10)) -> 0
A12: 65 | B12: =ABS('Human Details'!J11-'gpt-4.1-mini-Details'!J11) -> 0.11111111 | C12: =ABS('Human Details'!K11-'gpt-4.1-mini-Details'!K11) -> 0 | D12: =ABS('Human Details'!L11-'gpt-4.1-mini-Details'!L11) -> 0.66666667 | E12: =ABS('Human Details'!M11-'gpt-4.1-mini-Details'!M11) -> 0.35285398 | F12: =ABS('Human Details'!N11-'gpt-4.1-mini-Details'!N11) -> 0.875 | G12: =ABS('Human Details'!O11-'gpt-4.1-mini-Details'!O11) -> 1 | J12: 65 | K12: ='gpt-4.1-mini-Details'!J11-'Human Details'!J11 -> -0.11111111 | L12: ='gpt-4.1-mini-Details'!K11-'Human Details'!K11 -> 0 | M12: ='gpt-4.1-mini-Details'!L11-'Human Details'!L11 -> -0.66666667 | N12: ='gpt-4.1-mini-Details'!M11-'Human Details'!M11 -> 0.35285398 | O12: ='gpt-4.1-mini-Details'!N11-'Human Details'!N11 -> -0.875 | P12: ='gpt-4.1-mini-Details'!O11-'Human Details'!O11 -> -1 | R12: 65 | S12: =IFERROR(('gpt-4.1-mini-Details'!J11-'Human Details'!J11)/'gpt-4.1-mini-Details'!J11, ('gpt-4.1-mini-Details'!J11-'Human Details'!J11)) -> -0.2 | T12: =IFERROR(('gpt-4.1-mini-Details'!K11-'Human Details'!K11)/'gpt-4.1-mini-Details'!K11, ('gpt-4.1-mini-Details'!K11-'Human Details'!K11)) -> 0 | U12: =IFERROR(('gpt-4.1-mini-Details'!L11-'Human Details'!L11)/'gpt-4.1-mini-Details'!L11, ('gpt-4.1-mini-Details'!L11-'Human Details'!L11)) -> -2 | V12: =IFERROR(('gpt-4.1-mini-Details'!M11-'Human Details'!M11)/'gpt-4.1-mini-Details'!M11, ('gpt-4.1-mini-Details'!M11-'Human Details'!M11)) -> 0.41373317 | W12: =IFERROR(('gpt-4.1-mini-Details'!N11-'Human Details'!N11)/'gpt-4.1-mini-Details'!N11, ('gpt-4.1-mini-Details'!N11-'Human Details'!N11)) -> -7 | X12: =IFERROR(('gpt-4.1-mini-Details'!O11-'Human Details'!O11)/'gpt-4.1-mini-Details'!O11, ('gpt-4.1-mini-Details'!O11-'Human Details'!O11)) -> -1
A13: 84 | B13: =ABS('Human Details'!J12-'gpt-4.1-mini-Details'!J12) -> 0.21428571 | C13: =ABS('Human Details'!K12-'gpt-4.1-mini-Details'!K12) -> 0.4 | D13: =ABS('Human Details'!L12-'gpt-4.1-mini-Details'!L12) -> 0.16666667 | E13: =ABS('Human Details'!M12-'gpt-4.1-mini-Details'!M12) -> 0.21745192 | F13: =ABS('Human Details'!N12-'gpt-4.1-mini-Details'!N12) -> 0.11428571 | G13: =ABS('Human Details'!O12-'gpt-4.1-mini-Details'!O12) -> 0.020727081 | J13: 84 | K13: ='gpt-4.1-mini-Details'!J12-'Human Details'!J12 -> 0.21428571 | L13: ='gpt-4.1-mini-Details'!K12-'Human Details'!K12 -> 0.4 | M13: ='gpt-4.1-mini-Details'!L12-'Human Details'!L12 -> -0.16666667 | N13: ='gpt-4.1-mini-Details'!M12-'Human Details'!M12 -> 0.21745192 | O13: ='gpt-4.1-mini-Details'!N12-'Human Details'!N12 -> -0.11428571 | P13: ='gpt-4.1-mini-Details'!O12-'Human Details'!O12 -> -0.020727081 | R13: 84 | S13: =IFERROR(('gpt-4.1-mini-Details'!J12-'Human Details'!J12)/'gpt-4.1-mini-Details'!J12, ('gpt-4.1-mini-Details'!J12-'Human Details'!J12)) -> 0.23076923 | T13: =IFERROR(('gpt-4.1-mini-Details'!K12-'Human Details'!K12)/'gpt-4.1-mini-Details'!K12, ('gpt-4.1-mini-Details'!K12-'Human Details'!K12)) -> 0.5 | U13: =IFERROR(('gpt-4.1-mini-Details'!L12-'Human Details'!L12)/'gpt-4.1-mini-Details'!L12, ('gpt-4.1-mini-Details'!L12-'Human Details'!L12)) -> -0.2 | V13: =IFERROR(('gpt-4.1-mini-Details'!M12-'Human Details'!M12)/'gpt-4.1-mini-Details'!M12, ('gpt-4.1-mini-Details'!M12-'Human Details'!M12)) -> 0.30308918 | W13: =IFERROR(('gpt-4.1-mini-Details'!N12-'Human Details'!N12)/'gpt-4.1-mini-Details'!N12, ('gpt-4.1-mini-Details'!N12-'Human Details'!N12)) -> -0.11428571 | X13: =IFERROR(('gpt-4.1-mini-Details'!O12-'Human Details'!O12)/'gpt-4.1-mini-Details'!O12, ('gpt-4.1-mini-Details'!O12-'Human Details'!O12)) -> -0.021165786
