Workbook

Sheet Detaillierte Ergebnisse
A1: id | B1: category | C1: difficulty | D1: user_input | E1: response | F1: reference | G1: retrieved_contexts | H1: retrieved_urls | I1: retrieved_content_types | J1: faithfulness | K1: context_recall | L1: context_precision | M1: semantic_similarity | N1: context_entity_recall | O1: answer_relevancy | P1: bert_f1 | Q1: bert_precision | R1: bert_recall | S1: RR_at5 | T1: hit_at5 | U1: latency | V1: prompt_tokens | W1: completion_tokens | X1: total_tokens | Y1: reranking_tokens | Z1: context_count | AA1: response_time_seconds
A2: 1 | B2: Allgemein | C2: medium | D2: Inwiefern würde ich als Student von einem Studium an der WiSo-Fakultät profitieren? | E2: Als Student von einem Studium an der WiSo-Fakultät profitieren Sie in verschiedenen Bereichen: 1. Multidisziplinäre Ausrichtung: Im Verlauf des Studiums können Sie je nach gewählter Studienrichtung vom Austausch und von der Verknüpfung verschiedener Fachbereiche innerhalb der WiSo-Fakultät profitieren. 2. Möglichkeit eines Auslandsstudiums: Die WiSo-Fakultät bietet Ihren Studierenden die Möglichkeit eines Auslandsstudiums innerhalb ihres weltweiten und exzellenten Netzwerks an Partneruniversitäten. Ein Auslandsemester bietet die Chance, den Horizont zu erweitern, interkulturelle Kompetenzen zu erwerben und die akademische Laufbahn zu bereichern. 3. Gezielte inhaltliche Schwerpunkte: Sie können gezielt inhaltliche Schwerpunkte setzen, was Ihnen ermöglicht, Ihre Interessen und Fähigkeiten zu stärken. 4. Abschließende Masterarbeit: Für die abschließende Masterarbeit inklusive ihrer Verteidigung sind 30 LP vorgesehen. Diese Vorteile können dazu beitragen, dass Sie als Student von einem Studium an der WiSo-Fakultät eine umfassende und vielseitige Ausbildung erhalten. | F2: Als Student profitierst du von einem theorie- und methodenorientierten Studienansatz, in dem Forschung und Lehre eng mit der Praxis verzahnt sind, sowie von der ausgeprägten Praxisnähe durch die langjährige Zusammenarbeit der WiSo-Fakultät mit Unternehmen und Lehrbeauftragten aus verschiedenen Berufsfeldern. | G2: ['s den Bereichen BWL, VWL und Sozialwissenschaften gewählt werden. Die Masterthesis bildet den letzten Bereich und umfas st 30 LP. --- Page 8 --- Gültig für Studierende der PO 2021 (Einschreibung ab WiSe 2021/22) BUSINESS ADMINISTRATION : ACCOUNTING AND TAXATION - MASTER OF SCIENCE 4 1.4 Study Abroad Option Die WiSo -Fakultät bietet Ihren Studierenden die Möglichkeit eines Auslandsstudiums innerhalb ihres weltweiten und exzellenten Netzwerks an Partneruniversitäten . Ein Auslandsemester bietet die Chance, den Horizont zu erweitern, interkulturelle Kompetenzen zu erwerben und die akademische Laufbahn zu bereichern. Die Optionen im Überblick: 1. Study Abroad Programme (STAP): o Ein etabliertes Programm, das einen einsemestrigen Austausch an einer der renommierten Partnerhochschu len ermöglicht. Im Rahmen von STAP ist eine ERASMUS -Förderung möglich, die finanzielle Unterstützung während des Auslandssemesters bietet. o Vorteile: Direkter Kontakt zu den Partneruniversitäten, Organisatorische Unterstützung durch die WiSo -Fakultät , Befre iung von Studiengebühren an der Gasthochschule. 2. WiSo@: Akademische Kurzprogramme für WiSo Studierende o Es gibt jährlich die Möglichkeit, an akademischen Kurzprogrammen im Ausland teilzunehmen und so während der Semesterferien weitere Credits zu erwerben . 3. Fakultätsübergreifende Kooperationen : o Darüber hinaus gibt es noch weitere Möglichkeiten für ein Auslandsstudium, die durch das Dezernat 9 – Internationales (D9) der Universität zu Köln', 'mir sicher, dass ich durch diese Fähigkeit in der Zukunft auch selbst wirtschaftliche Prozesse mitgestalten kann.\n\nzum Seitenanfang\n\n### B.Sc. VWL - Studienrichtung Economics, Politics, and Society\n\n## Ihre Vorteile auf einen Blick:\n\n- Multidisziplinäre Ausrichtung: Im Verlauf des Studiums profitieren Sie je nach gewählter Studienrichtung vom Austausch und von der Verknüpfung verschiedener Fachbereiche innerhalb der WiSo-Fakultät. In zwei der drei Studienrichtungen können Sie volkswirtschaftliche Fragen durch die Brille von Politikwissenschaft, Soziologie oder Betriebswirtschaftslehre betrachten.\n- Frühzeitige Spezialisierung: Der Bachelorstudiengang Volkswirtschaftslehre bietet neben der typischen Grundausbildung in Ökonomik bereits frühzeitig einen Wahlbereich mit den Themen Behavioural Economics, Ecological Economics, Economic History und International Economics. Weitere Studienfächer behandeln aktuelle Themen wie Klimawandel, Einkommensverteilung, Arbeitsmarktdiskriminierung, Medienmärkte oder Bankenkrisen.\n- Verlinkung mit Deutschlands einzigem wirtschaftswissenschaftlichen Exzellenz-Cluster mit volkswirtschaftlichem Schwerpunkt: Der Fachbereich Volkswirtschaftslehre ist gegenwärtig Teil des Exzellenz-Clusters ECONTribute, in dem die Wissenschaftler:innen des Fachbereichs sich verstärkt mit dem Bereich Märkte und Public Policy beschäftigen und dabei durch umfangreiche Forschungsförderungen unterstützt werden. Clustermitglieder bringen sich und ihre Themen auch in der Le', 'Wirtschaftsinformatik und Data Analysis gewählt werden. Die Masterth esis bildet den letzten Bereich und umfasst 30 LP. --- Page 7 --- Gültig für Studierende der PO 2021 (Einschreibung ab WiSe 2021/22) BUSINESS ANALYTICS & ECONOMETRICS - MASTER OF SCIENCE 3 1.4 Study Abroad Option Die WiSo -Fakultät bietet Ihren Studierenden die Möglichkeit eines Auslandsstudiums innerhalb ihres weltweiten und exzellenten Netzwerks an Partneruniversitäten . Ein Auslandsemester bietet die Chance, den Horizont zu erweitern, interkulturelle Kompetenzen zu erwerben und die akademische Laufbahn zu bereichern. Die Optionen im Überblick: 1. Study Abroad Programme (STAP): o Ein etabliertes Programm, das einen einsemestrigen Austausch an einer der renommierten Partnerhochschulen ermöglicht. Im Rahmen von STAP ist eine ERASMUS -Förderung möglich, die finanzielle Unterstützung während des Auslandssemesters bietet. o Vorteile: Direkter Kontakt zu den Partneruniversitäten, Organisatorische Unterstützung durch die WiSo -Fakultät , Befreiung von Studiengebühren an der Gasthochschule. 2. WiSo@: Akademische Kurzprogramme für WiSo Studierende o Es gibt jährlich die Möglichkeit, an akademischen Kurzprogrammen im Ausland teilzunehmen und so während der Semesterferien weitere Credits zu erwerben . 3. Fakultätsübergreifende Kooperationen : o Darüber hinaus gibt es noch weitere Möglichkeiten für ein Auslandsstudium, die durch das Dezernat 9 – Internationales (D9) der Universität zu Köln angeboten werden. Au ch das', 'den gezielte inhaltliche Schwerpunkte setzen. Für die abschließende Masterarbeit inklusive ihrer Verteidigung sind 30 LP vorgesehen. 1.4 Study Abroad Opt ion Die WiSo -Fakultät bietet Ihren Studierenden die Möglichkeit eines Auslandsstudiums inner- halb ihres weltweiten und exzellenten Netzwerks an Partneruniversitäten . Ein Auslandsemes- ter bietet die Chance, den Horizont zu erweitern, interkulturelle Kompetenzen zu erwerben und die akademische Laufbahn zu bereichern. Die Optionen im Überblick: 1. Study Abroad Programme (STAP): o Ein etabliertes Programm, das einen einsemestrigen Austausch an einer der re- nommierten Partnerhochschulen ermöglicht. Im Rahmen von STAP ist eine ERASMUS -Förderung möglich, die finanzielle Unterstützung während des Aus- landssemesters bietet. o Vorteile: Direkter Kontakt zu den Partneruniversitäten, Organisatorische Unterstüt- zung durch die WiSo -Fakultät , Befreiung von Studiengebühren a n der Gasthoch- schule. 2. WiSo@NYC: Exklusive Summer School in New York City o Es gibt jährlich die Möglichkeit, an der exklusiven Summer School in einer der größten Metropolen der Welt teilzunehmen und während der Semesterferien weitere Credits zu erwerben. --- Page 8 --- Gültig für Studierende der PO 2021 (Einschreibung ab WiSe 2021/22) ECONOMIC RESEARCH – MASTER OF SCIENCE 8 3. Fakultätsübergreifende Kooperationen : o Darüber hinaus gibt es noch weitere Möglichkeiten für ein Auslandsstudium, die durch das Dezernat 9 – Internationales (D9) der Universität z', 'gt die Bachelorarbeit (12 LP). --- Page 8 --- Gültig für Studierende der PO 2021 (Einschreibung ab WiSe 2021/22) MODULHANDBUCH – BETRIEBSWIRTSCHAFTSLEHRE – BACHELOR OF SCIENCE 8 1.4 Study Abroad Option Die WiSo -Fakultät bietet Ihren Studierenden die Möglichkeit eines Auslandsstudiums innerhalb ihres weltweiten und exzellenten Netzwerks an Partneruniversitäten . Ein Auslandsemester bietet die Chance, den Horizont zu erweitern, interkulturelle Kompetenzen zu erwerben und die akademische Laufbahn zu bereichern. Die Optionen im Überblick: 1. Study Abroad Programme (STAP): o Ein etabliertes Programm, das einen einsemestrigen Austausch an einer der renommierten Partnerhochschulen ermöglicht. Im Rahmen von STAP ist eine ERASMUS -Förderung möglich, die finanzielle Unterstützung während des Auslandssemesters bietet. o Vorteile: Direkter Kontakt zu den Partneruniversitäten, Organisatorische Unterstützung durch die WiSo -Fakultät , Befreiung von Studiengebühren an der Gasthochschule. 2. WiSo@ : Akademische Kurzprogramme für W iSo Studierende o Es gibt jährlich die Möglichkeit, an akademischen Kurzprogrammen im Ausland teilzunehmen und so während der Semesterferien weitere Credits zu erwerben. Bachelorarbeit 12 LP Schwerpunktbereich 30 LPErgänzungsbereich 18 LP Basis-und Aufbaubereich 108 LP Gesamtumfang: 180 LP = 6 Semester Regelstudienzeit Studium Integrale 12 LP --- Page 9 --- Gültig für Studierende der PO 2021 (Einschreibung ab WiSe 2021/22) MODULHANDBUCH – BETRIEBSWIRTSCHAFTSLEHRE'] | H2: ['file://D:/Uni-Köln/Masterarbeit/Software/uzk-masterarbeit/data/pdf_cache/__wiso.uni-koeln.de_sites_fakultaet_dokumente_downloads_Modulhandbuecher_Master_MHB_aktuelles_Studienjahr_m_mhb_po2021_ba_accounting.pdf', 'https://wiso.uni-koeln.de/de/studium/bachelor/bachelor-vwl', 'file://D:/Uni-Köln/Masterarbeit/Software/uzk-masterarbeit/data/pdf_cache/__wiso.uni-koeln.de_sites_fakultaet_dokumente_downloads_Modulhandbuecher_Master_MHB_aktuelles_Studienjahr_m_mhb_po2021_business_analytics.pdf', 'file://D:/Uni-Köln/Masterarbeit/Software/uzk-masterarbeit/data/pdf_cache/__wiso.uni-koeln.de_sites_fakultaet_dokumente_downloads_Modulhandbuecher_Master_MHB_aktuelles_Studienjahr_m_mhb_po2021_economic_res.pdf', 'file://D:/Uni-Köln/Masterarbeit/Software/uzk-masterarbeit/data/pdf_cache/__wiso.uni-koeln.de_sites_fakultaet_dokumente_downloads_Modulhandbuecher_Bachelor_MHB_aktuelles_Studienjahr_b_mhb_po2021_bwl.pdf'] | I2: ['pdf', 'html', 'pdf', 'pdf', 'pdf'] | J2: 0.76923077 | K2: 0 | L2: 0 | M2: 0.69978004 | N2: 0.11111111 | O2: 0.92927389 | P2: 0.13976763 | Q2: 0.03489098 | R2: 0.24489997 | S2: 0 | T2: 0 | U2: 25.882106 | V2: 2271 | W2: 329 | X2: 2600 | Y2: 0 | Z2: 5 | AA2: 25.882106
A3: 2 | B3: Allgemein | C3: easy | D3: Welche Kosten fallen für reguläre Studienprogramme der WiSo-Fakultät an? | E3: Die Kosten für reguläre Studienprogramme der WiSo-Fakultät an der Universität zu Köln variieren je nach Studiengang und Art des Studiums. Hier sind einige allgemeine Informationen: * Die Semesterbeiträge für das Wintersemester 2022/23 betragen 302,50 € pro Monat (entspricht 1.151,00 € pro Semester) für Studenten mit deutscher Staatsbürgerschaft. * Für internationale Studierende gelten höhere Beiträge: 322,50 € pro Monat (entspricht 1.291,00 € pro Semester). * Darüber hinaus fallen Gebühren für die Studiengebühr an, die je nach Studiengang zwischen 150,00 € und 300,00 € pro Semester liegen kann. * Es gibt auch weitere Kosten wie z.B. für Bücher, Materialien, Reisen zu Praktika oder Auslandssemester. Es ist ratsam, sich direkt bei der Universität zu informieren, um die aktuellsten Informationen über die Kosten für das gewünschte Studienprogramm zu erhalten. Quelle: [Universität zu Köln - Semesterbeiträge](https://www.uni-koeln.de/studium/finanzielles/semesterbeitraege.html) | F3: Für die regulären Studienprogramme fällt nur der halbjährliche Semesterbeitrag an, der bereits das Semesterticket für den öffentlichen Nahverkehr in ganz Nordrhein-Westfalen umfasst. | G3: ['kultät studiert werden?\n\nFolgenden Masterstudiengänge werden an der WiSo-Fakultät angeboten:\n\n- Business Administration (mit 5 verschiedenen Spezialisierungen)\n- International Management (CEMS MIM)\n- Business Analytics and Econometrics\n- Economics\n- Economic Research\n- Politikwissenschaft\n- Sociology: Social Research\n- Sociology: Social and Economic Psychology\n- Gesundheitsökonomie\n- Information Systems\n- Wirtschaftspädagogik (M.Ed.)\n\nBeim Masterstudiengang Politikwissenschaft handelt es sich um einen Master of Arts, beim Masterstudiengang Wirtschaftspädagogik mit zwei Ausrichtungen um einen Master of Education/Master of Science. Die anderen Masterstudiengänge sind Master of Science. Nähere Informationen zu den einzelnen Studiengängen Sie auf unseren Internetseiten.\n\n## 4. Wieviel kostet ein Studium an der Universität zu Köln?\n\nStudiengebühren gibt es an der Universität zu Köln nicht, dafür wird pro Semester ein Semesterbeitrag fällig. Im Semesterbeitrag enthalten ist u.a. das NRW-Semesterticket, mit dem Sie in ganz Nordrhein-Westfalen den öffentlichen Personennahverkehr nutzen können. Nicht enthalten sind hier Kosten zum Lebensunterhalt, Verpflegung in der Mensa oder Lernmaterialien. Eine Orientierung zu weiteren Kosten Sie u.a. hier.\n\n## 5. Was zeichnet das Studium an der Wiso Fakultät aus?\n\nEin Studium an der WiSo-Fakultät der Universität zu Köln stellt eine hervorragende Ausgangsbasis für Ihre weiteren professionellen und persönlichen Pläne dar. Mit ca. 9.000 Studierenden', 'Studiengänge an der WiSo-Fakultät\n\n# Master\n\nWir freuen uns über Ihr Interesse an unseren Masterstudiengängen!\n\nDie Wirtschafts- und Sozialwissenschaftliche Fakultät (kurz: WiSo-Fakultät) der Universität zu Köln zählt konstant zu den Spitzenfakultäten in Deutschland. Sie zeichnet sich durch eine starke Forschungsorientierung, internationale Möglichkeiten sowie enge Verbindungen zu Wirtschaft und Gesellschaft aus. Unsere Masterstudiengänge, die auf Englisch unterrichtet werden, vermitteln den Studierenden die Fähigkeiten, Perspektiven und Netzwerke, um ihre globale Zukunft aktiv zu gestalten und einen bedeutenden Beitrag zu leisten. Die WiSo-Masterprogramme bieten eine erstklassige Ausbildung ohne Studiengebühren und eröffnen zahlreiche berufliche Perspektiven.\n\nNeben dem in Deutschland exklusiv angebotenen Master of International Management (CEMS MIM) und 5 Doppelmaster-Programmen bietet die Fakultät 15 konsekutive Masterstudiengänge in Betriebswirtschaftslehre, Volkswirtschaftslehre und Sozialwissenschaften sowie den Executive MBA an.\n\nHaben Sie noch weitere Fragen? Dann schauen Sie mal in unsere Master-FAQs!\n\n## Master-Virtueller Infotag\n\nBitte HIER ANMELDEN, um am virtuellen Master-Infotag teilzunehmen. Nutzen Sie die Gelegenheit, mehr über die WiSo-Fakultät zu erfahren, die Studienprogramme zu erkunden und wertvolle Einblicke von Professor:innen, aktuellen Studierenden und Alumni zu gewinnen.\n\n## Inhaltsverzeichnis\n\n- Unsere Masterprogramme in der Übersicht\n- Masterstudie', "ter-Infotag teilzunehmen. Nutzen Sie die Gelegenheit, mehr über die WiSo-Fakultät zu erfahren, die Studienprogramme zu erkunden und wertvolle Einblicke von Professor:innen, aktuellen Studierenden und Alumni zu gewinnen.\n\n## Inhaltsverzeichnis\n\n- Unsere Masterprogramme in der Übersicht\n- Masterstudiengänge mit WiSo-Beteiligung\n- Weitere Master der PO 2015\n\n## Unsere Masterprogramme in der Übersicht\n\n## International Management (CEMS MIM)\n\n## Business Administration\n\n## Double Master's Programme in Business Administration\n\n## Business Analytics & Econometrics\n\n## Economics\n\n## Double Master's Programme in Economics\n\n## Economic Research\n\n## Gesundheitsökonomie\n\n## Double Master's Programme in Health Economics and Management\n\n## Information Systems\n\n## Political Science\n\n## Double Master's Programme in European Studies\n\n## Sociology\n\n## Double Master's Programme in Demography and Social Inequality\n\n## Wirtschaftspädagogik\n\nzum Seitenanfang\n\n## Masterstudiengänge mit WiSo-Beteiligung\n\nAn der WiSo-Fakultät werden Wahlpflichtfächer zu den folgenden Verbund-Master der Philosophischen Fakultät studiert:\n\n- Medienwissenschaft\n- Regionalstudien China\n- Regionalstudien Lateinamerika\n- Regionalstudien Ost- und Mitteleuropa\n\nWeitere Informationen zu diesen Studiengängen erhalten Sie auf den Seiten der Philosophischen Fakultät.\n\nAuch in den Masterstudiengängen\n\n- Mathematik und\n- Wirtschaftsmathematik\n\nder Mathemathisch-Naturwissenschaftlichen Fakultät kann ein Nebenfach an der WiSo-Fakult", 'en der WiSo-Fakultät sind Ihnen bei Unsicherheiten und Fragen gerne behilflich.\n\n## 3. Welche Veranstaltungen kann ich im Studium Integrale belegen und was ist dabei zu beachten?\n\nGrundsätzlich können Sie jedes Modul im Studium Integrale absolvieren, welches in diesem Bereich in Ihrem Studiengangbaum in KLIPS 2.0 aufgeführt und zur Belegung freigeschaltet ist. Bitte beachten Sie aber, dass WiSo-Module die auch als reguläre Module in einem anderen WiSo-Bachelorstudiengang gelehrt werden, zur Belegung nicht freigeschaltet sind. Die Belegung der Module im Studium Integrale erfolgt ebenfalls über KLIPS 2.0. Insgesamt müssen Sie mindestens 12 ECTS im Studium Integrale erbringen. Zusätzlich können auch fachpraktische Tätigkeiten berücksichtigt werden.\n\n## 4. Sind Zusatzleistungen im Bachelorstudium möglich?\n\nDas Erbringen von Zusatzleistungen ist im Rahmen eines Bachelorstudiums an der WiSo-Fakultät der Universität zu Köln nicht vorgesehen und nicht möglich. Bitte haben Sie Verständnis dafür, dass aus Kapazitätsgründen keine Ausnahmen für diese Regelung möglich sind. Ausnahme bietet der Bereich des Studium Integrale. Hier können Sie mehr als die vorgesehenen 12 ECTS erbringen, die auch auf Ihrem Trancript of Records aufgeführt werden.\n\n## Auslandssemester und Praktika\n\n## 1. Wann muss ich mich zu einem Auslandssemester bewerben?\n\nSie haben einerseits die Möglichkeit, über das Zentrum für Internationale Beziehungen (ZIB) der WiSo-Fakultät an eine Partnerhochschule ins Ausland zu geh', 'en. Eine Orientierung zu weiteren Kosten Sie u.a. hier.\n\n## 5. Was zeichnet das Studium an der Wiso Fakultät aus?\n\nEin Studium an der WiSo-Fakultät der Universität zu Köln stellt eine hervorragende Ausgangsbasis für Ihre weiteren professionellen und persönlichen Pläne dar. Mit ca. 9.000 Studierenden und einer Vielzahl an Professuren und wissenschaftlichen Mitarbeitern ist die Fakultät eine der wissenschaftlich renommiertesten Fakultäten für Wirtschafts- und Sozialwissenschaften in Europa.\n\nEntscheidende Rankings bewerten die Qualität von Forschung und Lehre an Hochschulen und der Fakultätsentwicklung anhand verschiedener Kriterien. Die WiSo-Fakultät freut sich, ihre Position in vielen renommierten Rankings behaupten und in einigen Fällen ausbauen zu können.\n\nDie Verbindung von Forschung und Lehre, Theorie und Praxis, Wirtschafts- und Sozialwissenschaften begründet unser Leitbild: „Today\'s ideas. Tomorrow\'s impact". Innerhalb Ihres Studiums erarbeiten Sie mit Hilfe moderner Analysemethoden und Modelle neue Lösungsansätze für relevante wirtschafts- und sozialwissenschaftliche Zukunftsfragen.\n\nKöln ist nicht nur als Studienort eine attraktive Stadt. Sie ist weit über den Karneval hinaus für ihre vielfältige Kulturszene bekannt und stellt zusammen mit dem Umland einen der bedeutendsten Wirtschaftsstandorte in Deutschland dar.\n\n## Wenn Sie schon mal studiert haben\n\n## 1. Kann ich an der WiSo-Fakultät ein Studium aufnehmen, wenn ich einen gleichwertigen Studiengang bzw. eine dort v'] | H3: ['https://wiso.uni-koeln.de/de/studium/studienorganisation/faq/allgemeine-fragen', 'https://wiso.uni-koeln.de/de/studium/master', 'https://wiso.uni-koeln.de/de/studium/master', 'https://wiso.uni-koeln.de/de/studium/studienorganisation/faq/bachelor/fragen-im-bachelorstudium', 'https://wiso.uni-koeln.de/de/studium/studienorganisation/faq/allgemeine-fragen'] | I3: ['html', 'html', 'html', 'html', 'html'] | J3: 0.27272727 | K3: 1 | L3: 1 | M3: 0.61430154 | N3: 0.25 | O3: 0 | P3: 0.05437525 | Q3: -0.15783621 | R3: 0.28049436 | S3: 0 | T3: 0 | U3: 14.811629 | V3: 2230 | W3: 314 | X3: 2544 | Y3: 0 | Z3: 5 | AA3: 14.811629
A4: 3 | B4: Allgemein | C4: medium | D4: Wie wird die Qualität der WiSo-Absolvent:innen in Rankings und durch Arbeitgebereinschätzungen beschrieben? | E4: Die WiSo-Absolvent:innen werden in Rankings und Arbeitgeberbewertungen als hochwertig und qualifiziert beschrieben. Die Universität zu Köln, insbesondere die WiSo-Fakultät, hat sich in verschiedenen Hochschulrankings positioniert und wird von Personalverantwortlichen deutscher Unternehmen als Top-Ausbildungsstätte für BWL, VWL und Wirtschaftsinformatik angesehen. Die Absolvent:innen der WiSo-Fakultät profitieren vom theorie- und methodenorientierten Ansatz, der sowohl Forschung als auch Lehre mit der Praxis vereint. Die Nähe zur Praxis zeigt sich in der Lehre durch die langjährige Erfahrung in der Zusammenarbeit mit Unternehmen und Lehrbeauftragten aus verschiedenen Berufsfeldern. Insgesamt wird die WiSo-Fakultät für ihre hohen Qualitätsstandards und die erfolgreiche Vorbereitung ihrer Absolvent:innen auf den Arbeitsmarkt gelobt. | F4: Die Qualität der WiSo-Absolvent:innen wird dadurch hervorgehoben, dass mehrere DAX40-Vorstände an der Universität zu Köln studiert haben, sie laut dem aktuellen Ranking des Wirtschaftsmagazins „Wirtschaftswoche“ bei der Einstellung durch Personaler bevorzugt werden und die Fakultät im „Careers Rank“ des Financial Times Masters in Management Ranking eine deutschlandweite Spitzenposition einnimmt. | G4: ['# Rankings: Top positioniert\n\nHochschulrankings spielen in der Positionierung der Hochschule im nationalen und internationalen Umfeld sowie als Informationsquelle für Studieninteressierte, Arbeitgeber:innen, Ministerien und andere Stakeholder:innen eine wichtige Rolle. Entscheidende Rankings bewerten die Qualität von Forschung und Lehre an Hochschulen und der Fakultätsentwicklung anhand verschiedener Kriterien. Die WiSo-Fakultät freut sich, ihre Position in vielen renommierten Rankings behaupten und in einigen Fällen ausbauen zu können.\n\n> Hohe Rankingpositionen sind ein wichtiges Qualitätsindiz der Forschung und Lehre an der WiSo-Fakultät. Unsere exzellenten Ergebnisse in namhaften Rankings unterstreichen die Wettbewerbsfähigkeit der WiSo-Fakultät im nationalen sowie internationalen Hochschulumfeld.\n\nIm aktuellen Global Ranking of Academic Subjects (GRAS, "Shanghai Ranking")\xa0belegt die Universität zu Köln in der nationalen Auswertung Platz 1 für\xa0 "Sociology".\n\nIm AIS research ranking im Bereich Wirtschaftsinformatik liegt die UzK auf Platz 1 in Deutschland und auf Platz 4 in Europa.\n\nAn keiner anderen deutschen Hochschule haben so viele der aktuellen Vorstände der 40 Dax Unternehmen studiert wie an der Universität zu Köln. Die meisten davon kommen aus der WiSo-Fakultät (11. DAX Vorstandsreport, Handelsblatt).\n\nDie WiSo-Fakultät belegt in der Rubrik "International course experience rank" des Financial Times Masters in Management Rankings Platz 1 in Deutschland (weltweit Platz', '# Rankings: Top positioniert\n\nHochschulrankings spielen in der Positionierung der Hochschule im nationalen und internationalen Umfeld sowie als Informationsquelle für Studieninteressierte, Arbeitgeber:innen, Ministerien und andere Stakeholder:innen eine wichtige Rolle. Entscheidende Rankings bewerten die Qualität von Forschung und Lehre an Hochschulen und der Fakultätsentwicklung anhand verschiedener Kriterien. Die WiSo-Fakultät freut sich, ihre Position in vielen renommierten Rankings behaupten und in einigen Fällen ausbauen zu können.\n\n> Hohe Rankingpositionen sind ein wichtiges Qualitätsindiz der Forschung und Lehre an der WiSo-Fakultät. Unsere exzellenten Ergebnisse in namhaften Rankings unterstreichen die Wettbewerbsfähigkeit der WiSo-Fakultät im nationalen sowie internationalen Hochschulumfeld.\n\nIm aktuellen Global Ranking of Academic Subjects (GRAS, "Shanghai Ranking")\xa0belegt die Universität zu Köln in der nationalen Auswertung Platz 1 für\xa0 "Sociology".\n\nIm AIS research ranking im Bereich Wirtschaftsinformatik liegt die UzK auf Platz 1 in Deutschland und auf Platz 4 in Europa.\n\nAn keiner anderen deutschen Hochschule haben so viele der aktuellen Vorstände der 40 Dax Unternehmen studiert wie an der Universität zu Köln. Die meisten davon kommen aus der WiSo-Fakultät (11. DAX Vorstandsreport, Handelsblatt).\n\nDie WiSo-Fakultät belegt in der Rubrik "International course experience rank" des Financial Times Masters in Management Rankings Platz 1 in Deutschland (weltweit Platz', '# Rankings: Top positioniert\n\nHochschulrankings spielen in der Positionierung der Hochschule im nationalen und internationalen Umfeld sowie als Informationsquelle für Studieninteressierte, Arbeitgeber:innen, Ministerien und andere Stakeholder:innen eine wichtige Rolle. Entscheidende Rankings bewerten die Qualität von Forschung und Lehre an Hochschulen und der Fakultätsentwicklung anhand verschiedener Kriterien. Die WiSo-Fakultät freut sich, ihre Position in vielen renommierten Rankings behaupten und in einigen Fällen ausbauen zu können.\n\n> Hohe Rankingpositionen sind ein wichtiges Qualitätsindiz der Forschung und Lehre an der WiSo-Fakultät. Unsere exzellenten Ergebnisse in namhaften Rankings unterstreichen die Wettbewerbsfähigkeit der WiSo-Fakultät im nationalen sowie internationalen Hochschulumfeld.\n\nIm aktuellen Global Ranking of Academic Subjects (GRAS, "Shanghai Ranking")\xa0belegt die Universität zu Köln in der nationalen Auswertung Platz 1 für\xa0 "Sociology".\n\nIm AIS research ranking im Bereich Wirtschaftsinformatik liegt die UzK auf Platz 1 in Deutschland und auf Platz 4 in Europa.\n\nAn keiner anderen deutschen Hochschule haben so viele der aktuellen Vorstände der 40 Dax Unternehmen studiert wie an der Universität zu Köln. Die meisten davon kommen aus der WiSo-Fakultät (11. DAX Vorstandsreport, Handelsblatt).\n\nDie WiSo-Fakultät belegt in der Rubrik "International course experience rank" des Financial Times Masters in Management Rankings Platz 1 in Deutschland (weltweit Platz', '# Personaler-Ranking der Wirtschaftswoche 2020\n\n24.04.2020\n\nDie Universität zu Köln gehört auch 2020 zu den Top-Ausbildungsstätten für BWL, VWL und Wirtschaftsinformatik.\n\n"Von welcher dieser 200 Hochschule stellen Sie besonders gern Absolventen ein?" So lautet kurz gefasst die Kernfrage des jährlichen Personaler-Rankings der Wirtschaftswoche unter knapp 600 Personalverantwortlichen deutscher Unternehmen. Beim so zustande gekommenen Ranking belegt die WiSo-Fakultät 2020 erneut herausragende Platzierungen. Hinsichtlich der Berufschancen ihrer Absolventen ist die Universität zu Köln damit weiter eine Top-Adresse für ein BWL-, VWL- oder Wirtschaftsinformatik-Studium (nach denen unter anderem im Ranking differenziert wird).\n\nDies gilt dabei auch unter Einbezug der Bereiche, in denen private Hochschulen gute Rankingpositionen erzielen. So setzen die befragten Personalchef*Innen die WiSo-Fakultät etwa bei den BWL-Absolventen auf den 3 Platz. Im Bereich VWL, laut Wirtschaftswoche der „knappste“ Bereich des gesamten Rankings, liegt die WiSo-Fakultät auf dem 2. Rang und verbesserte sich damit um einen Platz gegenüber dem Vorjahr. Nicht zuletzt gehört die Universität zu Köln auch im Bereich Wirtschaftinformatik mit einem 6. Platz unter den gelisteten Universitäten und Fachhochschulen zu den Top Ten Ausbildungsstätten.\n\n• Informationen zum WiWo-Ranking\n\nZurück\n\n#### Social-Media-Kanäle der WiSo-Fakultät\n\n[ follow us! ]\n\nHI\n\nzum Seitenanfang', 'Studium an der WiSo-Fakultät\n\n# Starten Sie mit uns Ihren persönlichen Karriereweg!\n\nUnsere Studierenden profitieren in unseren Bachelor- und Masterstudiengängen vom theorie- und methodenorientierten Ansatz, der sowohl Forschung als auch Lehre mit der Praxis vereint. Die Nähe zur Praxis zeigt sich in der Lehre durch unsere langjährige Erfahrung in der Zusammenarbeit mit Unternehmen und Lehrbeauftragten aus verschiedenen Berufsfeldern. Ein Großteil unserer Lehrbeauftragten sind Fach- und Führungskräfte, die über wichtige Praxiserfahrungen verfügen. Dadurch können branchenspezifische und aktuelle Lehrinhalte kompetent und praxisnah vermittelt werden. Die Praxisorientierung, und somit die Verzahnung zwischen Praxis und Theorie im Studium, wird somit sicherstellt und der Austausch zwischen Studierenden und Unternehmen gefördert.\n\n## Top im Ranking\n\nMehrere DAX40-Vorstände studierten an der Universität zu Köln, soviele wie von keiner ansderen Universität. Dies unterstreicht die Fach- und Führungskompetenzen unserer Absolventen. Laut aktuellem Ranking des Wirtschaftsmagazins „Wirtschaftswoche“ werden unsere Absolventen bei der Einstellung durch Personaler bevorzugt. Eine deutschlandweite Spitzenposition halten wir derzeit in der Rubrik „Careers Rank“ des Financial Times Masters in Management Ranking. Hierbei wird betrachtet, wie viele der Absolventen drei Jahre nach Studienabschluss Führungspositionen verantworten und wie groß das jeweilige Unternehmen ist.\n\n## Internationale Ausri'] | H4: ['https://wiso.uni-koeln.de/de/service/rankings/', 'https://wiso.uni-koeln.de/de/services/rankings', 'https://wiso.uni-koeln.de/de/service/rankings', 'https://wiso.uni-koeln.de/de/aktuelles-und-neuigkeiten/news-einzelansicht/personaler-ranking-der-wirtschaftswoche-2020', 'https://wiso.uni-koeln.de/de/studium/bewerbung/studium-an-der-wiso-fakultaet'] | I4: ['html', 'html', 'html', 'html', 'html'] | J4: 1 | K4: 1 | L4: 0.36666667 | M4: 0.81694685 | N4: 0.625 | O4: 0.8201472 | P4: 0.18233339 | Q4: 0.12567064 | R4: 0.23648198 | S4: 0.2 | T4: 1 | U4: 13.043421 | V4: 2211 | W4: 258 | X4: 2469 | Y4: 0 | Z4: 5 | AA4: 13.043421
A5: 4 | B5: Allgemein | C5: medium | D5: Wie ist die internationale Ausrichtung der WiSo-Fakultät beschrieben? | E5: Die internationale Ausrichtung der WiSo-Fakultät der Universität zu Köln ist stark ausgeprägt. Die Fakultät bietet eine Vielzahl von Möglichkeiten, um internationale Erfahrungen zu sammeln, wie zum Beispiel das Optionale Auslandssemester oder die Teilnahme an Kurzprogrammen wie WiSo@NYC oder einer Summer School im Ausland. Die Fakultät ist Mitglied in mehreren Netzwerken internationaler Universitäten und bietet Kooperationen mit renommierten Partnerhochschulen weltweit, darunter Erasmus-Abkommen mit europäischen Universitäten. Dies ermöglicht es den Studierenden, ein Semester an einer internationalen Hochschule zu verbringen. Darüber hinaus bietet die WiSo-Fakultät eine breite BWL-Grundlagenausbildung und gleichzeitig die Möglichkeit einer individuellen Spezialisierung über vielfältige Angebote im Ergänzungs- und Schwerpunktbereich. Die Studierenden können ihre Kenntnisse und Fähigkeiten in anwendungsorientierten Modulen umsetzen, indem sie analytisches Denken und Handeln in die Praxis einbringen. Die internationale Ausrichtung der WiSo-Fakultät macht sie zu einem erstklassigen Ziel für Studierende, die eine Karriere in internationalen Arbeitsumgebungen anstreben. | F5: Die WiSo-Fakultät ist einziges deutsches Mitglied im CEMS-Netzwerk und bietet gemeinsam mit Partnern den Master in International Management (CEMS MIM) an. Viele Studienprogramme enthalten einen hohen Anteil englischsprachiger Module und nahezu alle Masterprogramme können vollständig auf Englisch studiert werden. Zudem bestehen Partnerschaften mit über 130 Hochschulen für Auslandssemester. | G5: ['sgewogenen Theorie- und Praxisansatz auf eine Karriere in internationalen Arbeitsumgebungen vor und befähigt Sie, in internationalisierten Unternehmen zu arbeiten.\n\nDarüber hinaus verfügt die WiSo-Fakultät über ein starkes Alumni-Netzwerk ehemaliger Studierender, die in allen Geschäftsbereichen weltweit tätig sind.\n\n### Eine internationale Fakultät\n\nDie internationale Ausrichtung und exzellente Reputation der WiSo-Fakultät der Universität zu Köln machen sie zu einem erstklassigen Ziel für Ihr Studium in Deutschland – mitten in Europa.\n\n- Veranstaltungskalender für internationale Studierende\n- Interesse an einem Deutschkurs? Fach- und Fertigkeitsspezifische Deutschkurse\n- Fragen zu Visum, Bescheinigungen oder Jobs? Das International Office hilft weiter!\n\nzum Seitenanfang\n\n## Karrieremöglichkeiten\n\nDieses Programm wird Sie für eine Karriere in einer Vielzahl von Rollen in verschiedenen Branchen qualifizieren. Nach Abschluss des Programms steigen unsere Studierenden in ein Management-Trainee-Programme, Stabsfunktionen in Strategie-, Unternehmensentwicklungs-, Compliance-Management-Einheiten oder Personalmanagement-Abteilungen ein. Viele starten ihre Karriere auch in Beratungsunternehmen. Potenzielle Arbeitgeber*innen reichen von Start-ups und kleinen/mittleren Unternehmen bis hin zu großen und globalen Konzernen.\n\nEbenso sind unsere Alumni branchenübergreifend und über alle Stufen der Wertschöpfungskette hinweg beschäftigt - von der Produktion über den Vertrieb bis hin zu Handel', 'h auf ein internationales und interkulturelles Umfeld an der Fakultät und auch innerhalb Ihres Studiengangs freuen können. Eine Vielzahl der Kurse wird je nach Spezialisierung in englischer Sprache angeboten.\n\n### Optionales Auslandssemester\n\nDie WiSo-Fakultät ist Mitglied in mehreren Netzwerken internationaler Universitäten, was Ihnen dabei hilft, ein Semester an einer renommierten Partnerhochschule im Ausland zu verbringen. Das Programm ist so konzipiert, dass Sie im vierten oder fünften Semester ein Auslandssemester absolvieren können. Wir beraten Sie gerne über Ihre Möglichkeiten und unterstützen Sie organisatorisch vor, während und nach Ihrem Auslandsaufenthalt.\n\n### Ihre Chance für globales Networking\n\nDer Studiengang bereitet Sie mit seinem ausgewogenen Theorie- und Praxisansatz auf den Einstieg in international ausgerichtete Berufe vor und befähigt Sie, in einem internationalisierten Umfeld zu arbeiten. Darüber hinaus verfügt die WiSo-Fakultät über ein breites Alumni-Netzwerk ehemaliger Studierender, die in allen Geschäftsbereichen rund um den Globus tätig sind.\n\n### Eine internationale Fakultät\n\nDie internationale Ausrichtung und exzellente Reputation der WiSo-Fakultät der Universität zu Köln machen sie zu einem erstklassigen Ziel für Dein Studium in Deutschland – mitten in Europa.\n\n- Veranstaltungskalender für internationale Studierende\n- Interesse an einem Deutschkurs? Fach- und Fertigkeitsspezifische Deutschkurse\n- Fragen zu Visum, Bescheinigungen', 'le verfügbaren Möglichkeiten zu nutzen, um eigene internationale Erfahrungen zu sammeln. Kooperationen mit einer Vielzahl exzellenter Partnerhochschulen weltweit, darunter Erasmus-Abkommen mit einer Vielzahl von europäischen Universitäten, bieten Ihnen attraktive Möglichkeiten, Ihr Auslandssemester zu verbringen. Wir beraten Sie gerne über ihre Möglichkeiten. Studierende, die ihr Auslandssemester selbst organisieren möchten, können dies als Freemover tun.\n\nZusätzlich zu einem Auslandssemester können Sie Ihr Studium bereichern, indem Sie an einem unserer Kurzprogramme wie WiSo@NYC oder einer Summer School im Ausland teilnehmen, oder ein Auslandspraktikum mit finanzieller Unterstützung durch Erasmus absolvieren.\n\n### Breites internationales Netzwerk\n\nDer international ausgerichtete Masterstudiengang bereitet Sie mit seinem ausgewogenen Theorie- und Praxisansatz auf eine Karriere in internationalen Arbeitsumgebungen vor und befähigt Sie, in internationalisierten Unternehmen zu arbeiten.\n\nDarüber hinaus verfügt die WiSo-Fakultät über ein starkes Alumni-Netzwerk ehemaliger Studierender, die in vielen Geschäftsbereichen weltweit tätig sind.\n\n### Eine internationale Fakultät\n\nDie internationale Ausrichtung und exzellente Reputation der WiSo-Fakultät der Universität zu Köln machen sie zu einem erstklassigen Ziel für Ihr Studium in Deutschland – mitten in Europa.\n\n- Veranstaltungskalender für internationale Studierende\n- Interesse an einem Deutschkurs? Fach- und Fertigkeitsspezifische', 'onnen, die in der weiteren beruflichen Laufbahn intensiviert und spezialisiert werden können.\n\n> Das Bachelorstudium der Betriebswirtschaftslehre an der Kölner WiSo-Fakultät bietet eine breite BWL-Grundlagenausbildung und gleichzeitig die Möglichkeit einer individuellen Spezialisierung über vielfältige Angebote im Ergänzungs- und Schwerpunktbereich. In anwendungsorientierten Modulen können Sie analytisches Denken und Handeln in die Praxis umsetzen, indem Sie die erworbenen Kenntnisse und Fähigkeiten zur Lösung praktischer Problemstellungen einsetzen.\n\nzum Seitenanfang\n\n## Akademische Exzellenz mit internationalem Angebot\n\n### Internationale Ausrichtung über das gesamte Studium hinweg\n\nFür den Großteil unseres Studienangebots erhalten wir Bewerbungen von einer großen Anzahl verschiedener Nationalitäten, sodass Sie sich auf ein internationales und interkulturelles Umfeld an der Fakultät und auch innerhalb Ihres Studiengangs freuen können. Eine Vielzahl der Kurse wird je nach Spezialisierung in englischer Sprache angeboten.\n\n### Optionales Auslandssemester\n\nDie WiSo-Fakultät ist Mitglied in mehreren Netzwerken internationaler Universitäten, was Ihnen dabei hilft, ein Semester an einer der über 140 renommierten Partnerhochschulen im Ausland zu verbringen. Das Programm ist so konzipiert, dass Sie im vierten oder fünften Semester ein Auslandssemester absolvieren können. Wir beraten Sie gerne über Ihre Möglichkeiten und unterstützen Sie organisatorisch vor, während und nach Ihrem Au', 'ter zu verbringen.\xa0Wir beraten Sie gerne über ihre Möglichkeiten. Studierende, die ihr Auslandssemester selbst organisieren möchten, können dies als Freemover tun. Zusätzlich zu einem Auslandssemester können Sie Ihr Studium bereichern, indem Sie an einem unserer Kurzprogramme wie WiSo@NYC oder einer Summer School im Ausland teilnehmen, oder ein Auslandspraktikum mit finanzieller Unterstützung durch Erasmus absolvieren.\n\n### Breites internationales Netzwerk\n\nDer international ausgerichtete Masterstudiengang bereitet Sie mit seinem ausgewogenen Theorie- und Praxisansatz auf eine Karriere in internationalen Arbeitsumgebungen vor und befähigt Sie, in internationalisierten Unternehmen zu arbeiten. Darüber hinaus verfügt die WiSo-Fakultät über ein starkes Alumni-Netzwerk ehemaliger Studierender, die in allen Geschäftsbereichen weltweit tätig sind.\n\n### Eine internationale Fakultät\n\nDie internationale Ausrichtung und exzellente Reputation der WiSo-Fakultät der Universität zu Köln machen sie zu einem erstklassigen Ziel für Ihr Studium in Deutschland – mitten in Europa.\n\n- Veranstaltungskalender für internationale Studierende\n- Interesse an einem Deutschkurs? Fach- und Fertigkeitsspezifische Deutschkurse\n- Fragen zu Visum, Bescheinigungen oder Jobs? Das International Office hilft weiter!\n\nzum Seitenanfang\n\n## Karrieremöglichkeiten\n\nDer M.Sc. in SCM zielt auf die Ausbildung zukünftiger Führungskräfte und Gründer:innen, die branchenübergreifend u.a. in der Logistik- und Produktionsplanu'] | H5: ['https://wiso.uni-koeln.de/de/studium/master/master-business-administration/corporate-development', 'https://wiso.uni-koeln.de/de/studium/bachelor/bachelor-wirtschaftsinformatik', 'https://wiso.uni-koeln.de/de/studium/master/master-business-administration/accounting-and-taxation', 'https://wiso.uni-koeln.de/de/studium/bachelor/bachelor-bwl', 'https://wiso.uni-koeln.de/de/studium/master/master-business-administration/supply-chain-management'] | I5: ['html', 'html', 'html', 'html', 'html'] | J5: 1 | K5: 0.66666667 | L5: 0 | M5: 0.64766007 | N5: 0.14285714 | O5: 0.8366044 | P5: 0.18402644 | Q5: 0.086959876 | R5: 0.28091517 | S5: 0 | T5: 0 | U5: 14.956461 | V5: 2190 | W5: 331 | X5: 2521 | Y5: 0 | Z5: 5 | AA5: 14.956461
A6: 5 | B6: Allgemein | C6: easy | D6: Welches Ziel verfolgen die Lehrinnovationen an der WiSo-Fakultät? | E6: Die Lehrinnovationen an der WiSo-Fakultät verfolgen das Ziel, die Lehre zu verbessern und neue Wege für eine effektive Vermittlung von Wissen zu beschreiben. Dazu gehören: 1. **Forschungsorientierte Lehre**: Die Lehre soll realen Problemen widerspiegeln und wissenschaftliche Ansätze zur Lösung von Problemen in der Praxis anwenden. 2. **Verbesserung der Lehrqualität**: Durch innovative Ideen und Lehrkonzepte sollen die Studierenden besser auf die Herausforderungen der Zukunft vorbereitet werden. 3. **Förderung von Kreativität und Kritikdenken**: Die WiSo-Fakultät möchte, dass die Studierenden kritisch denken und Probleme kreativ lösen können. Die Lehrinnovationen zielen darauf ab, die Studierenden auf die Herausforderungen der Zukunft vorzubereiten und sie zu eigenständigen und innovativen Denkern auszubilden. | F6: Mit den Lehrinnovationen möchte die WiSo-Fakultät ihre Lehre weiterentwickeln, indem sie neue Formen und Ansätze im Unterricht ausprobiert, um die Qualität der Lehrveranstaltungen zu steigern. Die Projekte können dabei inhaltlich sehr unterschiedlich sein, solange sie einen klaren Bezug zur Lehre haben. | G6: ['# Lehrinnovationen\n\nFür eine Verbesserung der Lehre entwickelt die WiSo-Fakultät innovative Ideen und Lehrkonzepte, die neue Wege beschreiten und die Lehrqualität verbessern. Dabei sind der Vielfältigkeit der Ideen – bis auf den erforderlichen Bezug zur Lehre – bewusst keine Grenzen gesetzt. Eine Auswahl der aktuellen Projekte Sie im Folgenden beschrieben.\n\n"Durch den Schwerpunkt der WiSo-Fakultät auf Innovation und Zusammenarbeit habe ich gelernt, kritisch zu denken, Probleme kreativ zu lösen und in vielfältigen Teams zu arbeiten – Fähigkeiten, die meinen Berufseinstieg beschleunigt haben und mir immer noch jeden Tag zum Erfolg verhelfen."\n\nMaximilian vom Eyser\nSenior Digital Growth Strategist, Google\n\nOnline Vorlesung: „Einführung in die Betriebswirtschaftslehre"\n\n## Weitere Lehrinnovationen an der WiSo-Fakultät\n\n## E-PLUS: Crowdsourcing-basiertes, individuelles Lernen\n\nInitiiert wurde das Projekt von Prof. Dr. Detlef Schoder, Inhaber des Seminars für Wirtschaftsinformatik und Informationsmanagement und akademischer Programm-Direktor für Wirtschaftsinformatik. Es wird erstmalig im Wintersemester 2017/18 im Rahmen der Lehrveranstaltung „Basismodul Grundlagen der Wirtschaftsinformatik“ (für Betriebswirte) angewandt. Angelehnt an das Konzept des Crowdsourcing konzipieren Studierende als Lernende im laufenden Semester Aufgaben und Lösungen zum Vorlesungsmaterial und bewerten und korrigieren die Aufgaben und Lösungen gegenseitig (Peer Reviewing). Die Studierenden werden somit ak', '# WiSo Strategie 2030\n\nDer WiSo Fakultätsentwicklungsplan\n\n# Inhaltsverzeichnis\n\n- Unsere Strategie für die Zukunft\n- Unsere strategischen Ziele bis 2030\n\n- Forschung\n- Lehre\n- Transfer\n- Karriere\n- Governance\n- Administrative und professionelle Dienstleistungen\n- Interdisziplinarität und Querschnittsthemen\n\n- Unsere Top Ten Prioritäten bis 2030\n- Gemeinsam die Zukunft gestalten!\n\n## Unsere Strategie für die Zukunft\n\nDie WiSo-Fakultät der Universität zu Köln stellt sich den Herausforderungen einer zunehmend globalisierten, digitalen und auf Nachhaltigkeit ausgerichteten Welt. Mit dem Strategischen Entwicklungsplan WiSo 2030 setzen wir uns klare Ziele, um unsere Position als eine der führenden akademischen Institutionen in den Bereichen Management, Volkswirtschaftslehre und Sozialwissenschaften weiter auszubauen.\n\nWir verfolgen das Ziel, exzellente Forschung mit gesellschaftlicher Relevanz zu verbinden, unseren Studierenden eine praxisorientierte Ausbildung zu bieten und einen positiven Beitrag für Menschen, Organisationen, die Gesellschaft und den Planeten zu leisten.\n\n## Unsere strategischen Ziele bis 2030\n\n### Forschung\n\n- Förderung der Forschung zu großen gesellschaftlichen Herausforderungen durch Forschungskooperationen\n- Erhöhung der externen Finanzierung zur Unterstützung unserer Forschung\n- Ausbau der Doktorand:innenausbildung zur Steigerung der Forschungsqualität und -leistung\n\n### Lehre\n\n- Steigerung von Relevanz und Wettbewerbsfähigkeit durch ein attraktives Studien', '# WiSo Strategie 2030\n\nDer WiSo Fakultätsentwicklungsplan\n\n# Inhaltsverzeichnis\n\n- Unsere Strategie für die Zukunft\n- Unsere strategischen Ziele bis 2030\n\n- Forschung\n- Lehre\n- Transfer\n- Karriere\n- Governance\n- Administrative und professionelle Dienstleistungen\n- Interdisziplinarität und Querschnittsthemen\n\n- Unsere Top Ten Prioritäten bis 2030\n- Gemeinsam die Zukunft gestalten!\n\n## Unsere Strategie für die Zukunft\n\nDie WiSo-Fakultät der Universität zu Köln stellt sich den Herausforderungen einer zunehmend globalisierten, digitalen und auf Nachhaltigkeit ausgerichteten Welt. Mit dem Strategischen Entwicklungsplan WiSo 2030 setzen wir uns klare Ziele, um unsere Position als eine der führenden akademischen Institutionen in den Bereichen Management, Volkswirtschaftslehre und Sozialwissenschaften weiter auszubauen.\n\nWir verfolgen das Ziel, exzellente Forschung mit gesellschaftlicher Relevanz zu verbinden, unseren Studierenden eine praxisorientierte Ausbildung zu bieten und einen positiven Beitrag für Menschen, Organisationen, die Gesellschaft und den Planeten zu leisten.\n\n## Unsere strategischen Ziele bis 2030\n\n### Forschung\n\n- Förderung der Forschung zu großen gesellschaftlichen Herausforderungen durch Forschungskooperationen\n- Erhöhung der externen Finanzierung zur Unterstützung unserer Forschung\n- Ausbau der Doktorand:innenausbildung zur Steigerung der Forschungsqualität und -leistung\n\n### Lehre\n\n- Steigerung von Relevanz und Wettbewerbsfähigkeit durch ein attraktives Studien', '# Forschungsorientierte Lehre\n\nDie Lehre an der WiSo-Fakultät zeichnet sich durch ihre Fokussierung auf Forschung, Theorie und Methoden aus. Daher widmet sich die Lehre realen Problemen, die gegenwärtige wirtschaftliche und soziale Veränderungen widerspiegeln. Die Studierenden werden aufgefordert, wissenschaftliche Ansätze zur Lösung von Problemen in der Praxis anzuwenden und bei Interesse frühzeitig Kenntnisse in der aktiven Forschung zu entwickeln. Daher legt die WiSo-Fakultät den Schwerpunkt auf den Erwerb von Forschungskompetenzen und die Anwendung der Theorie im Rahmen des gewählten Studiengangs.\n\nDiese Forschungsorientierung zeigt sich in der Gestaltung und Abfolge der Bachelor-, Master- und Doktorandenprogramme. Alle Programme haben einen gemeinsamen Kern, der sich an dem Fakultätsmotto "Today’s ideas. Tomorrow’s impact." orientiert. Dies zeigt sich sowohl in der Kombination von forschungsorientierter Lehre als auch durch die Berücksichtigung aktueller gesellschaftlicher Fragestellungen.\n\nEin positiver Trend in den letzten Jahren war die Zunahme von interaktiven Kursformaten, forschungsorientiertem Lernen und speziellen Kurs- und Serviceangeboten. Darüber hinaus hilft der verstärkte Einsatz von Fallstudien als Lehr- und Lernmethode den Studierenden, Forschungsergebnisse in der Praxis anzuwenden und praktische Managementfähigkeiten wie die Arbeit in (internationalen und interdisziplinären) Teams anzuwenden.\n\nDes Weiteren ist die WiSo-Fakultät bestrebt, ihre Programminha', 'evised mission and vision. The SILOs are:WiSo’s graduates make a positive impact in the world by addressing current and future challenges and (1) apply subject-related knowledge , analytical methods, and research-based approaches, (2) work with an open mind in diverse teams to share knowledge and develop solutions, and (3) actively engage in the development of their profes-sional and social environments. T he SILOs address students’ analytical skills and subject- related knowledge but also, social and personal competences and are translated into the Intended Learning Outcomes on programme, module and course level. They ensure that teaching and learning processes of the School focus on educating responsible graduates who make a positive impact in the world by addressing current and future challenges. WiSo is committed to fostering our students’ autonomy, sense of responsibility, discretion, critical thinking and readiness to fulfil high expectations, both during their studies and in their professional lives. The School aims to stimulate a culture of active learning and research-orientation while assisting students in mastering their field of study. Education at the School is characterised by a strong orientation towards research, theory and methods, with students playing an active role in their learning. They are encouraged to understand their own responsibility to shape a successful learning experience. A further characteristic is teaching which draws on reallife problems ref'] | H6: ['https://wiso.uni-koeln.de/de/studium/lehrinnovationen', 'https://wiso.uni-koeln.de/de/fakultaet/fakultaetsstrategie', 'https://wiso.uni-koeln.de/de/fakultaet/fakultaetsstrategie/wiso-strategie-2030', 'https://wiso.uni-koeln.de/de/studium/forschungsorientierte-lehre', 'file://D:/Uni-Köln/Masterarbeit/Software/uzk-masterarbeit/data/pdf_cache/__wiso.uni-koeln.de_sites_fakultaet_dokumente_ethik_WiSo-PRME-SIP-2022-web.pdf'] | I6: ['html', 'html', 'html', 'html', 'pdf'] | J6: 0.64285714 | K6: 1 | L6: 1 | M6: 0.85735251 | N6: 0.99999999 | O6: 0.97501414 | P6: 0.29177096 | Q6: 0.15998346 | R6: 0.4268249 | S6: 1 | T6: 1 | U6: 12.850104 | V6: 2229 | W6: 262 | X6: 2491 | Y6: 0 | Z6: 5 | AA6: 12.850104
